Workbook

Sheet Sheet
A1: Nivel | B1: Nombre Alumno | C1: A. Paterno Alumno | D1: A. Materno Alumno | E1: Matrícula | F1: Nombre | G1: Carrera | H1: Grado | I1: Sexo | J1: Situación | K1: Grupo | L1: Total Total
A2: LICENCIATURA | B2: ABBY DESSIRE | C2: PELAYO | D2: DIAZ | E2: 111772 | F2: PELAYO DIAZ ABBY DESSIRE | G2: NUTRICION Y GASTRONOMIA | H2: 4to | I2: Femenino | J2: Activo | K2: NUT 4° | L2: 1
A3: LICENCIATURA | B3: ABIGAIL | C3: MENDOZA | D3: VILLELA | E3: 112156 | F3: MENDOZA VILLELA ABIGAIL | G3: PSICOLOGIA | H3: 2do | I3: Femenino | J3: Activo | K3: PSI 2° | L3: 1
A4: LICENCIATURA | B4: ABRIL ISABELLA | C4: GODOY | D4: FLORES | E4: 111103 | F4: GODOY FLORES ABRIL ISABELLA | G4: INGENIERIA CIBERNETICA Y EN SISTEMAS COMPUTACIONALES | H4: 6to | I4: Femenino | J4: Activo | K4: CIB 6° | L4: 1
A5: LICENCIATURA | B5: ADAN OSWALDO | C5: SANDOVAL | D5: CARDENAS | E5: 111031 | F5: SANDOVAL CARDENAS ADAN OSWALDO | G5: INGENIERIA AEROESPACIAL | H5: 6to | I5: Masculino | J5: Activo | K5: AERO 6° | L5: 1
A6: LICENCIATURA | B6: ADIB KALEB | C6: GONZALEZ | D6: TOSCANO | E6: 110517 | F6: GONZALEZ TOSCANO ADIB KALEB | G6: INGENIERIA AEROESPACIAL | H6: 8vo | I6: Masculino | J6: Activo | K6: AERO 8° | L6: 1
A7: LICENCIATURA | B7: ADOLFO ALEXANDER | C7: VEGA | D7: RUELAS | E7: 112194 | F7: VEGA RUELAS ADOLFO ALEXANDER | G7: INGENIERÍA AUTOMOTRIZ | H7: 2do | I7: Masculino | J7: Activo | K7: AUTO 2° A | L7: 1
A8: LICENCIATURA | B8: ADRIAN | C8: ESQUEDA | D8: MACIAS | E8: 109814 | F8: ESQUEDA MACIAS ADRIAN | G8: INGENIERIA AEROESPACIAL | H8: 10mo | I8: Masculino | J8: Activo | K8: AERO_10° | L8: 1
A9: LICENCIATURA | B9: ADRIAN | C9: JAIME | D9: OJEDA | E9: 111784 | F9: JAIME OJEDA ADRIAN | G9: INGENIERÍA AUTOMOTRIZ | H9: 4to | I9: Masculino | J9: Activo | K9: AUTO 4° | L9: 1
A10: LICENCIATURA | B10: ADRIAN ASSIS | C10: TAPIA | D10: CORRIPIO | E10: 109374 | F10: TAPIA CORRIPIO ADRIAN ASSIS | G10: INGENIERIA AEROESPACIAL | H10: 6to | I10: Masculino | J10: Activo | K10: AERO 6° | L10: 1
A11: LICENCIATURA | B11: ADRIAN BRYANT | C11: VEGA | D11: CASTAÑEDA | E11: 111793 | F11: VEGA CASTAÑEDA ADRIAN BRYANT | G11: PSICOLOGIA | H11: 4to | I11: Masculino | J11: Activo | K11: PSI 4° | L11: 1
A12: LICENCIATURA | B12: ADRIAN ENRIQUE | C12: MORALES | D12: ORTIZ | E12: 112223 | F12: MORALES ORTIZ ADRIAN ENRIQUE | G12: INGENIERIA AEROESPACIAL | H12: 2do | I12: Masculino | J12: Activo | K12: AERO 2°A | L12: 1
A13: LICENCIATURA | B13: ADRIANA | C13: AMARO | D13: BALTIERRA | E13: 111068 | F13: AMARO BALTIERRA ADRIANA | G13: INGENIERIA AEROESPACIAL | H13: 6to | I13: Femenino | J13: Activo | K13: AERO 6° | L13: 1
... A117: LICENCIATURA | B117: BRUNO SANTIAGO | C117: MUÑOZ | D117: GUTIERREZ | E117: 112196 | F117: MUÑOZ GUTIERREZ BRUNO SANTIAGO | G117: INGENIERÍA AUTOMOTRIZ | H117: 2do | I117: Masculino | J117: Activo | K117: AUTO 2° B | L117: 1
A118: LICENCIATURA | B118: CAMILLA | C118: ZEPEDA JIMENEZ | E118: 112248 | F118: ZEPEDA JIMENEZ CAMILLA | G118: INGENIERIA AEROESPACIAL | H118: 2do | I118: Femenino | J118: Activo | K118: AERO 2°A | L118: 1
A119: LICENCIATURA | B119: CARLA | C119: CARPINTERO | D119: MERINO | E119: 110478 | F119: CARPINTERO MERINO CARLA | G119: INGENIERIA CIBERNETICA Y EN SISTEMAS COMPUTACIONALES | H119: 8vo | I119: Femenino | J119: Activo | K119: CIB 8° | L119: 1
A120: LICENCIATURA | B120: CARLOS ALONSO | C120: MORENO | D120: DIAZ | E120: 112218 | F120: MORENO DIAZ CARLOS ALONSO | G120: PSICOLOGIA | H120: 2do | I120: Masculino | J120: Activo | K120: PSI 2° | L120: 1
A121: LICENCIATURA | B121: CARLOS EDUARDO | C121: YERENA | D121: NAVARRO | E121: 007404 | F121: YERENA NAVARRO CARLOS EDUARDO | G121: PSICOLOGIA | H121: 8vo | I121: Masculino | J121: Activo | K121: PSI 8° | L121: 1
A122: LICENCIATURA | B122: CARLOS ERNESTO | C122: NAVARRO | D122: LESPRON | E122: 112346 | F122: NAVARRO LESPRON CARLOS ERNESTO | G122: ARQUITECTURA | H122: 2do | I122: Masculino | J122: Activo | K122: ARQ 2° | L122: 1
A123: LICENCIATURA | B123: CARLOS FERNANDO | C123: SERRANO | D123: AMADOR | E123: 111208 | F123: SERRANO AMADOR CARLOS FERNANDO | G123: INGENIERÍA EN INTELIGENCIA ARTIFICIAL | H123: 6to | I123: Masculino | J123: Activo | K123: IA 6° | L123: 1
A124: LICENCIATURA | B124: CARLOS IVAN | C124: FLORES | D124: GUTIERREZ | E124: 110559 | F124: FLORES GUTIERREZ CARLOS IVAN | G124: ANIMACION DIGITAL Y VIDEOJUEGOS | H124: 8vo | I124: Masculino | J124: Activo | K124: ANIM 8° | L124: 1
A125: LICENCIATURA | B125: CARLOS OSVALDO | C125: MEDINA | D125: DIAZ | E125: 112201 | F125: MEDINA DIAZ CARLOS OSVALDO | G125: INGENIERÍA AUTOMOTRIZ | H125: 2do | I125: Masculino | J125: Activo | K125: AUTO 2° B | L125: 1
A126: LICENCIATURA | B126: CARLOS ROBERTO | C126: RAMIREZ | D126: GARCIA | E126: 110498 | F126: RAMIREZ GARCIA CARLOS ROBERTO | G126: ANIMACION DIGITAL Y VIDEOJUEGOS | H126: 8vo | I126: Masculino | J126: Activo | K126: ANIM 8° | L126: 1
A127: LICENCIATURA | B127: CARLOS SANTIAGO | C127: PEREZ | D127: DIEZ | E127: 111663 | F127: PEREZ DIEZ CARLOS SANTIAGO | G127: INGENIERIA AEROESPACIAL | H127: 4to | I127: Masculino | J127: Activo | K127: AERO 4°B | L127: 1
A128: LICENCIATURA | B128: CAROL MARIAN | C128: CASTILLO | D128: MUNGUIA | E128: 109970 | F128: CASTILLO MUNGUIA CAROL MARIAN | G128: INGENIERIA AEROESPACIAL | H128: 10mo | I128: Femenino | J128: Activo | K128: AERO_10° | L128: 1
A129: LICENCIATURA | B129: CAROL NOEMI | C129: HURTADO | D129: MACIAS | E129: 110423 | F129: HURTADO MACIAS CAROL NOEMI | G129: ANIMACION DIGITAL Y VIDEOJUEGOS | H129: 8vo | I129: Femenino | J129: Activo | K129: ANIM 8° | L129: 1
A130: LICENCIATURA | B130: CAROL VANESSA | C130: CAMARGO | D130: CARMONA | E130: 112237 | F130: CAMARGO CARMONA CAROL VANESSA | G130: INGENIERÍA AUTOMOTRIZ | H130: 2do | I130: Femenino | J130: Activo | K130: AUTO 2° A | L130: 1
... A169: LICENCIATURA | B169: DARIA MADAI | C169: ALCARAZ | D169: ARROYO | E169: 112215 | F169: ALCARAZ ARROYO DARIA MADAI | G169: INGENIERIA AEROESPACIAL | H169: 2do | I169: Femenino | J169: Activo | K169: AERO 2°A | L169: 1
A170: LICENCIATURA | B170: DARIO | C170: AGUILAR | E170: 111170 | F170: AGUILAR DARIO | G170: INGENIERÍA AUTOMOTRIZ | H170: 6to | I170: Masculino | J170: Activo | K170: AUTO 6° | L170: 1
A171: LICENCIATURA | B171: DARSHAN GAEL | C171: ORTIZ | D171: ARIZA | E171: 110477 | F171: ORTIZ ARIZA DARSHAN GAEL | G171: NUTRICION Y GASTRONOMIA | H171: 8vo | I171: Masculino | J171: Activo | K171: NUT 8° | L171: 1
A172: LICENCIATURA | B172: DAVID | C172: ARECHEDERRA | D172: TREJO | E172: 006890 | F172: ARECHEDERRA TREJO DAVID | G172: INGENIERIA CIBERNETICA Y EN SISTEMAS COMPUTACIONALES | H172: 8vo | I172: Masculino | J172: Activo | K172: CIB 8° | L172: 1
A173: LICENCIATURA | B173: DAVID | C173: WILSON | D173: TORRES | E173: 110508 | F173: WILSON TORRES DAVID | G173: INGENIERIA AEROESPACIAL | H173: 8vo | I173: Masculino | J173: Activo | K173: AERO 8° | L173: 1
A174: LICENCIATURA | B174: DAVID ISRAEL | C174: ALVAREZ | D174: JIMENEZ | E174: 108218 | F174: ALVAREZ JIMENEZ DAVID ISRAEL | G174: INGENIERIA AEROESPACIAL | H174: 8vo | I174: Masculino | J174: Activo | K174: AERO 8° | L174: 1
A175: LICENCIATURA | B175: DAVID IVAN | C175: CARRANZA | D175: BARBA | E175: 110464 | F175: CARRANZA BARBA DAVID IVAN | G175: ARQUITECTURA | H175: 8vo | I175: Masculino | J175: Activo | K175: ARQ 8° | L175: 1
A176: LICENCIATURA | B176: DAVID RICARDO | C176: MONTERO | D176: JARAMILLO | E176: 112298 | F176: MONTERO JARAMILLO DAVID RICARDO | G176: ANIMACION DIGITAL Y VIDEOJUEGOS | H176: 2do | I176: Masculino | J176: Activo | K176: ANIM 2° | L176: 1
A177: LICENCIATURA | B177: DAYRA MICHELLE | C177: ZUÑIGA | D177: HERNANDEZ | E177: 111764 | F177: ZUÑIGA HERNANDEZ DAYRA MICHELLE | G177: ADMINISTRACION Y DIRECCION DE NEGOCIOS | H177: 4to | I177: Femenino | J177: Activo | K177: ADMON 4° | L177: 1
A178: LICENCIATURA | B178: DENZZEL | C178: DE LOS SANTOS | D178: DOMINGUEZ | E178: 112318 | F178: DE LOS SANTOS DOMINGUEZ DENZZEL | G178: INGENIERÍA AUTOMOTRIZ | H178: 2do | I178: Masculino | J178: Activo | K178: AUTO 2° A | L178: 1
A179: LICENCIATURA | B179: DIANA PAOLA | C179: CORONADO | D179: TIRADO | E179: 111201 | F179: CORONADO TIRADO DIANA PAOLA | G179: INGENIERÍA EN INTELIGENCIA ARTIFICIAL | H179: 6to | I179: Femenino | J179: Activo | K179: IA 6° | L179: 1
A180: LICENCIATURA | B180: DIANA PAULA | C180: DE ALVA | D180: COVARRUBIAS | E180: 110430 | F180: DE ALVA COVARRUBIAS DIANA PAULA | G180: ARQUITECTURA | H180: 8vo | I180: Femenino | J180: Activo | K180: ARQ 8° | L180: 1
A181: LICENCIATURA | B181: DIANA SARAHI | C181: RAMIREZ | D181: TABAREZ | E181: 111053 | F181: RAMIREZ TABAREZ DIANA SARAHI | G181: PSICOLOGIA | H181: 6to | I181: Femenino | J181: Activo | K181: PSI 6° | L181: 1
...

Sheet Alumnos
A1: Nivel | B1: Nombre Alumno | C1: A. Paterno Alumno | D1: A. Materno Alumno | E1: Correo | F1: Matrícula | G1: clave | H1: Nombre | I1: Carrera | J1: Grado | K1: Sexo | L1: Situación | M1: Grupo
A2: LICENCIATURA | B2: ABBY DESSIRE | C2: PELAYO | D2: DIAZ | E2: abbydessire.pelayodiaz | F2: =CONCATENATE("'",Sheet!E2) -> '111772 | G2: TOMAR DEL SND | H2: =Sheet!F2 -> PELAYO DIAZ ABBY DESSIRE | I2: =Sheet!G2 -> NUTRICION Y GASTRONOMIA | J2: =Sheet!H2 -> 4to | K2: =Sheet!I2 -> Femenino | L2: =Sheet!J2 -> Activo | M2: =Sheet!K2 -> NUT 4°
A3: LICENCIATURA | B3: ABIGAIL | C3: MENDOZA | D3: VILLELA | E3: abigail.mendozavillela | F3: =CONCATENATE("'",Sheet!E3) -> '112156 | G3: TOMAR DEL SND | H3: =Sheet!F3 -> MENDOZA VILLELA ABIGAIL | I3: =Sheet!G3 -> PSICOLOGIA | J3: =Sheet!H3 -> 2do | K3: =Sheet!I3 -> Femenino | L3: =Sheet!J3 -> Activo | M3: =Sheet!K3 -> PSI 2°
A4: LICENCIATURA | B4: ABRIL ISABELLA | C4: GODOY | D4: FLORES | E4: abrilisabella.godoyflores | F4: =CONCATENATE("'",Sheet!E4) -> '111103 | G4: TOMAR DEL SND | H4: =Sheet!F4 -> GODOY FLORES ABRIL ISABELLA | I4: =Sheet!G4 -> INGENIERIA CIBERNETICA Y EN SISTEMAS COMPUTACIONALES | J4: =Sheet!H4 -> 6to | K4: =Sheet!I4 -> Femenino | L4: =Sheet!J4 -> Activo | M4: =Sheet!K4 -> CIB 6°
A5: LICENCIATURA | B5: ADAN OSWALDO | C5: SANDOVAL | D5: CARDENAS | E5: adanoswaldo.sandovalcardenas | F5: =CONCATENATE("'",Sheet!E5) -> '111031 | G5: TOMAR DEL SND | H5: =Sheet!F5 -> SANDOVAL CARDENAS ADAN OSWALDO | I5: =Sheet!G5 -> INGENIERIA AEROESPACIAL | J5: =Sheet!H5 -> 6to | K5: =Sheet!I5 -> Masculino | L5: =Sheet!J5 -> Activo | M5: =Sheet!K5 -> AERO 6°
A6: LICENCIATURA | B6: ADIB KALEB | C6: GONZALEZ | D6: TOSCANO | E6: adibkaleb.gonzaleztoscano | F6: =CONCATENATE("'",Sheet!E6) -> '110517 | G6: TOMAR DEL SND | H6: =Sheet!F6 -> GONZALEZ TOSCANO ADIB KALEB | I6: =Sheet!G6 -> INGENIERIA AEROESPACIAL | J6: =Sheet!H6 -> 8vo | K6: =Sheet!I6 -> Masculino | L6: =Sheet!J6 -> Activo | M6: =Sheet!K6 -> AERO 8°
A7: LICENCIATURA | B7: ADOLFO ALEXANDER | C7: VEGA | D7: RUELAS | E7: adolfoalexander.vegaruelas | F7: =CONCATENATE("'",Sheet!E7) -> '112194 | G7: TOMAR DEL SND | H7: =Sheet!F7 -> VEGA RUELAS ADOLFO ALEXANDER | I7: =Sheet!G7 -> INGENIERÍA AUTOMOTRIZ | J7: =Sheet!H7 -> 2do | K7: =Sheet!I7 -> Masculino | L7: =Sheet!J7 -> Activo | M7: =Sheet!K7 -> AUTO 2° A
A8: LICENCIATURA | B8: ADRIAN | C8: ESQUEDA | D8: MACIAS | E8: adrian.esquedamacias | F8: =CONCATENATE("'",Sheet!E8) -> '109814 | G8: TOMAR DEL SND | H8: =Sheet!F8 -> ESQUEDA MACIAS ADRIAN | I8: =Sheet!G8 -> INGENIERIA AEROESPACIAL | J8: =Sheet!H8 -> 10mo | K8: =Sheet!I8 -> Masculino | L8: =Sheet!J8 -> Activo | M8: =Sheet!K8 -> AERO_10°
A9: LICENCIATURA | B9: ADRIAN | C9: JAIME | D9: OJEDA | E9: adrian.jaimeojeda | F9: =CONCATENATE("'",Sheet!E9) -> '111784 | G9: TOMAR DEL SND | H9: =Sheet!F9 -> JAIME OJEDA ADRIAN | I9: =Sheet!G9 -> INGENIERÍA AUTOMOTRIZ | J9: =Sheet!H9 -> 4to | K9: =Sheet!I9 -> Masculino | L9: =Sheet!J9 -> Activo | M9: =Sheet!K9 -> AUTO 4°
A10: LICENCIATURA | B10: ADRIAN ASSIS | C10: TAPIA | D10: CORRIPIO | E10: adrianassis.tapiacorripio | F10: =CONCATENATE("'",Sheet!E10) -> '109374 | G10: TOMAR DEL SND | H10: =Sheet!F10 -> TAPIA CORRIPIO ADRIAN ASSIS | I10: =Sheet!G10 -> INGENIERIA AEROESPACIAL | J10: =Sheet!H10 -> 6to | K10: =Sheet!I10 -> Masculino | L10: =Sheet!J10 -> Activo | M10: =Sheet!K10 -> AERO 6°
A11: LICENCIATURA | B11: ADRIAN BRYANT | C11: VEGA | D11: CASTAÑEDA | E11: adrianbryant.vegacastaneda | F11: =CONCATENATE("'",Sheet!E11) -> '111793 | G11: TOMAR DEL SND | H11: =Sheet!F11 -> VEGA CASTAÑEDA ADRIAN BRYANT | I11: =Sheet!G11 -> PSICOLOGIA | J11: =Sheet!H11 -> 4to | K11: =Sheet!I11 -> Masculino | L11: =Sheet!J11 -> Activo | M11: =Sheet!K11 -> PSI 4°
A12: LICENCIATURA | B12: ADRIAN ENRIQUE | C12: MORALES | D12: ORTIZ | E12: adrianenrique.moralesortiz | F12: =CONCATENATE("'",Sheet!E12) -> '112223 | G12: TOMAR DEL SND | H12: =Sheet!F12 -> MORALES ORTIZ ADRIAN ENRIQUE | I12: =Sheet!G12 -> INGENIERIA AEROESPACIAL | J12: =Sheet!H12 -> 2do | K12: =Sheet!I12 -> Masculino | L12: =Sheet!J12 -> Activo | M12: =Sheet!K12 -> AERO 2°A
A13: LICENCIATURA | B13: ADRIANA | C13: AMARO | D13: BALTIERRA | E13: adriana.amarobaltierra | F13: =CONCATENATE("'",Sheet!E13) -> '111068 | G13: TOMAR DEL SND | H13: =Sheet!F13 -> AMARO BALTIERRA ADRIANA | I13: =Sheet!G13 -> INGENIERIA AEROESPACIAL | J13: =Sheet!H13 -> 6to | K13: =Sheet!I13 -> Femenino | L13: =Sheet!J13 -> Activo | M13: =Sheet!K13 -> AERO 6°
... A288: LICENCIATURA | B288: JAAZIEL ALEJANDRO | C288: MORENO | D288: TOSCANO | E288: jaazielalejandro.morenotoscano | F288: =CONCATENATE("'",Sheet!E288) -> '110570 | G288: TOMAR DEL SND | H288: =Sheet!F288 -> MORENO TOSCANO JAAZIEL ALEJANDRO | I288: =Sheet!G288 -> INGENIERIA AEROESPACIAL | J288: =Sheet!H288 -> 8vo | K288: =Sheet!I288 -> Masculino | L288: =Sheet!J288 -> Activo | M288: =Sheet!K288 -> AERO 8°
A289: LICENCIATURA | B289: JACKELINE | C289: HERNANDEZ | E289: jackeline.hernandez | F289: =CONCATENATE("'",Sheet!E289) -> '111213 | G289: TOMAR DEL SND | H289: =Sheet!F289 -> HERNANDEZ JACKELINE | I289: =Sheet!G289 -> ARQUITECTURA | J289: =Sheet!H289 -> 6to | K289: =Sheet!I289 -> Femenino | L289: =Sheet!J289 -> Activo | M289: =Sheet!K289 -> ARQ 6°
A290: LICENCIATURA | B290: JACOBO | C290: NUÑEZ | D290: VEGA | E290: jacobo.nunezvega | F290: =CONCATENATE("'",Sheet!E290) -> '112211 | G290: TOMAR DEL SND | H290: =Sheet!F290 -> NUÑEZ VEGA JACOBO | I290: =Sheet!G290 -> INGENIERIA AEROESPACIAL | J290: =Sheet!H290 -> 2do | K290: =Sheet!I290 -> Masculino | L290: =Sheet!J290 -> Activo | M290: =Sheet!K290 -> AERO 2°B
A291: LICENCIATURA | B291: JADYN | C291: MEZA | D291: CORTES | E291: jadyn.mezacortes | F291: =CONCATENATE("'",Sheet!E291) -> '110425 | G291: TOMAR DEL SND | H291: =Sheet!F291 -> MEZA CORTES JADYN | I291: =Sheet!G291 -> ANIMACION DIGITAL Y VIDEOJUEGOS | J291: =Sheet!H291 -> 8vo | K291: =Sheet!I291 -> Femenino | L291: =Sheet!J291 -> Activo | M291: =Sheet!K291 -> ANIM 8°
A292: LICENCIATURA | B292: JAIME EMMANUEL | C292: GUTIERREZ | D292: AVILA | E292: jaimeemmanuel.gutierrezavila | F292: =CONCATENATE("'",Sheet!E292) -> '109993 | G292: TOMAR DEL SND | H292: =Sheet!F292 -> GUTIERREZ AVILA JAIME EMMANUEL | I292: =Sheet!G292 -> INGENIERIA AEROESPACIAL | J292: =Sheet!H292 -> 10mo | K292: =Sheet!I292 -> Masculino | L292: =Sheet!J292 -> Activo | M292: =Sheet!K292 -> AERO_10°
A293: LICENCIATURA | B293: JAIME GABRIEL | C293: MUÑOZ | D293: SANDOVAL | E293: jaimegabriel.munozsandoval | F293: =CONCATENATE("'",Sheet!E293) -> '111762 | G293: TOMAR DEL SND | H293: =Sheet!F293 -> MUÑOZ SANDOVAL JAIME GABRIEL | I293: =Sheet!G293 -> INGENIERIA AEROESPACIAL | J293: =Sheet!H293 -> 4to | K293: =Sheet!I293 -> Masculino | L293: =Sheet!J293 -> Activo | M293: =Sheet!K293 -> AERO 4°B
A294: LICENCIATURA | B294: JANETH | C294: QUESNEY | D294: CABRERA | E294: janeth.quesneycabrera | F294: =CONCATENATE("'",Sheet!E294) -> '111731 | G294: TOMAR DEL SND | H294: =Sheet!F294 -> QUESNEY CABRERA JANETH | I294: =Sheet!G294 -> ANIMACION DIGITAL Y VIDEOJUEGOS | J294: =Sheet!H294 -> 4to | K294: =Sheet!I294 -> Femenino | L294: =Sheet!J294 -> Activo | M294: =Sheet!K294 -> ANIM 4°
A295: LICENCIATURA | B295: JARED ESAU | C295: VALLADOLID | D295: GARCIA | E295: jaredesau.valladolidgarcia | F295: =CONCATENATE("'",Sheet!E295) -> '112302 | G295: TOMAR DEL SND | H295: =Sheet!F295 -> VALLADOLID GARCIA JARED ESAU | I295: =Sheet!G295 -> INGENIERIA AEROESPACIAL | J295: =Sheet!H295 -> 2do | K295: =Sheet!I295 -> Masculino | L295: =Sheet!J295 -> Activo | M295: =Sheet!K295 -> AERO 2°A
A296: LICENCIATURA | B296: JAVIER | C296: AYALA | D296: ESPARZA | E296: javier.ayalaesparza | F296: =CONCATENATE("'",Sheet!E296) -> '111171 | G296: TOMAR DEL SND | H296: =Sheet!F296 -> AYALA ESPARZA JAVIER | I296: =Sheet!G296 -> INGENIERÍA AUTOMOTRIZ | J296: =Sheet!H296 -> 6to | K296: =Sheet!I296 -> Masculino | L296: =Sheet!J296 -> Activo | M296: =Sheet!K296 -> AUTO 6°
A297: LICENCIATURA | B297: JAVIER | C297: HERNANDEZ | D297: RENDON | E297: javier.hernandezrendon | F297: =CONCATENATE("'",Sheet!E297) -> '110442 | G297: TOMAR DEL SND | H297: =Sheet!F297 -> HERNANDEZ RENDON JAVIER | I297: =Sheet!G297 -> PSICOLOGIA | J297: =Sheet!H297 -> 8vo | K297: =Sheet!I297 -> Masculino | L297: =Sheet!J297 -> Activo | M297: =Sheet!K297 -> PSI 8°
A298: LICENCIATURA | B298: JAVIER ALEJANDRO | C298: CORONA | D298: HERNANDEZ | E298: javieralejandro.coronahernandez | F298: =CONCATENATE("'",Sheet!E298) -> '112189 | G298: TOMAR DEL SND | H298: =Sheet!F298 -> CORONA HERNANDEZ JAVIER ALEJANDRO | I298: =Sheet!G298 -> INGENIERÍA AUTOMOTRIZ | J298: =Sheet!H298 -> 2do | K298: =Sheet!I298 -> Masculino | L298: =Sheet!J298 -> Activo | M298: =Sheet!K298 -> AUTO 2° B
A299: LICENCIATURA | B299: JAVIER ANDRES | C299: ARIAS | D299: ESCOBAR | E299: javierandres.ariasescobar | F299: =CONCATENATE("'",Sheet!E299) -> '111330 | G299: TOMAR DEL SND | H299: =Sheet!F299 -> ARIAS ESCOBAR JAVIER ANDRES | I299: =Sheet!G299 -> ANIMACION DIGITAL Y VIDEOJUEGOS | J299: =Sheet!H299 -> 4to | K299: =Sheet!I299 -> Masculino | L299: =Sheet!J299 -> Activo | M299: =Sheet!K299 -> ANIM 4°
A300: LICENCIATURA | B300: JAVIER ANTONIO | C300: MARISCAL | D300: REYES | E300: javierantonio.mariscalreyes | F300: =CONCATENATE("'",Sheet!E300) -> '111613 | G300: TOMAR DEL SND | H300: =Sheet!F300 -> MARISCAL REYES JAVIER ANTONIO | I300: =Sheet!G300 -> INGENIERIA AEROESPACIAL | J300: =Sheet!H300 -> 4to | K300: =Sheet!I300 -> Masculino | L300: =Sheet!J300 -> Activo | M300: =Sheet!K300 -> AERO 4°B
A301: LICENCIATURA | B301: JAVIER EDUARDO | C301: AGUILAR | D301: LUGO | E301: javiereduardo.aguilarlugo | F301: =CONCATENATE("'",Sheet!E301) -> '109958 | G301: TOMAR DEL SND | H301: =Sheet!F301 -> AGUILAR LUGO JAVIER EDUARDO | I301: =Sheet!G301 -> INGENIERIA AEROESPACIAL | J301: =Sheet!H301 -> 10mo | K301: =Sheet!I301 -> Masculino | L301: =Sheet!J301 -> Activo | M301: =Sheet!K301 -> AERO_10°
... A475: LICENCIATURA | B475: MICHELLE CAROLINA | C475: OCHOA | D475: GONZALEZ | E475: michellecarolina.ochoagonzalez | F475: =CONCATENATE("'",Sheet!E475) -> '111189 | G475: TOMAR DEL SND | H475: =Sheet!F475 -> OCHOA GONZALEZ MICHELLE CAROLINA | I475: =Sheet!G475 -> ARQUITECTURA | J475: =Sheet!H475 -> 6to | K475: =Sheet!I475 -> Femenino | L475: =Sheet!J475 -> Activo | M475: =Sheet!K475 -> ARQ 6°
A476: LICENCIATURA | B476: MIGUEL | C476: DELGADO | E476: miguel.delgado | F476: =CONCATENATE("'",Sheet!E476) -> '111610 | G476: TOMAR DEL SND | H476: =Sheet!F476 -> DELGADO MIGUEL | I476: =Sheet!G476 -> INGENIERIA AEROESPACIAL | J476: =Sheet!H476 -> 4to | K476: =Sheet!I476 -> Masculino | L476: =Sheet!J476 -> Activo | M476: =Sheet!K476 -> AERO 4°A
A477: LICENCIATURA | B477: MIGUEL ANGEL | C477: NUÑO | D477: ARANA | E477: miguelangel.nunoarana | F477: =CONCATENATE("'",Sheet!E477) -> '112236 | G477: TOMAR DEL SND | H477: =Sheet!F477 -> NUÑO ARANA MIGUEL ANGEL | I477: =Sheet!G477 -> INGENIERÍA EN INTELIGENCIA ARTIFICIAL | J477: =Sheet!H477 -> 2do | K477: =Sheet!I477 -> Masculino | L477: =Sheet!J477 -> Activo | M477: =Sheet!K477 -> IA 2°
A478: LICENCIATURA | B478: MIGUEL ANGEL SNAYDER | C478: RUIZ | D478: GAMARRA | E478: miguelangelsnayder.ruizgamarra | F478: =CONCATENATE("'",Sheet!E478) -> '112251 | G478: TOMAR DEL SND | H478: =Sheet!F478 -> RUIZ GAMARRA MIGUEL ANGEL SNAYDER | I478: =Sheet!G478 -> ANIMACION DIGITAL Y VIDEOJUEGOS | J478: =Sheet!H478 -> 2do | K478: =Sheet!I478 -> Masculino | L478: =Sheet!J478 -> Activo | M478: =Sheet!K478 -> ANIM 2°
A479: LICENCIATURA | B479: MIRANDA CAROLINA | C479: LOPEZ | D479: VARGAS | E479: mirandacarolina.lopezvargas | F479: =CONCATENATE("'",Sheet!E479) -> '111746 | G479: TOMAR DEL SND | H479: =Sheet!F479 -> LOPEZ VARGAS MIRANDA CAROLINA | I479: =Sheet!G479 -> INGENIERIA AEROESPACIAL | J479: =Sheet!H479 -> 4to | K479: =Sheet!I479 -> Femenino | L479: =Sheet!J479 -> Activo | M479: =Sheet!K479 -> AERO 4°A
A480: LICENCIATURA | B480: MIRIAM ALEJANDRA | C480: RODRIGUEZ | D480: MARTINEZ | E480: miriamalejandra.rodriguezmartinez | F480: =CONCATENATE("'",Sheet!E480) -> '111824 | G480: TOMAR DEL SND | H480: =Sheet!F480 -> RODRIGUEZ MARTINEZ MIRIAM ALEJANDRA | I480: =Sheet!G480 -> NUTRICION Y GASTRONOMIA | J480: =Sheet!H480 -> 4to | K480: =Sheet!I480 -> Femenino | L480: =Sheet!J480 -> Activo | M480: =Sheet!K480 -> NUT 4°
A481: LICENCIATURA | B481: MONICA ALEJANDRA | C481: GONZALEZ | D481: BLANCO | E481: monicaalejandra.gonzalezblanco | F481: =CONCATENATE("'",Sheet!E481) -> '007662 | G481: TOMAR DEL SND | H481: =Sheet!F481 -> GONZALEZ BLANCO MONICA ALEJANDRA | I481: =Sheet!G481 -> ANIMACION DIGITAL Y VIDEOJUEGOS | J481: =Sheet!H481 -> 6to | K481: =Sheet!I481 -> Femenino | L481: =Sheet!J481 -> Activo | M481: =Sheet!K481 -> ANIM 6°
A482: LICENCIATURA | B482: MONTSERRAT | C482: HERRERA | D482: DUEÑAS | E482: montserrat.herreraduenas | F482: =CONCATENATE("'",Sheet!E482) -> '110443 | G482: TOMAR DEL SND | H482: =Sheet!F482 -> HERRERA DUEÑAS MONTSERRAT | I482: =Sheet!G482 -> PSICOLOGIA | J482: =Sheet!H482 -> 8vo | K482: =Sheet!I482 -> Femenino | L482: =Sheet!J482 -> Activo | M482: =Sheet!K482 -> PSI 8°
A483: LICENCIATURA | B483: MONTSERRAT | C483: MIRANDA | D483: DIAZ | E483: montserrat.mirandadiaz | F483: =CONCATENATE("'",Sheet!E483) -> '110426 | G483: TOMAR DEL SND | H483: =Sheet!F483 -> MIRANDA DIAZ MONTSERRAT | I483: =Sheet!G483 -> ANIMACION DIGITAL Y VIDEOJUEGOS | J483: =Sheet!H483 -> 8vo | K483: =Sheet!I483 -> Femenino | L483: =Sheet!J483 -> Activo | M483: =Sheet!K483 -> ANIM 8°
A484: LICENCIATURA | B484: MYRIAM SOFIA | C484: ESQUIVEL | D484: ENCARNACION | E484: myriamsofia.esquivelencarnacion | F484: =CONCATENATE("'",Sheet!E484) -> '111028 | G484: TOMAR DEL SND | H484: =Sheet!F484 -> ESQUIVEL ENCARNACION MYRIAM SOFIA | I484: =Sheet!G484 -> ARQUITECTURA | J484: =Sheet!H484 -> 6to | K484: =Sheet!I484 -> Femenino | L484: =Sheet!J484 -> Activo | M484: =Sheet!K484 -> ARQ 6°
A485: LICENCIATURA | B485: NAOMI DANAI | C485: RAMIREZ | D485: HIDALGO | E485: naomidanai.ramirezhidalgo | F485: =CONCATENATE("'",Sheet!E485) -> '112167 | G485: TOMAR DEL SND | H485: =Sheet!F485 -> RAMIREZ HIDALGO NAOMI DANAI | I485: =Sheet!G485 -> ARQUITECTURA | J485: =Sheet!H485 -> 2do | K485: =Sheet!I485 -> Femenino | L485: =Sheet!J485 -> Activo | M485: =Sheet!K485 -> ARQ 2°
A486: LICENCIATURA | B486: NAOMI JIMENA | C486: HERNANDEZ | D486: GARCIA | E486: naomijimena.hernandezgarcia | F486: =CONCATENATE("'",Sheet!E486) -> '110645 | G486: TOMAR DEL SND | H486: =Sheet!F486 -> HERNANDEZ GARCIA NAOMI JIMENA | I486: =Sheet!G486 -> PSICOLOGIA | J486: =Sheet!H486 -> 8vo | K486: =Sheet!I486 -> Femenino | L486: =Sheet!J486 -> Activo | M486: =Sheet!K486 -> PSI 8°
A487: LICENCIATURA | B487: NATALIA | C487: ESQUER | D487: QUINTANILLA | E487: natalia.esquerquintanilla | F487: =CONCATENATE("'",Sheet!E487) -> '111122 | G487: TOMAR DEL SND | H487: =Sheet!F487 -> ESQUER QUINTANILLA NATALIA | I487: =Sheet!G487 -> NUTRICION Y GASTRONOMIA | J487: =Sheet!H487 -> 6to | K487: =Sheet!I487 -> Femenino | L487: =Sheet!J487 -> Activo | M487: =Sheet!K487 -> NUT 6°
...

Sheet Participantes
A1: ID | B1: Nivel | C1: Correo | D1: Matrícula | E1: Clave | F1: Nombre | G1: Carrera | H1: Grado | I1: Sexo | J1: Situación | K1: =CONCATENATE("INSERT INTO participantes (",L1,") VALUES (") -> INSERT INTO participantes (id,nivel,correo,matricula,clave,nombre,carrera,grado,sexo,situacion,evaluados,num_evaluados,total_evaluaciones,ultimo_acceso,nivel_acceso) VALUES ( | L1: id,nivel,correo,matricula,clave,nombre,carrera,grado,sexo,situacion,evaluados,num_evaluados,total_evaluaciones,ultimo_acceso,nivel_acceso
A2: 1001 | B2: 'LICENCIATURA' | C2: =CONCATENATE("'",Alumnos!E2,"'") -> 'abbydessire.pelayodiaz' | D2: =CONCATENATE(Alumnos!F2,"'") -> '111772' | E2: TOMAR DEL SND' | F2: =CONCATENATE("'",Alumnos!H2,"'") -> 'PELAYO DIAZ ABBY DESSIRE' | G2: =CONCATENATE("'",Alumnos!I2,"'") -> 'NUTRICION Y GASTRONOMIA' | H2: =CONCATENATE("'",Alumnos!J2,"'") -> '4to' | I2: =UPPER(CONCATENATE("'",Alumnos!K2,"'")) -> 'FEMENINO' | J2: =UPPER(CONCATENATE("'",Alumnos!L2,"'")) -> 'ACTIVO' | K2: =CONCATENATE(A2,",",B2,",",C2,",",D2,",'",E2,",",F2,",",G2,",",H2,",",UPPER(I2),",",UPPER(J2),",'',0,0,'','ALUMNO'") -> 1001,'LICENCIATURA','abbydessire.pelayodiaz','111772','TOMAR DEL SND','PELAYO DIAZ ABBY DESSIRE','NUTRICION Y GASTRONOMIA','4to','FEMENINO','ACTIVO','',0,0,'','ALUMNO' | L2: =CONCATENATE($K$1,K2,");") -> INSERT INTO participantes (id,nivel,correo,matricula,clave,nombre,carrera,grado,sexo,situacion,evaluados,num_evaluados,total_evaluaciones,ultimo_acceso,nivel_acceso) VALUES (1001,'LICENCIATURA','abbydessire.pelayodiaz','111772','TOMAR DEL SND','PELAYO DIAZ ABBY DESSIRE','NUTRICION Y GASTRONOMIA','4to','FEMENINO','ACTIVO','',0,0,'','ALUMNO'); | M2: =CONCATENATE("update participantes set correo=",C2," where id=",A2,";") -> update participantes set correo='abbydessire.pelayodiaz' where id=1001;
A3: 1002 | B3: 'LICENCIATURA' | C3: =CONCATENATE("'",Alumnos!E143,"'") -> 'cristian.villarruelsandoval' | D3: =CONCATENATE(Alumnos!F143,"'") -> '111773' | E3: TOMAR DEL SND' | F3: =CONCATENATE("'",Alumnos!H143,"'") -> 'VILLARRUEL SANDOVAL CRISTIAN' | G3: =CONCATENATE("'",Alumnos!I143,"'") -> 'ADMINISTRACION Y DIRECCION DE NEGOCIOS' | H3: =CONCATENATE("'",Alumnos!J143,"'") -> '4to' | I3: =UPPER(CONCATENATE("'",Alumnos!K143,"'")) -> 'MASCULINO' | J3: =UPPER(CONCATENATE("'",Alumnos!L143,"'")) -> 'ACTIVO' | K3: =CONCATENATE(A3,",",B3,",",C3,",",D3,",'",E3,",",F3,",",G3,",",H3,",",UPPER(I3),",",UPPER(J3),",'',0,0,'','ALUMNO'") -> 1002,'LICENCIATURA','cristian.villarruelsandoval','111773','TOMAR DEL SND','VILLARRUEL SANDOVAL CRISTIAN','ADMINISTRACION Y DIRECCION DE NEGOCIOS','4to','MASCULINO','ACTIVO','',0,0,'','ALUMNO' | L3: =CONCATENATE($K$1,K3,");") -> INSERT INTO participantes (id,nivel,correo,matricula,clave,nombre,carrera,grado,sexo,situacion,evaluados,num_evaluados,total_evaluaciones,ultimo_acceso,nivel_acceso) VALUES (1002,'LICENCIATURA','cristian.villarruelsandoval','111773','TOMAR DEL SND','VILLARRUEL SANDOVAL CRISTIAN','ADMINISTRACION Y DIRECCION DE NEGOCIOS','4to','MASCULINO','ACTIVO','',0,0,'','ALUMNO'); | M3: =CONCATENATE("update participantes set correo=",C3," where id=",A3,";") -> update participantes set correo='cristian.villarruelsandoval' where id=1002;
A4: 1003 | B4: 'LICENCIATURA' | C4: =CONCATENATE("'",Alumnos!E262,"'") -> 'guillermojose.sosayavilagonzalez' | D4: =CONCATENATE(Alumnos!F262,"'") -> '111774' | E4: TOMAR DEL SND' | F4: =CONCATENATE("'",Alumnos!H262,"'") -> 'SOSA Y AVILA GONZALEZ GUILLERMO JOSE' | G4: =CONCATENATE("'",Alumnos!I262,"'") -> 'INGENIERIA AEROESPACIAL' | H4: =CONCATENATE("'",Alumnos!J262,"'") -> '4to' | I4: =UPPER(CONCATENATE("'",Alumnos!K262,"'")) -> 'MASCULINO' | J4: =UPPER(CONCATENATE("'",Alumnos!L262,"'")) -> 'ACTIVO' | K4: =CONCATENATE(A4,",",B4,",",C4,",",D4,",'",E4,",",F4,",",G4,",",H4,",",UPPER(I4),",",UPPER(J4),",'',0,0,'','ALUMNO'") -> 1003,'LICENCIATURA','guillermojose.sosayavilagonzalez','111774','TOMAR DEL SND','SOSA Y AVILA GONZALEZ GUILLERMO JOSE','INGENIERIA AEROESPACIAL','4to','MASCULINO','ACTIVO','',0,0,'','ALUMNO' | L4: =CONCATENATE($K$1,K4,");") -> INSERT INTO participantes (id,nivel,correo,matricula,clave,nombre,carrera,grado,sexo,situacion,evaluados,num_evaluados,total_evaluaciones,ultimo_acceso,nivel_acceso) VALUES (1003,'LICENCIATURA','guillermojose.sosayavilagonzalez','111774','TOMAR DEL SND','SOSA Y AVILA GONZALEZ GUILLERMO JOSE','INGENIERIA AEROESPACIAL','4to','MASCULINO','ACTIVO','',0,0,'','ALUMNO'); | M4: =CONCATENATE("update participantes set correo=",C4," where id=",A4,";") -> update participantes set correo='guillermojose.sosayavilagonzalez' where id=1003;
A5: 1004 | B5: 'LICENCIATURA' | C5: =CONCATENATE("'",Alumnos!E490,"'") -> 'natalia.ortizlopez' | D5: =CONCATENATE(Alumnos!F490,"'") -> '111777' | E5: TOMAR DEL SND' | F5: =CONCATENATE("'",Alumnos!H490,"'") -> 'ORTIZ LOPEZ NATALIA' | G5: =CONCATENATE("'",Alumnos!I490,"'") -> 'PSICOLOGIA' | H5: =CONCATENATE("'",Alumnos!J490,"'") -> '4to' | I5: =UPPER(CONCATENATE("'",Alumnos!K490,"'")) -> 'FEMENINO' | J5: =UPPER(CONCATENATE("'",Alumnos!L490,"'")) -> 'ACTIVO' | K5: =CONCATENATE(A5,",",B5,",",C5,",",D5,",'",E5,",",F5,",",G5,",",H5,",",UPPER(I5),",",UPPER(J5),",'',0,0,'','ALUMNO'") -> 1004,'LICENCIATURA','natalia.ortizlopez','111777','TOMAR DEL SND','ORTIZ LOPEZ NATALIA','PSICOLOGIA','4to','FEMENINO','ACTIVO','',0,0,'','ALUMNO' | L5: =CONCATENATE($K$1,K5,");") -> INSERT INTO participantes (id,nivel,correo,matricula,clave,nombre,carrera,grado,sexo,situacion,evaluados,num_evaluados,total_evaluaciones,ultimo_acceso,nivel_acceso) VALUES (1004,'LICENCIATURA','natalia.ortizlopez','111777','TOMAR DEL SND','ORTIZ LOPEZ NATALIA','PSICOLOGIA','4to','FEMENINO','ACTIVO','',0,0,'','ALUMNO'); | M5: =CONCATENATE("update participantes set correo=",C5," where id=",A5,";") -> update participantes set correo='natalia.ortizlopez' where id=1004;
A6: 1005 | B6: 'LICENCIATURA' | C6: =CONCATENATE("'",Alumnos!E604,"'") -> 'valeriaalejandra.estradagil' | D6: =CONCATENATE(Alumnos!F604,"'") -> '111778' | E6: TOMAR DEL SND' | F6: =CONCATENATE("'",Alumnos!H604,"'") -> 'ESTRADA GIL VALERIA ALEJANDRA' | G6: =CONCATENATE("'",Alumnos!I604,"'") -> 'ADMINISTRACION Y DIRECCION DE NEGOCIOS' | H6: =CONCATENATE("'",Alumnos!J604,"'") -> '4to' | I6: =UPPER(CONCATENATE("'",Alumnos!K604,"'")) -> 'FEMENINO' | J6: =UPPER(CONCATENATE("'",Alumnos!L604,"'")) -> 'ACTIVO' | K6: =CONCATENATE(A6,",",B6,",",C6,",",D6,",'",E6,",",F6,",",G6,",",H6,",",UPPER(I6),",",UPPER(J6),",'',0,0,'','ALUMNO'") -> 1005,'LICENCIATURA','valeriaalejandra.estradagil','111778','TOMAR DEL SND','ESTRADA GIL VALERIA ALEJANDRA','ADMINISTRACION Y DIRECCION DE NEGOCIOS','4to','FEMENINO','ACTIVO','',0,0,'','ALUMNO' | L6: =CONCATENATE($K$1,K6,");") -> INSERT INTO participantes (id,nivel,correo,matricula,clave,nombre,carrera,grado,sexo,situacion,evaluados,num_evaluados,total_evaluaciones,ultimo_acceso,nivel_acceso) VALUES (1005,'LICENCIATURA','valeriaalejandra.estradagil','111778','TOMAR DEL SND','ESTRADA GIL VALERIA ALEJANDRA','ADMINISTRACION Y DIRECCION DE NEGOCIOS','4to','FEMENINO','ACTIVO','',0,0,'','ALUMNO'); | M6: =CONCATENATE("update participantes set correo=",C6," where id=",A6,";") -> update participantes set correo='valeriaalejandra.estradagil' where id=1005;
A7: 1006 | B7: 'LICENCIATURA' | C7: =CONCATENATE("'",Alumnos!E474,"'") -> 'michelleanahi.navarrozapata' | D7: =CONCATENATE(Alumnos!F474,"'") -> '111779' | E7: TOMAR DEL SND' | F7: =CONCATENATE("'",Alumnos!H474,"'") -> 'NAVARRO ZAPATA MICHELLE ANAHI' | G7: =CONCATENATE("'",Alumnos!I474,"'") -> 'ANIMACION DIGITAL Y VIDEOJUEGOS' | H7: =CONCATENATE("'",Alumnos!J474,"'") -> '4to' | I7: =UPPER(CONCATENATE("'",Alumnos!K474,"'")) -> 'FEMENINO' | J7: =UPPER(CONCATENATE("'",Alumnos!L474,"'")) -> 'ACTIVO' | K7: =CONCATENATE(A7,",",B7,",",C7,",",D7,",'",E7,",",F7,",",G7,",",H7,",",UPPER(I7),",",UPPER(J7),",'',0,0,'','ALUMNO'") -> 1006,'LICENCIATURA','michelleanahi.navarrozapata','111779','TOMAR DEL SND','NAVARRO ZAPATA MICHELLE ANAHI','ANIMACION DIGITAL Y VIDEOJUEGOS','4to','FEMENINO','ACTIVO','',0,0,'','ALUMNO' | L7: =CONCATENATE($K$1,K7,");") -> INSERT INTO participantes (id,nivel,correo,matricula,clave,nombre,carrera,grado,sexo,situacion,evaluados,num_evaluados,total_evaluaciones,ultimo_acceso,nivel_acceso) VALUES (1006,'LICENCIATURA','michelleanahi.navarrozapata','111779','TOMAR DEL SND','NAVARRO ZAPATA MICHELLE ANAHI','ANIMACION DIGITAL Y VIDEOJUEGOS','4to','FEMENINO','ACTIVO','',0,0,'','ALUMNO'); | M7: =CONCATENATE("update participantes set correo=",C7," where id=",A7,";") -> update participantes set correo='michelleanahi.navarrozapata' where id=1006;
A8: 1007 | B8: 'LICENCIATURA' | C8: =CONCATENATE("'",Alumnos!E337,"'") -> 'joseluis.hortasoltero' | D8: =CONCATENATE(Alumnos!F337,"'") -> '111783' | E8: TOMAR DEL SND' | F8: =CONCATENATE("'",Alumnos!H337,"'") -> 'HORTA SOLTERO JOSE LUIS' | G8: =CONCATENATE("'",Alumnos!I337,"'") -> 'INGENIERÍA AUTOMOTRIZ' | H8: =CONCATENATE("'",Alumnos!J337,"'") -> '4to' | I8: =UPPER(CONCATENATE("'",Alumnos!K337,"'")) -> 'MASCULINO' | J8: =UPPER(CONCATENATE("'",Alumnos!L337,"'")) -> 'ACTIVO' | K8: =CONCATENATE(A8,",",B8,",",C8,",",D8,",'",E8,",",F8,",",G8,",",H8,",",UPPER(I8),",",UPPER(J8),",'',0,0,'','ALUMNO'") -> 1007,'LICENCIATURA','joseluis.hortasoltero','111783','TOMAR DEL SND','HORTA SOLTERO JOSE LUIS','INGENIERÍA AUTOMOTRIZ','4to','MASCULINO','ACTIVO','',0,0,'','ALUMNO' | L8: =CONCATENATE($K$1,K8,");") -> INSERT INTO participantes (id,nivel,correo,matricula,clave,nombre,carrera,grado,sexo,situacion,evaluados,num_evaluados,total_evaluaciones,ultimo_acceso,nivel_acceso) VALUES (1007,'LICENCIATURA','joseluis.hortasoltero','111783','TOMAR DEL SND','HORTA SOLTERO JOSE LUIS','INGENIERÍA AUTOMOTRIZ','4to','MASCULINO','ACTIVO','',0,0,'','ALUMNO'); | M8: =CONCATENATE("update participantes set correo=",C8," where id=",A8,";") -> update participantes set correo='joseluis.hortasoltero' where id=1007;
A9: 1008 | B9: 'LICENCIATURA' | C9: =CONCATENATE("'",Alumnos!E9,"'") -> 'adrian.jaimeojeda' | D9: =CONCATENATE(Alumnos!F9,"'") -> '111784' | E9: TOMAR DEL SND' | F9: =CONCATENATE("'",Alumnos!H9,"'") -> 'JAIME OJEDA ADRIAN' | G9: =CONCATENATE("'",Alumnos!I9,"'") -> 'INGENIERÍA AUTOMOTRIZ' | H9: =CONCATENATE("'",Alumnos!J9,"'") -> '4to' | I9: =UPPER(CONCATENATE("'",Alumnos!K9,"'")) -> 'MASCULINO' | J9: =UPPER(CONCATENATE("'",Alumnos!L9,"'")) -> 'ACTIVO' | K9: =CONCATENATE(A9,",",B9,",",C9,",",D9,",'",E9,",",F9,",",G9,",",H9,",",UPPER(I9),",",UPPER(J9),",'',0,0,'','ALUMNO'") -> 1008,'LICENCIATURA','adrian.jaimeojeda','111784','TOMAR DEL SND','JAIME OJEDA ADRIAN','INGENIERÍA AUTOMOTRIZ','4to','MASCULINO','ACTIVO','',0,0,'','ALUMNO' | L9: =CONCATENATE($K$1,K9,");") -> INSERT INTO participantes (id,nivel,correo,matricula,clave,nombre,carrera,grado,sexo,situacion,evaluados,num_evaluados,total_evaluaciones,ultimo_acceso,nivel_acceso) VALUES (1008,'LICENCIATURA','adrian.jaimeojeda','111784','TOMAR DEL SND','JAIME OJEDA ADRIAN','INGENIERÍA AUTOMOTRIZ','4to','MASCULINO','ACTIVO','',0,0,'','ALUMNO'); | M9: =CONCATENATE("update participantes set correo=",C9," where id=",A9,";") -> update participantes set correo='adrian.jaimeojeda' where id=1008;
A10: 1009 | B10: 'LICENCIATURA' | C10: =CONCATENATE("'",Alumnos!E603,"'") -> 'valeria.torresfarias' | D10: =CONCATENATE(Alumnos!F603,"'") -> '111785' | E10: TOMAR DEL SND' | F10: =CONCATENATE("'",Alumnos!H603,"'") -> 'TORRES FARIAS VALERIA' | G10: =CONCATENATE("'",Alumnos!I603,"'") -> 'ANIMACION DIGITAL Y VIDEOJUEGOS' | H10: =CONCATENATE("'",Alumnos!J603,"'") -> '4to' | I10: =UPPER(CONCATENATE("'",Alumnos!K603,"'")) -> 'FEMENINO' | J10: =UPPER(CONCATENATE("'",Alumnos!L603,"'")) -> 'ACTIVO' | K10: =CONCATENATE(A10,",",B10,",",C10,",",D10,",'",E10,",",F10,",",G10,",",H10,",",UPPER(I10),",",UPPER(J10),",'',0,0,'','ALUMNO'") -> 1009,'LICENCIATURA','valeria.torresfarias','111785','TOMAR DEL SND','TORRES FARIAS VALERIA','ANIMACION DIGITAL Y VIDEOJUEGOS','4to','FEMENINO','ACTIVO','',0,0,'','ALUMNO' | L10: =CONCATENATE($K$1,K10,");") -> INSERT INTO participantes (id,nivel,correo,matricula,clave,nombre,carrera,grado,sexo,situacion,evaluados,num_evaluados,total_evaluaciones,ultimo_acceso,nivel_acceso) VALUES (1009,'LICENCIATURA','valeria.torresfarias','111785','TOMAR DEL SND','TORRES FARIAS VALERIA','ANIMACION DIGITAL Y VIDEOJUEGOS','4to','FEMENINO','ACTIVO','',0,0,'','ALUMNO'); | M10: =CONCATENATE("update participantes set correo=",C10," where id=",A10,";") -> update participantes set correo='valeria.torresfarias' where id=1009;
A11: 1010 | B11: 'LICENCIATURA' | C11: =CONCATENATE("'",Alumnos!E268,"'") -> 'hector.camposcardenas' | D11: =CONCATENATE(Alumnos!F268,"'") -> '111787' | E11: TOMAR DEL SND' | F11: =CONCATENATE("'",Alumnos!H268,"'") -> 'CAMPOS CARDENAS HECTOR' | G11: =CONCATENATE("'",Alumnos!I268,"'") -> 'INGENIERÍA AUTOMOTRIZ' | H11: =CONCATENATE("'",Alumnos!J268,"'") -> '4to' | I11: =UPPER(CONCATENATE("'",Alumnos!K268,"'")) -> 'MASCULINO' | J11: =UPPER(CONCATENATE("'",Alumnos!L268,"'")) -> 'ACTIVO' | K11: =CONCATENATE(A11,",",B11,",",C11,",",D11,",'",E11,",",F11,",",G11,",",H11,",",UPPER(I11),",",UPPER(J11),",'',0,0,'','ALUMNO'") -> 1010,'LICENCIATURA','hector.camposcardenas','111787','TOMAR DEL SND','CAMPOS CARDENAS HECTOR','INGENIERÍA AUTOMOTRIZ','4to','MASCULINO','ACTIVO','',0,0,'','ALUMNO' | L11: =CONCATENATE($K$1,K11,");") -> INSERT INTO participantes (id,nivel,correo,matricula,clave,nombre,carrera,grado,sexo,situacion,evaluados,num_evaluados,total_evaluaciones,ultimo_acceso,nivel_acceso) VALUES (1010,'LICENCIATURA','hector.camposcardenas','111787','TOMAR DEL SND','CAMPOS CARDENAS HECTOR','INGENIERÍA AUTOMOTRIZ','4to','MASCULINO','ACTIVO','',0,0,'','ALUMNO'); | M11: =CONCATENATE("update participantes set correo=",C11," where id=",A11,";") -> update participantes set correo='hector.camposcardenas' where id=1010;
A12: 1011 | B12: 'LICENCIATURA' | C12: =CONCATENATE("'",Alumnos!E499,"'") -> 'oliver.rochagarcia' | D12: =CONCATENATE(Alumnos!F499,"'") -> '111788' | E12: TOMAR DEL SND' | F12: =CONCATENATE("'",Alumnos!H499,"'") -> 'ROCHA GARCIA OLIVER' | G12: =CONCATENATE("'",Alumnos!I499,"'") -> 'PSICOLOGIA' | H12: =CONCATENATE("'",Alumnos!J499,"'") -> '4to' | I12: =UPPER(CONCATENATE("'",Alumnos!K499,"'")) -> 'MASCULINO' | J12: =UPPER(CONCATENATE("'",Alumnos!L499,"'")) -> 'ACTIVO' | K12: =CONCATENATE(A12,",",B12,",",C12,",",D12,",'",E12,",",F12,",",G12,",",H12,",",UPPER(I12),",",UPPER(J12),",'',0,0,'','ALUMNO'") -> 1011,'LICENCIATURA','oliver.rochagarcia','111788','TOMAR DEL SND','ROCHA GARCIA OLIVER','PSICOLOGIA','4to','MASCULINO','ACTIVO','',0,0,'','ALUMNO' | L12: =CONCATENATE($K$1,K12,");") -> INSERT INTO participantes (id,nivel,correo,matricula,clave,nombre,carrera,grado,sexo,situacion,evaluados,num_evaluados,total_evaluaciones,ultimo_acceso,nivel_acceso) VALUES (1011,'LICENCIATURA','oliver.rochagarcia','111788','TOMAR DEL SND','ROCHA GARCIA OLIVER','PSICOLOGIA','4to','MASCULINO','ACTIVO','',0,0,'','ALUMNO'); | M12: =CONCATENATE("update participantes set correo=",C12," where id=",A12,";") -> update participantes set correo='oliver.rochagarcia' where id=1011;
A13: 1012 | B13: 'LICENCIATURA' | C13: =CONCATENATE("'",Alumnos!E101,"'") -> 'berthaerica.guzmanaparicio' | D13: =CONCATENATE(Alumnos!F101,"'") -> '111791' | E13: TOMAR DEL SND' | F13: =CONCATENATE("'",Alumnos!H101,"'") -> 'GUZMAN APARICIO BERTHA ERICA' | G13: =CONCATENATE("'",Alumnos!I101,"'") -> 'ANIMACION DIGITAL Y VIDEOJUEGOS' | H13: =CONCATENATE("'",Alumnos!J101,"'") -> '4to' | I13: =UPPER(CONCATENATE("'",Alumnos!K101,"'")) -> 'FEMENINO' | J13: =UPPER(CONCATENATE("'",Alumnos!L101,"'")) -> 'ACTIVO' | K13: =CONCATENATE(A13,",",B13,",",C13,",",D13,",'",E13,",",F13,",",G13,",",H13,",",UPPER(I13),",",UPPER(J13),",'',0,0,'','ALUMNO'") -> 1012,'LICENCIATURA','berthaerica.guzmanaparicio','111791','TOMAR DEL SND','GUZMAN APARICIO BERTHA ERICA','ANIMACION DIGITAL Y VIDEOJUEGOS','4to','FEMENINO','ACTIVO','',0,0,'','ALUMNO' | L13: =CONCATENATE($K$1,K13,");") -> INSERT INTO participantes (id,nivel,correo,matricula,clave,nombre,carrera,grado,sexo,situacion,evaluados,num_evaluados,total_evaluaciones,ultimo_acceso,nivel_acceso) VALUES (1012,'LICENCIATURA','berthaerica.guzmanaparicio','111791','TOMAR DEL SND','GUZMAN APARICIO BERTHA ERICA','ANIMACION DIGITAL Y VIDEOJUEGOS','4to','FEMENINO','ACTIVO','',0,0,'','ALUMNO'); | M13: =CONCATENATE("update participantes set correo=",C13," where id=",A13,";") -> update participantes set correo='berthaerica.guzmanaparicio' where id=1012;
A14: 1013 | B14: 'LICENCIATURA' | C14: =CONCATENATE("'",Alumnos!E400,"'") -> 'leonardoaugusto.vazquezcastellanos' | D14: =CONCATENATE(Alumnos!F400,"'") -> '111792' | E14: TOMAR DEL SND' | F14: =CONCATENATE("'",Alumnos!H400,"'") -> 'VAZQUEZ CASTELLANOS LEONARDO AUGUSTO' | G14: =CONCATENATE("'",Alumnos!I400,"'") -> 'ARQUITECTURA' | H14: =CONCATENATE("'",Alumnos!J400,"'") -> '4to' | I14: =UPPER(CONCATENATE("'",Alumnos!K400,"'")) -> 'MASCULINO' | J14: =UPPER(CONCATENATE("'",Alumnos!L400,"'")) -> 'ACTIVO' | K14: =CONCATENATE(A14,",",B14,",",C14,",",D14,",'",E14,",",F14,",",G14,",",H14,",",UPPER(I14),",",UPPER(J14),",'',0,0,'','ALUMNO'") -> 1013,'LICENCIATURA','leonardoaugusto.vazquezcastellanos','111792','TOMAR DEL SND','VAZQUEZ CASTELLANOS LEONARDO AUGUSTO','ARQUITECTURA','4to','MASCULINO','ACTIVO','',0,0,'','ALUMNO' | L14: =CONCATENATE($K$1,K14,");") -> INSERT INTO participantes (id,nivel,correo,matricula,clave,nombre,carrera,grado,sexo,situacion,evaluados,num_evaluados,total_evaluaciones,ultimo_acceso,nivel_acceso) VALUES (1013,'LICENCIATURA','leonardoaugusto.vazquezcastellanos','111792','TOMAR DEL SND','VAZQUEZ CASTELLANOS LEONARDO AUGUSTO','ARQUITECTURA','4to','MASCULINO','ACTIVO','',0,0,'','ALUMNO'); | M14: =CONCATENATE("update participantes set correo=",C14," where id=",A14,";") -> update participantes set correo='leonardoaugusto.vazquezcastellanos' where id=1013;
A15: 1014 | B15: 'LICENCIATURA' | C15: =CONCATENATE("'",Alumnos!E11,"'") -> 'adrianbryant.vegacastaneda' | D15: =CONCATENATE(Alumnos!F11,"'") -> '111793' | E15: TOMAR DEL SND' | F15: =CONCATENATE("'",Alumnos!H11,"'") -> 'VEGA CASTAÑEDA ADRIAN BRYANT' | G15: =CONCATENATE("'",Alumnos!I11,"'") -> 'PSICOLOGIA' | H15: =CONCATENATE("'",Alumnos!J11,"'") -> '4to' | I15: =UPPER(CONCATENATE("'",Alumnos!K11,"'")) -> 'MASCULINO' | J15: =UPPER(CONCATENATE("'",Alumnos!L11,"'")) -> 'ACTIVO' | K15: =CONCATENATE(A15,",",B15,",",C15,",",D15,",'",E15,",",F15,",",G15,",",H15,",",UPPER(I15),",",UPPER(J15),",'',0,0,'','ALUMNO'") -> 1014,'LICENCIATURA','adrianbryant.vegacastaneda','111793','TOMAR DEL SND','VEGA CASTAÑEDA ADRIAN BRYANT','PSICOLOGIA','4to','MASCULINO','ACTIVO','',0,0,'','ALUMNO' | L15: =CONCATENATE($K$1,K15,");") -> INSERT INTO participantes (id,nivel,correo,matricula,clave,nombre,carrera,grado,sexo,situacion,evaluados,num_evaluados,total_evaluaciones,ultimo_acceso,nivel_acceso) VALUES (1014,'LICENCIATURA','adrianbryant.vegacastaneda','111793','TOMAR DEL SND','VEGA CASTAÑEDA ADRIAN BRYANT','PSICOLOGIA','4to','MASCULINO','ACTIVO','',0,0,'','ALUMNO'); | M15: =CONCATENATE("update participantes set correo=",C15," where id=",A15,";") -> update participantes set correo='adrianbryant.vegacastaneda' where id=1014;
A16: 1015 | B16: 'LICENCIATURA' | C16: =CONCATENATE("'",Alumnos!E425,"'") -> 'luzangelicanaomi.gomezosorio' | D16: =CONCATENATE(Alumnos!F425,"'") -> '111795' | E16: TOMAR DEL SND' | F16: =CONCATENATE("'",Alumnos!H425,"'") -> 'GOMEZ OSORIO LUZ ANGELICA NAOMI' | G16: =CONCATENATE("'",Alumnos!I425,"'") -> 'PSICOLOGIA' | H16: =CONCATENATE("'",Alumnos!J425,"'") -> '4to' | I16: =UPPER(CONCATENATE("'",Alumnos!K425,"'")) -> 'FEMENINO' | J16: =UPPER(CONCATENATE("'",Alumnos!L425,"'")) -> 'ACTIVO' | K16: =CONCATENATE(A16,",",B16,",",C16,",",D16,",'",E16,",",F16,",",G16,",",H16,",",UPPER(I16),",",UPPER(J16),",'',0,0,'','ALUMNO'") -> 1015,'LICENCIATURA','luzangelicanaomi.gomezosorio','111795','TOMAR DEL SND','GOMEZ OSORIO LUZ ANGELICA NAOMI','PSICOLOGIA','4to','FEMENINO','ACTIVO','',0,0,'','ALUMNO' | L16: =CONCATENATE($K$1,K16,");") -> INSERT INTO participantes (id,nivel,correo,matricula,clave,nombre,carrera,grado,sexo,situacion,evaluados,num_evaluados,total_evaluaciones,ultimo_acceso,nivel_acceso) VALUES (1015,'LICENCIATURA','luzangelicanaomi.gomezosorio','111795','TOMAR DEL SND','GOMEZ OSORIO LUZ ANGELICA NAOMI','PSICOLOGIA','4to','FEMENINO','ACTIVO','',0,0,'','ALUMNO'); | M16: =CONCATENATE("update participantes set correo=",C16," where id=",A16,";") -> update participantes set correo='luzangelicanaomi.gomezosorio' where id=1015;
A17: 1016 | B17: 'LICENCIATURA' | C17: =CONCATENATE("'",Alumnos!E347,"'") -> 'juancarlos.banuelosperez' | D17: =CONCATENATE(Alumnos!F347,"'") -> '111796' | E17: TOMAR DEL SND' | F17: =CONCATENATE("'",Alumnos!H347,"'") -> 'BAÑUELOS PEREZ JUAN CARLOS' | G17: =CONCATENATE("'",Alumnos!I347,"'") -> 'ARQUITECTURA' | H17: =CONCATENATE("'",Alumnos!J347,"'") -> '4to' | I17: =UPPER(CONCATENATE("'",Alumnos!K347,"'")) -> 'MASCULINO' | J17: =UPPER(CONCATENATE("'",Alumnos!L347,"'")) -> 'ACTIVO' | K17: =CONCATENATE(A17,",",B17,",",C17,",",D17,",'",E17,",",F17,",",G17,",",H17,",",UPPER(I17),",",UPPER(J17),",'',0,0,'','ALUMNO'") -> 1016,'LICENCIATURA','juancarlos.banuelosperez','111796','TOMAR DEL SND','BAÑUELOS PEREZ JUAN CARLOS','ARQUITECTURA','4to','MASCULINO','ACTIVO','',0,0,'','ALUMNO' | L17: =CONCATENATE($K$1,K17,");") -> INSERT INTO participantes (id,nivel,correo,matricula,clave,nombre,carrera,grado,sexo,situacion,evaluados,num_evaluados,total_evaluaciones,ultimo_acceso,nivel_acceso) VALUES (1016,'LICENCIATURA','juancarlos.banuelosperez','111796','TOMAR DEL SND','BAÑUELOS PEREZ JUAN CARLOS','ARQUITECTURA','4to','MASCULINO','ACTIVO','',0,0,'','ALUMNO'); | M17: =CONCATENATE("update participantes set correo=",C17," where id=",A17,";") -> update participantes set correo='juancarlos.banuelosperez' where id=1016;
A18: 1017 | B18: 'LICENCIATURA' | C18: =CONCATENATE("'",Alumnos!E383,"'") -> 'kevin.villalobosmendoza' | D18: =CONCATENATE(Alumnos!F383,"'") -> '111797' | E18: TOMAR DEL SND' | F18: =CONCATENATE("'",Alumnos!H383,"'") -> 'VILLALOBOS MENDOZA KEVIN' | G18: =CONCATENATE("'",Alumnos!I383,"'") -> 'INGENIERÍA AUTOMOTRIZ' | H18: =CONCATENATE("'",Alumnos!J383,"'") -> '4to' | I18: =UPPER(CONCATENATE("'",Alumnos!K383,"'")) -> 'MASCULINO' | J18: =UPPER(CONCATENATE("'",Alumnos!L383,"'")) -> 'ACTIVO' | K18: =CONCATENATE(A18,",",B18,",",C18,",",D18,",'",E18,",",F18,",",G18,",",H18,",",UPPER(I18),",",UPPER(J18),",'',0,0,'','ALUMNO'") -> 1017,'LICENCIATURA','kevin.villalobosmendoza','111797','TOMAR DEL SND','VILLALOBOS MENDOZA KEVIN','INGENIERÍA AUTOMOTRIZ','4to','MASCULINO','ACTIVO','',0,0,'','ALUMNO' | L18: =CONCATENATE($K$1,K18,");") -> INSERT INTO participantes (id,nivel,correo,matricula,clave,nombre,carrera,grado,sexo,situacion,evaluados,num_evaluados,total_evaluaciones,ultimo_acceso,nivel_acceso) VALUES (1017,'LICENCIATURA','kevin.villalobosmendoza','111797','TOMAR DEL SND','VILLALOBOS MENDOZA KEVIN','INGENIERÍA AUTOMOTRIZ','4to','MASCULINO','ACTIVO','',0,0,'','ALUMNO'); | M18: =CONCATENATE("update participantes set correo=",C18," where id=",A18,";") -> update participantes set correo='kevin.villalobosmendoza' where id=1017;
A19: 1018 | B19: 'LICENCIATURA' | C19: =CONCATENATE("'",Alumnos!E110,"'") -> 'brendaguadalupe.bojadodelreal' | D19: =CONCATENATE(Alumnos!F110,"'") -> '111798' | E19: TOMAR DEL SND' | F19: =CONCATENATE("'",Alumnos!H110,"'") -> 'BOJADO DEL REAL BRENDA GUADALUPE' | G19: =CONCATENATE("'",Alumnos!I110,"'") -> 'ARQUITECTURA' | H19: =CONCATENATE("'",Alumnos!J110,"'") -> '4to' | I19: =UPPER(CONCATENATE("'",Alumnos!K110,"'")) -> 'FEMENINO' | J19: =UPPER(CONCATENATE("'",Alumnos!L110,"'")) -> 'ACTIVO' | K19: =CONCATENATE(A19,",",B19,",",C19,",",D19,",'",E19,",",F19,",",G19,",",H19,",",UPPER(I19),",",UPPER(J19),",'',0,0,'','ALUMNO'") -> 1018,'LICENCIATURA','brendaguadalupe.bojadodelreal','111798','TOMAR DEL SND','BOJADO DEL REAL BRENDA GUADALUPE','ARQUITECTURA','4to','FEMENINO','ACTIVO','',0,0,'','ALUMNO' | L19: =CONCATENATE($K$1,K19,");") -> INSERT INTO participantes (id,nivel,correo,matricula,clave,nombre,carrera,grado,sexo,situacion,evaluados,num_evaluados,total_evaluaciones,ultimo_acceso,nivel_acceso) VALUES (1018,'LICENCIATURA','brendaguadalupe.bojadodelreal','111798','TOMAR DEL SND','BOJADO DEL REAL BRENDA GUADALUPE','ARQUITECTURA','4to','FEMENINO','ACTIVO','',0,0,'','ALUMNO'); | M19: =CONCATENATE("update participantes set correo=",C19," where id=",A19,";") -> update participantes set correo='brendaguadalupe.bojadodelreal' where id=1018;
A20: 1019 | B20: 'LICENCIATURA' | C20: =CONCATENATE("'",Alumnos!E53,"'") -> 'anasofia.carrionlopez' | D20: =CONCATENATE(Alumnos!F53,"'") -> '111799' | E20: TOMAR DEL SND' | F20: =CONCATENATE("'",Alumnos!H53,"'") -> 'CARRION LOPEZ ANA SOFIA' | G20: =CONCATENATE("'",Alumnos!I53,"'") -> 'ANIMACION DIGITAL Y VIDEOJUEGOS' | H20: =CONCATENATE("'",Alumnos!J53,"'") -> '4to' | I20: =UPPER(CONCATENATE("'",Alumnos!K53,"'")) -> 'FEMENINO' | J20: =UPPER(CONCATENATE("'",Alumnos!L53,"'")) -> 'ACTIVO' | K20: =CONCATENATE(A20,",",B20,",",C20,",",D20,",'",E20,",",F20,",",G20,",",H20,",",UPPER(I20),",",UPPER(J20),",'',0,0,'','ALUMNO'") -> 1019,'LICENCIATURA','anasofia.carrionlopez','111799','TOMAR DEL SND','CARRION LOPEZ ANA SOFIA','ANIMACION DIGITAL Y VIDEOJUEGOS','4to','FEMENINO','ACTIVO','',0,0,'','ALUMNO' | L20: =CONCATENATE($K$1,K20,");") -> INSERT INTO participantes (id,nivel,correo,matricula,clave,nombre,carrera,grado,sexo,situacion,evaluados,num_evaluados,total_evaluaciones,ultimo_acceso,nivel_acceso) VALUES (1019,'LICENCIATURA','anasofia.carrionlopez','111799','TOMAR DEL SND','CARRION LOPEZ ANA SOFIA','ANIMACION DIGITAL Y VIDEOJUEGOS','4to','FEMENINO','ACTIVO','',0,0,'','ALUMNO'); | M20: =CONCATENATE("update participantes set correo=",C20," where id=",A20,";") -> update participantes set correo='anasofia.carrionlopez' where id=1019;
A21: 1020 | B21: 'LICENCIATURA' | C21: =CONCATENATE("'",Alumnos!E280,"'") -> 'isaacemiliano.chavezsaavedra' | D21: =CONCATENATE(Alumnos!F280,"'") -> '111800' | E21: TOMAR DEL SND' | F21: =CONCATENATE("'",Alumnos!H280,"'") -> 'CHAVEZ SAAVEDRA ISAAC EMILIANO' | G21: =CONCATENATE("'",Alumnos!I280,"'") -> 'INGENIERÍA AUTOMOTRIZ' | H21: =CONCATENATE("'",Alumnos!J280,"'") -> '4to' | I21: =UPPER(CONCATENATE("'",Alumnos!K280,"'")) -> 'MASCULINO' | J21: =UPPER(CONCATENATE("'",Alumnos!L280,"'")) -> 'ACTIVO' | K21: =CONCATENATE(A21,",",B21,",",C21,",",D21,",'",E21,",",F21,",",G21,",",H21,",",UPPER(I21),",",UPPER(J21),",'',0,0,'','ALUMNO'") -> 1020,'LICENCIATURA','isaacemiliano.chavezsaavedra','111800','TOMAR DEL SND','CHAVEZ SAAVEDRA ISAAC EMILIANO','INGENIERÍA AUTOMOTRIZ','4to','MASCULINO','ACTIVO','',0,0,'','ALUMNO' | L21: =CONCATENATE($K$1,K21,");") -> INSERT INTO participantes (id,nivel,correo,matricula,clave,nombre,carrera,grado,sexo,situacion,evaluados,num_evaluados,total_evaluaciones,ultimo_acceso,nivel_acceso) VALUES (1020,'LICENCIATURA','isaacemiliano.chavezsaavedra','111800','TOMAR DEL SND','CHAVEZ SAAVEDRA ISAAC EMILIANO','INGENIERÍA AUTOMOTRIZ','4to','MASCULINO','ACTIVO','',0,0,'','ALUMNO'); | M21: =CONCATENATE("update participantes set correo=",C21," where id=",A21,";") -> update participantes set correo='isaacemiliano.chavezsaavedra' where id=1020;
A22: 1021 | B22: 'LICENCIATURA' | C22: =CONCATENATE("'",Alumnos!E79,"'") -> 'angeldavid.sanchezlopez' | D22: =CONCATENATE(Alumnos!F79,"'") -> '111802' | E22: TOMAR DEL SND' | F22: =CONCATENATE("'",Alumnos!H79,"'") -> 'SANCHEZ LOPEZ ANGEL DAVID' | G22: =CONCATENATE("'",Alumnos!I79,"'") -> 'INGENIERÍA AUTOMOTRIZ' | H22: =CONCATENATE("'",Alumnos!J79,"'") -> '4to' | I22: =UPPER(CONCATENATE("'",Alumnos!K79,"'")) -> 'MASCULINO' | J22: =UPPER(CONCATENATE("'",Alumnos!L79,"'")) -> 'ACTIVO' | K22: =CONCATENATE(A22,",",B22,",",C22,",",D22,",'",E22,",",F22,",",G22,",",H22,",",UPPER(I22),",",UPPER(J22),",'',0,0,'','ALUMNO'") -> 1021,'LICENCIATURA','angeldavid.sanchezlopez','111802','TOMAR DEL SND','SANCHEZ LOPEZ ANGEL DAVID','INGENIERÍA AUTOMOTRIZ','4to','MASCULINO','ACTIVO','',0,0,'','ALUMNO' | L22: =CONCATENATE($K$1,K22,");") -> INSERT INTO participantes (id,nivel,correo,matricula,clave,nombre,carrera,grado,sexo,situacion,evaluados,num_evaluados,total_evaluaciones,ultimo_acceso,nivel_acceso) VALUES (1021,'LICENCIATURA','angeldavid.sanchezlopez','111802','TOMAR DEL SND','SANCHEZ LOPEZ ANGEL DAVID','INGENIERÍA AUTOMOTRIZ','4to','MASCULINO','ACTIVO','',0,0,'','ALUMNO'); | M22: =CONCATENATE("update participantes set correo=",C22," where id=",A22,";") -> update participantes set correo='angeldavid.sanchezlopez' where id=1021;
A23: 1022 | B23: 'LICENCIATURA' | C23: =CONCATENATE("'",Alumnos!E227,"'") -> 'esmeralda.cadenabobadilla' | D23: =CONCATENATE(Alumnos!F227,"'") -> '111804' | E23: TOMAR DEL SND' | F23: =CONCATENATE("'",Alumnos!H227,"'") -> 'CADENA BOBADILLA ESMERALDA' | G23: =CONCATENATE("'",Alumnos!I227,"'") -> 'NUTRICION Y GASTRONOMIA' | H23: =CONCATENATE("'",Alumnos!J227,"'") -> '4to' | I23: =UPPER(CONCATENATE("'",Alumnos!K227,"'")) -> 'FEMENINO' | J23: =UPPER(CONCATENATE("'",Alumnos!L227,"'")) -> 'ACTIVO' | K23: =CONCATENATE(A23,",",B23,",",C23,",",D23,",'",E23,",",F23,",",G23,",",H23,",",UPPER(I23),",",UPPER(J23),",'',0,0,'','ALUMNO'") -> 1022,'LICENCIATURA','esmeralda.cadenabobadilla','111804','TOMAR DEL SND','CADENA BOBADILLA ESMERALDA','NUTRICION Y GASTRONOMIA','4to','FEMENINO','ACTIVO','',0,0,'','ALUMNO' | L23: =CONCATENATE($K$1,K23,");") -> INSERT INTO participantes (id,nivel,correo,matricula,clave,nombre,carrera,grado,sexo,situacion,evaluados,num_evaluados,total_evaluaciones,ultimo_acceso,nivel_acceso) VALUES (1022,'LICENCIATURA','esmeralda.cadenabobadilla','111804','TOMAR DEL SND','CADENA BOBADILLA ESMERALDA','NUTRICION Y GASTRONOMIA','4to','FEMENINO','ACTIVO','',0,0,'','ALUMNO'); | M23: =CONCATENATE("update participantes set correo=",C23," where id=",A23,";") -> update participantes set correo='esmeralda.cadenabobadilla' where id=1022;
A24: 1023 | B24: 'LICENCIATURA' | C24: =CONCATENATE("'",Alumnos!E142,"'") -> 'claudiapatricia.martinezreynoso' | D24: =CONCATENATE(Alumnos!F142,"'") -> '111805' | E24: TOMAR DEL SND' | F24: =CONCATENATE("'",Alumnos!H142,"'") -> 'MARTINEZ REYNOSO CLAUDIA PATRICIA' | G24: =CONCATENATE("'",Alumnos!I142,"'") -> 'PSICOLOGIA' | H24: =CONCATENATE("'",Alumnos!J142,"'") -> '4to' | I24: =UPPER(CONCATENATE("'",Alumnos!K142,"'")) -> 'FEMENINO' | J24: =UPPER(CONCATENATE("'",Alumnos!L142,"'")) -> 'ACTIVO' | K24: =CONCATENATE(A24,",",B24,",",C24,",",D24,",'",E24,",",F24,",",G24,",",H24,",",UPPER(I24),",",UPPER(J24),",'',0,0,'','ALUMNO'") -> 1023,'LICENCIATURA','claudiapatricia.martinezreynoso','111805','TOMAR DEL SND','MARTINEZ REYNOSO CLAUDIA PATRICIA','PSICOLOGIA','4to','FEMENINO','ACTIVO','',0,0,'','ALUMNO' | L24: =CONCATENATE($K$1,K24,");") -> INSERT INTO participantes (id,nivel,correo,matricula,clave,nombre,carrera,grado,sexo,situacion,evaluados,num_evaluados,total_evaluaciones,ultimo_acceso,nivel_acceso) VALUES (1023,'LICENCIATURA','claudiapatricia.martinezreynoso','111805','TOMAR DEL SND','MARTINEZ REYNOSO CLAUDIA PATRICIA','PSICOLOGIA','4to','FEMENINO','ACTIVO','',0,0,'','ALUMNO'); | M24: =CONCATENATE("update participantes set correo=",C24," where id=",A24,";") -> update participantes set correo='claudiapatricia.martinezreynoso' where id=1023;
A25: 1024 | B25: 'LICENCIATURA' | C25: =CONCATENATE("'",Alumnos!E239,"'") -> 'fernandaaraceli.romerogarcia' | D25: =CONCATENATE(Alumnos!F239,"'") -> '111806' | E25: TOMAR DEL SND' | F25: =CONCATENATE("'",Alumnos!H239,"'") -> 'ROMERO GARCIA FERNANDA ARACELI' | G25: =CONCATENATE("'",Alumnos!I239,"'") -> 'ARQUITECTURA' | H25: =CONCATENATE("'",Alumnos!J239,"'") -> '4to' | I25: =UPPER(CONCATENATE("'",Alumnos!K239,"'")) -> 'FEMENINO' | J25: =UPPER(CONCATENATE("'",Alumnos!L239,"'")) -> 'ACTIVO' | K25: =CONCATENATE(A25,",",B25,",",C25,",",D25,",'",E25,",",F25,",",G25,",",H25,",",UPPER(I25),",",UPPER(J25),",'',0,0,'','ALUMNO'") -> 1024,'LICENCIATURA','fernandaaraceli.romerogarcia','111806','TOMAR DEL SND','ROMERO GARCIA FERNANDA ARACELI','ARQUITECTURA','4to','FEMENINO','ACTIVO','',0,0,'','ALUMNO' | L25: =CONCATENATE($K$1,K25,");") -> INSERT INTO participantes (id,nivel,correo,matricula,clave,nombre,carrera,grado,sexo,situacion,evaluados,num_evaluados,total_evaluaciones,ultimo_acceso,nivel_acceso) VALUES (1024,'LICENCIATURA','fernandaaraceli.romerogarcia','111806','TOMAR DEL SND','ROMERO GARCIA FERNANDA ARACELI','ARQUITECTURA','4to','FEMENINO','ACTIVO','',0,0,'','ALUMNO'); | M25: =CONCATENATE("update participantes set correo=",C25," where id=",A25,";") -> update participantes set correo='fernandaaraceli.romerogarcia' where id=1024;
A26: 1025 | B26: 'LICENCIATURA' | C26: =CONCATENATE("'",Alumnos!E610,"'") -> 'victoria.romerogomez' | D26: =CONCATENATE(Alumnos!F610,"'") -> '111807' | E26: TOMAR DEL SND' | F26: =CONCATENATE("'",Alumnos!H610,"'") -> 'ROMERO GOMEZ VICTORIA' | G26: =CONCATENATE("'",Alumnos!I610,"'") -> 'NUTRICION Y GASTRONOMIA' | H26: =CONCATENATE("'",Alumnos!J610,"'") -> '4to' | I26: =UPPER(CONCATENATE("'",Alumnos!K610,"'")) -> 'FEMENINO' | J26: =UPPER(CONCATENATE("'",Alumnos!L610,"'")) -> 'ACTIVO' | K26: =CONCATENATE(A26,",",B26,",",C26,",",D26,",'",E26,",",F26,",",G26,",",H26,",",UPPER(I26),",",UPPER(J26),",'',0,0,'','ALUMNO'") -> 1025,'LICENCIATURA','victoria.romerogomez','111807','TOMAR DEL SND','ROMERO GOMEZ VICTORIA','NUTRICION Y GASTRONOMIA','4to','FEMENINO','ACTIVO','',0,0,'','ALUMNO' | L26: =CONCATENATE($K$1,K26,");") -> INSERT INTO participantes (id,nivel,correo,matricula,clave,nombre,carrera,grado,sexo,situacion,evaluados,num_evaluados,total_evaluaciones,ultimo_acceso,nivel_acceso) VALUES (1025,'LICENCIATURA','victoria.romerogomez','111807','TOMAR DEL SND','ROMERO GOMEZ VICTORIA','NUTRICION Y GASTRONOMIA','4to','FEMENINO','ACTIVO','',0,0,'','ALUMNO'); | M26: =CONCATENATE("update participantes set correo=",C26," where id=",A26,";") -> update participantes set correo='victoria.romerogomez' where id=1025;
A27: 1026 | B27: 'LICENCIATURA' | C27: =CONCATENATE("'",Alumnos!E593,"'") -> 'valentino.elizaldequintero' | D27: =CONCATENATE(Alumnos!F593,"'") -> '111808' | E27: TOMAR DEL SND' | F27: =CONCATENATE("'",Alumnos!H593,"'") -> 'ELIZALDE QUINTERO VALENTINO' | G27: =CONCATENATE("'",Alumnos!I593,"'") -> 'INGENIERIA AEROESPACIAL' | H27: =CONCATENATE("'",Alumnos!J593,"'") -> '4to' | I27: =UPPER(CONCATENATE("'",Alumnos!K593,"'")) -> 'MASCULINO' | J27: =UPPER(CONCATENATE("'",Alumnos!L593,"'")) -> 'ACTIVO' | K27: =CONCATENATE(A27,",",B27,",",C27,",",D27,",'",E27,",",F27,",",G27,",",H27,",",UPPER(I27),",",UPPER(J27),",'',0,0,'','ALUMNO'") -> 1026,'LICENCIATURA','valentino.elizaldequintero','111808','TOMAR DEL SND','ELIZALDE QUINTERO VALENTINO','INGENIERIA AEROESPACIAL','4to','MASCULINO','ACTIVO','',0,0,'','ALUMNO' | L27: =CONCATENATE($K$1,K27,");") -> INSERT INTO participantes (id,nivel,correo,matricula,clave,nombre,carrera,grado,sexo,situacion,evaluados,num_evaluados,total_evaluaciones,ultimo_acceso,nivel_acceso) VALUES (1026,'LICENCIATURA','valentino.elizaldequintero','111808','TOMAR DEL SND','ELIZALDE QUINTERO VALENTINO','INGENIERIA AEROESPACIAL','4to','MASCULINO','ACTIVO','',0,0,'','ALUMNO'); | M27: =CONCATENATE("update participantes set correo=",C27," where id=",A27,";") -> update participantes set correo='valentino.elizaldequintero' where id=1026;
