Workbook

Sheet BD ESTUDIANTES
A1: # | B1: GRUPO | C1: NOMBRE | D1: MATERIA | E1: TIPO | F1: SEXO | G1: CARRERA | H1: GRADO | I1: (1E) El o la docente domina la materia, explica, da ejemplos, resuelve dudas. | J1: (2E) El o la docente sabe relacionar su experiencia y saberes con mi formación profesional y me invita a vivir los valores maristas. | K1: (3E) El o la docente sabe enseñar y aprendo cosas útiles que me harán más competente en mi profesión. | L1: (4E) El o la docente me evalúa no solo los conocimientos sino también las habilidades, es decir, lo que debo saber hacer respecto a mi profesión. decir, lo que debo saber hacer respecto a mi profesión | M1: (5E) El o la docente promueve un ambiente respetuoso, motivante y confiable, lo que permite el intercambio de ideas y la sana convivencia. | N1: (6E) Comentarios, felicitaciones, sugerencias al docente.
A2: 294 | B2: ADMON 7� | C2: ABREU GÓMEZ DIANA CAROLINA | D2: ADQUISICIONES Y ABASTECIMIENTO | E2: GENERAL | F2: FEMENINO | G2: ADMINISTRACION Y DIRECCION DE NEGOCIOS | H2: 7mo | I2: 4 | J2: 4 | K2: 4 | L2: 4 | M2: 4
A3: 1874 | B3: ADMON 7� | C3: ABREU GÓMEZ DIANA CAROLINA | D3: ADQUISICIONES Y ABASTECIMIENTO | E3: GENERAL | F3: FEMENINO | G3: ADMINISTRACION Y DIRECCION DE NEGOCIOS | H3: 7mo | I3: 4 | J3: 4 | K3: 4 | L3: 4 | M3: 4 | N3: Muy buena maestra. Tiene mucha experiencia en su �rea.
A4: 2059 | B4: ADMON 7� | C4: ABREU GÓMEZ DIANA CAROLINA | D4: ADQUISICIONES Y ABASTECIMIENTO | E4: GENERAL | F4: FEMENINO | G4: ADMINISTRACION Y DIRECCION DE NEGOCIOS | H4: 7mo | I4: 3 | J4: 2 | K4: 2 | L4: 1 | M4: 2
A5: 2066 | B5: ADMON 7� | C5: ABREU GÓMEZ DIANA CAROLINA | D5: ADQUISICIONES Y ABASTECIMIENTO | E5: GENERAL | F5: FEMENINO | G5: ADMINISTRACION Y DIRECCION DE NEGOCIOS | H5: 7mo | I5: 4 | J5: 4 | K5: 4 | L5: 4 | M5: 4 | N5: Excelente maestra, nos apoya para seguir aprendiendo y comprendiendo los temas
A6: 2075 | B6: ADMON 7� | C6: ABREU GÓMEZ DIANA CAROLINA | D6: ADQUISICIONES Y ABASTECIMIENTO | E6: GENERAL | F6: FEMENINO | G6: ADMINISTRACION Y DIRECCION DE NEGOCIOS | H6: 7mo | I6: 4 | J6: 4 | K6: 4 | L6: 4 | M6: 4
A7: 2080 | B7: ADMON 7� | C7: ABREU GÓMEZ DIANA CAROLINA | D7: ADQUISICIONES Y ABASTECIMIENTO | E7: GENERAL | F7: FEMENINO | G7: ADMINISTRACION Y DIRECCION DE NEGOCIOS | H7: 7mo | I7: 4 | J7: 4 | K7: 4 | L7: 4 | M7: 4
A8: 2097 | B8: ADMON 7� | C8: ABREU GÓMEZ DIANA CAROLINA | D8: ADQUISICIONES Y ABASTECIMIENTO | E8: GENERAL | F8: FEMENINO | G8: ADMINISTRACION Y DIRECCION DE NEGOCIOS | H8: 7mo | I8: 4 | J8: 4 | K8: 4 | L8: 4 | M8: 4 | N8: Marivi es una maestra incre�ble, me gusta que sea mi maestra.
G9: Promedio de todos los resultados obtenidos | I9: =AVERAGE(I2:I8) -> 3.8571429 | J9: =AVERAGE(J2:J8) -> 3.7142857 | K9: =AVERAGE(K2:K8) -> 3.7142857 | L9: =AVERAGE(L2:L8) -> 3.5714286 | M9: =AVERAGE(M2:M8) -> 3.7142857
G10: Porcentaje alcanzado | I10: =(I9/4)*100 -> 96.428571 | J10: =(J9/4)*100 -> 92.857143 | K10: =(K9/4)*100 -> 92.857143 | L10: =(L9/4)*100 -> 89.285714 | M10: =(M9/4)*100 -> 92.857143

Sheet BD AUTOEVALUACIÓN
A1: NOMBRE | B1: SEXO | C1: CARRERA | D1: MATERIA | E1: GRUPO | F1: (1D) Tengo dominio sobre los contenidos de aprendizaje de la materia a mi cargo: conceptos, teorías, modelos, principios, prácticas, dentro de mi campo profesional. | G1: (2D) Relaciono mi experiencia profesional con los procesos de aprendizaje para la inserción laboral o social de las y los estudiantes. | H1: (3D) Me comunico eficientemente con mis estudiantes. Si la materia así lo exige, utilizo tecnologías de la información y comunicación. | I1: (4D) Comunico e invito a mis estudiantes a conducirse con ética profesional. | J1: (5D) Aplico estrategias metodológicas acordes con las características de los estudiantes y los objetivos de aprendizaje. | K1: (6D) Aplico estrategias, criterios y mecanismos de evaluación de forma integral y con perspectiva formativa. | L1: (7D) Promuevo con mis estudiantes un ambiente respetuoso, motivante y confiable, lo que permite el intercambio de ideas, el diálogo académico y la sana convivencia. | M1: (8D) Me conduzco eficaz y oportunamente en los entornos físicos, en las relaciones interpersonales y en los procesos relacionados con la función docente atendiendo las disposiciones institucionales y contribuyendo en los procesos de mejora continua. | N1: (9D) Me conduzco con honorabilidad, respeto a los derechos humanos y sentido de contribución con el logro de los valores institucionales. | O1: (10D) Participo en las reuniones de colegio de docentes. Si por razones de causa mayor no puedo asistir, solicito la información compartida. | P1: (11D) Mis fortalezas como docente son | Q1: (12D) Mis áreas de mejora como docente son
A2: ABREU GOMEZ DIANA CAROLINA | B2: FEMENINO | C2: ADMINISTRACIÓN Y DIRECCIÓN DE NEGOCIOS | D2: ADQUISICIONES Y ABASTECIMIENTO | E2: TC0703 2 | F2: 3 | G2: 4 | H2: 4 | I2: 4 | J2: 3 | K2: 4 | L2: 4 | M2: 4 | N2: 4 | O2: 4 | P2: Escucha a mis alumnos, constante actualizaci�n, diversidad de herramientas para el aprendizaje en clase | Q2: Seguirme capacitando como docente
A3: ABREU GOMEZ DIANA CAROLINA | B3: FEMENINO | C3: ADMINISTRACIÓN Y DIRECCIÓN DE NEGOCIOS | D3: ADQUISICIONES Y ABASTECIMIENTO | E3: TC0503 3 | F3: 3 | G3: 4 | H3: 4 | I3: 4 | J3: 4 | K3: 3 | L3: 4 | M3: 4 | N3: 4 | O3: 4 | P3: Hacer la clase din�mica, ser flexible con el alumnado, incluir herramientas o m�todos acordes a sus necesidades | Q3: Mantener m�s el orden en las actividades de di�logo o que se realicen de forma m�s l�dica
A4: ABREU GOMEZ DIANA CAROLINA | B4: FEMENINO | C4: ADMINISTRACIÓN Y DIRECCIÓN DE NEGOCIOS | D4: ADQUISICIONES Y ABASTECIMIENTO | E4: TC0503 4 | F4: 3 | G4: 4 | H4: 4 | I4: 4 | J4: 4 | K4: 3 | L4: 4 | M4: 4 | N4: 4 | O4: 4 | P4: Flexibilidad con mis estudiantes, usar herramientas y m�todos a partir de sus necesidades, buscar conocimiento actualizado | Q4: Mantener el orden en las actividades de di�logo o que se realicen de forma m�s l�dica
A5: ABREU GOMEZ DIANA CAROLINA | B5: FEMENINO | C5: ADMINISTRACIÓN Y DIRECCIÓN DE NEGOCIOS | D5: ADQUISICIONES Y ABASTECIMIENTO | E5: TC0103 2 | F5: 4 | G5: 4 | H5: 4 | I5: 4 | J5: 3 | K5: 3 | L5: 4 | M5: 4 | N5: 4 | O5: 4 | P5: Paciencia, fomentar espacios de reflexi�n y di�logo, diversidad de herramientas | Q5: Poner l�mites m�s firmes, de forma clara y tranquila, sobre todo con alumnos que no realicen tareas, asistan a clase, etc.
A6: ABREU GOMEZ DIANA CAROLINA | B6: FEMENINO | C6: ADMINISTRACIÓN Y DIRECCIÓN DE NEGOCIOS | D6: ADQUISICIONES Y ABASTECIMIENTO | E6: TC0103 8 | F6: 4 | G6: 4 | H6: 4 | I6: 4 | J6: 3 | K6: 3 | L6: 4 | M6: 4 | N6: 4 | O6: 4 | P6: Paciencia, fomentar espacios de reflexi�n y di�logo, diversidad de herramientas | Q6: Poner l�mites m�s firmes, de forma clara y tranquila, sobre todo con alumnos que no realicen tareas, asistan a clase, etc
A7: ABREU GOMEZ DIANA CAROLINA | B7: FEMENINO | C7: ADMINISTRACIÓN Y DIRECCIÓN DE NEGOCIOS | D7: ADQUISICIONES Y ABASTECIMIENTO | E7: TC0101 2 | F7: 4 | G7: 4 | H7: 4 | I7: 4 | J7: 3 | K7: 3 | L7: 4 | M7: 4 | N7: 4 | O7: 4 | P7: Paciencia, fomentar espacios de reflexi�n y di�logo, diversidad de herramientas | Q7: Poner l�mites m�s firmes, de forma clara y tranquila, sobre todo con alumnos que no realicen tareas, asistan a clase, etc
A8: ABREU GOMEZ DIANA CAROLINA | B8: FEMENINO | C8: ADMINISTRACIÓN Y DIRECCIÓN DE NEGOCIOS | D8: ADQUISICIONES Y ABASTECIMIENTO | E8: TC0101 8 | F8: 4 | G8: 4 | H8: 4 | I8: 4 | J8: 3 | K8: 3 | L8: 4 | M8: 4 | N8: 4 | O8: 4 | P8: Paciencia, fomentar espacios de reflexi�n y di�logo, diversidad de herramientas | Q8: Poner l�mites m�s firmes, de forma clara y tranquila, sobre todo con alumnos que no realicen tareas, asistan a clase, etc
D9: Promedio de todos los resultados obtenidos | F9: =AVERAGE(F2:F8) -> 3.5714286 | G9: =AVERAGE(G2:G8) -> 4 | H9: =AVERAGE(H2:H8) -> 4 | I9: =AVERAGE(I2:I8) -> 4 | J9: =AVERAGE(J2:J8) -> 3.2857143 | K9: =AVERAGE(K2:K8) -> 3.1428571 | L9: =AVERAGE(L2:L8) -> 4 | M9: =AVERAGE(M2:M8) -> 4 | ... O9: =AVERAGE(O2:O8) -> 4
D10: Porcentaje alcanzado | F10: =(F9/4)*100 -> 89.285714 | G10: =(G9/4)*100 -> 100 | H10: =(H9/4)*100 -> 100 | I10: =(I9/4)*100 -> 100 | J10: =(J9/4)*100 -> 82.142857 | K10: =(K9/4)*100 -> 78.571429 | L10: =(L9/4)*100 -> 100 | M10: =(M9/4)*100 -> 100 | ... O10: =(O9/4)*100 -> 100

Sheet BD COORDINACION
A1: # | B1: NOMBRE | C1: SEXO | D1: CARRERA | E1: (1C) El o la docente se conduce de manera respetuosa al relacionarse con las personas de todas las áreas de la Universidad, sin tener registro a la fecha de algún reporte de comportamiento inadecuado. | F1: (2C) El o la docente se conduce siempre bajo los principios de integridad académica. | G1: (3C) El o la docente cumple asiduamente sus compromisos como prestador de servicios: puntualidad/asistencia, atención a solicitudes administrativas como entrega de documentación, etc. | H1: (4C) El o la docente cumple asiduamente sus compromisos en procesos académicos, como captura de calificaciones, entrega de planeaciones, entre otros. | I1: (5C) El o la docente participa en reuniones del colegio de carrera. | J1: (6C) Comentarios, felicitaciones, sugerencias al docente. | K1: (7C) Calificación de capacitación (solo dígitos, máximo 10) | L1: (8C) Calificación de planeación didáctica (solo dígitos, máximo 15) | M1: (9C) Calificación de acompañamiento proceso enseñanza aprendizaje (solo dígitos, máximo 20)
A2: 2 | B2: ABREU GOMEZ DIANA CAROLINA | C2: FEMENINO | D2: ANIMACION DIGITAL Y VIDEOJUEGOS | E2: 3 | F2: 4 | G2: 4 | H2: 4 | I2: 4 | J2: nada | K2: 10 | L2: 15 | M2: 20
A3: 4 | B3: ABREU GOMEZ DIANA CAROLINA | C3: FEMENINO | D3: ANIMACION DIGITAL Y VIDEOJUEGOS | E3: 4 | F3: 4 | G3: 4 | H3: 4 | I3: 4 | J3: Muy responsable y excelente maestra. | K3: 9 | L3: 12 | M3: 19
D4: Promedio de todos los resultados obtenidos | E4: =AVERAGE(E2:E3) -> 3.5 | F4: =AVERAGE(F2:F3) -> 4 | G4: =AVERAGE(G2:G3) -> 4 | H4: =AVERAGE(H2:H3) -> 4 | I4: =AVERAGE(I2:I3) -> 4 | K4: =AVERAGE(K2:K3) -> 9.5 | L4: =AVERAGE(L2:L3) -> 13.5 | M4: =AVERAGE(M2:M3) -> 19.5
D5: Porcentaje alcanzado | E5: =(E4/4)*100 -> 87.5 | F5: =(F4/4)*100 -> 100 | G5: =(G4/4)*100 -> 100 | H5: =(H4/4)*100 -> 100 | I5: =(I4/4)*100 -> 100 | K5: Se captura calificación máxima de 10 | L5: Se captura calificación máxima de 15 | M5: Se captura calificación máxima de 20
K6: NO CONVERTIR A PORCENTAJE

Sheet REPORTE PARA DOCENTE (SC)
C1: Fecha
C2: Logo UMG | D2: REPORTE DE DOCENTES
D3: Ciclo 2025-II
C5: DOCENTE: | D5: ='BD ESTUDIANTES'!C2 -> ABREU GÓMEZ DIANA CAROLINA
C6: CARRERA: | D6: ='BD ESTUDIANTES'!G2 -> ADMINISTRACION Y DIRECCION DE NEGOCIOS
C7: RESULTADO DE EVALUACIÓN INTEGRADA: | D7: =F22 -> 93.823214
D10: EVALUACIÓN INTEGRADA
D11: La evaluación integrada presenta los resultados obtenidos en cada una de las etapas de la Ruta de Desarrollo Integral Docente. Puede haber variaciones respecto a la evaluación de competencias debido a la ponderación diferenciada.
E15: PONDERACIÓN | F15: RESULTADOS OBTENIDOS
D16: CAPACITACIÓN | E16: 0.1 | F16: ='BD COORDINACION'!K4 -> 9.5
D17: ENTREGA Y EVALUACIÓN DE LA PLANEACIÓN DIDÁCTICA | E17: 0.15 | F17: ='BD COORDINACION'!L4 -> 13.5
D18: ACOMPAÑAMEINTO DEL PROCESO ENSEÑANZA APRENDIZAJE | E18: 0.2 | F18: ='BD COORDINACION'!M4 -> 19.5
D19: EVALUACIÓN POR PARTE DE ESTUDIANTES | E19: 0.2 | F19: =(93*20)/100 -> 18.6
D20: AUTOEVALUACIÓN | E20: 0.1 | F20: =(F35*10)/100 -> 9.2857143
D21: EVALUACIÓN POR PARTE DE LA COORDINACIÓN | E21: 0.25 | F21: =(G35*25)/100 -> 23.4375
D22: TOTAL | E22: =SUM(E16:E21) -> 1 | F22: =SUM(F16:F21) -> 93.823214
D25: EVALUACIÓN POR COMPETENCIAS
C27: COMPETENCIA | D27: DESCRIPCIÓN | E27: ESTUDIANTE | F27: DOCENTE | G27: COORDINACIÓN | H27: RESULTADOS POR COMPETENCIA
C28: 1.Dominio de la disciplina | D28: Conoce y explica a profundidad los conceptos, teorías, modelos, principios o prácticas del campo disciplinar de su especialidad. | E28: ='BD ESTUDIANTES'!I10 -> 96.428571 | F28: ='BD AUTOEVALUACIÓN'!F10 -> 89.285714 | H28: =AVERAGE(E28:G28) -> 92.857143
C29: 2.Vinculación profesional | D29: Tiene experiencia en su campo profesional y la relaciona con los procesos de aprendizaje de las y los estudiantes. | E29: ='BD ESTUDIANTES'!J10 -> 92.857143 | F29: ='BD AUTOEVALUACIÓN'!G10 -> 100 | H29: =AVERAGE(E29:G29) -> 96.428571
C30: 3.Comunicación | D30: Se comunica eficazmente con el grupo. | F30: ='BD AUTOEVALUACIÓN'!H10 -> 100 | H30: =AVERAGE(E30:G30) -> 100
C31: 4.Mediación de los aprendizajes | D31: En su actividad en el aula demuestra manejo de grupo, organización, liderazgo, capacidad de implementar actividades y recursos diversos y congruentes con los objetivos de aprendizaje. | E31: ='BD ESTUDIANTES'!K10 -> 92.857143 | F31: ='BD AUTOEVALUACIÓN'!J10 -> 82.142857 | H31: =AVERAGE(E31:G31) -> 87.5 | M31: |
C32: 5.Evaluación de los aprendizajes | D32: Anticipa y presenta criterios de evaluación claros, evalúa de manera integral y brinda retroalimentación oportuna. | E32: ='BD ESTUDIANTES'!L10 -> 89.285714 | F32: ='BD AUTOEVALUACIÓN'!K10 -> 78.571429 | H32: =AVERAGE(E32:G32) -> 83.928571
C33: 6.Generación de ambientes seguros | D33: Promueve un ambiente respetuoso y libre de violencias, lo que favorece el diálogo y la sana convivencia . Se conduce con respeto hacia todas las personas de la comunidad educativa. | E33: ='BD ESTUDIANTES'!M10 -> 92.857143 | F33: ='BD AUTOEVALUACIÓN'!L10 -> 100 | G33: ='BD COORDINACION'!E5 -> 87.5 | H33: =AVERAGE(E33:G33) -> 93.452381
C34: 7.Compromiso institucional | D34: Promueve los valores maristas, se conduce con honorabilidad e integridad, participa en reuniones, cumple compromisos administrativos y académicos. | F34: =AVERAGE('BD AUTOEVALUACIÓN'!I10,'BD AUTOEVALUACIÓN'!M10,'BD AUTOEVALUACIÓN'!N10,'BD AUTOEVALUACIÓN'!O10) -> 100 | G34: =AVERAGE('BD COORDINACION'!I5,'BD COORDINACION'!F5,'BD COORDINACION'!G5,'BD COORDINACION'!H5,'BD COORDINACION'!I5) -> 100 | H34: =AVERAGE(E34:G34) -> 100
C35: TOTALES | E35: =AVERAGE(E28,E29,E31,E32,E33) -> 92.857143 | F35: =AVERAGE(F28,F29,F30,F31,F32,F33,F34) -> 92.857143 | G35: =AVERAGE(G33,G34) -> 93.75 | H35: =AVERAGE(H28:H34) -> 93.452381
C38: le invitamos a reflexionar sobre estos resultados y a identificar posibles áreas de mejora como una oportunidad para fortalecer su práctica docente. En la parte inferior encontrará un espacio destinado a la formulación de sus compromisos para la mejora integral. Agradecemos profundamente su compromiso con la excelencia educativa. Quedamos a su disposición para brindarle el apoyo adicional que considere necesario.
D40: Atentamente,
D42: Nombre de la Jefatura académica
C44: Compromisos para la mejora integral:
C56: ¿DE DÓNDE SALIERON LOS NÚMEROS?
C59: RESULTADO DE EVALUACIÓN INTEGRADA: | D59: Suma final de la tabla "evaluación integrada"
D61: EVALUACIÓN INTEGRADA
E63: PONDERACIÓN | F63: RESULTADOS OBTENIDOS
D64: CAPACITACIÓN | E64: 0.1 | F64: Dato directo de la pregunta 7C
D65: ENTREGA Y EVALUACIÓN DE LA PLANEACIÓN DIDÁCTICA | E65: 0.15 | F65: Dato directo de la pregunta 8C
D66: ACOMPAÑAMEINTO DEL PROCESO ENSEÑANZA APRENDIZAJE | E66: 0.2 | F66: Dato directo de la pregunta 9C
D67: EVALUACIÓN POR PARTE DE ESTUDIANTES | E67: 0.2 | F67: Promedio de calificaciones dadas por estudiantes a un docente, por 20 entre 100 (regla de 3)
D68: AUTOEVALUACIÓN | E68: 0.1 | F68: Promedio de calificaciones dadas por el docente en su autoevaluación, por 10 entre 100 (regla de 3)
D69: EVALUACIÓN POR PARTE DE LA COORDINACIÓN | E69: 0.25 | F69: Promedio de calificaciones dadas por la coordinación a un docente, por 25 entre 100 (regla de 3)
...

Sheet REPORTE PARA DOCENTE (CC)
C1: Fecha
C2: Logo UMG | D2: REPORTE DE DOCENTES
D3: Ciclo 2025-II
C5: DOCENTE: | D5: ='BD ESTUDIANTES'!C2 -> ABREU GÓMEZ DIANA CAROLINA
C6: CARRERA: | D6: ='BD ESTUDIANTES'!G2 -> ADMINISTRACION Y DIRECCION DE NEGOCIOS
C7: RESULTADO DE EVALUACIÓN INTEGRADA: | D7: =F23 -> 93.823214
D10: EVALUACIÓN INTEGRADA
D12: La evaluación integrada presenta los resultados obtenidos en cada una de las etapas de la Ruta de Desarrollo Integral Docente. Puede haber variaciones respecto a la evaluación de competencias debido a la ponderación diferenciada.
E16: PONDERACIÓN | F16: RESULTADOS OBTENIDOS
D17: Capacitación | E17: 0.1 | F17: ='BD COORDINACION'!K4 -> 9.5
D18: Entrega y evaluación de la planeación didáctica | E18: 0.15 | F18: ='BD COORDINACION'!L4 -> 13.5
D19: Acompañamiento del proceso enseñanza-aprendizaje | E19: 0.2 | F19: ='BD COORDINACION'!M4 -> 19.5
D20: Evaluación por parte de las y los estudiantes | E20: 0.2 | F20: =(93*20)/100 -> 18.6
D21: Autoevaluación | E21: 0.1 | F21: =(F36*10)/100 -> 9.2857143
D22: Evaluación por parte de la coordinación | E22: 0.25 | F22: =(G36*25)/100 -> 23.4375
D23: TOTAL | E23: =SUM(E17:E22) -> 1 | F23: =SUM(F17:F22) -> 93.823214
D26: EVALUACIÓN POR COMPETENCIAS
C28: COMPETENCIA | D28: DESCRIPCIÓN | E28: ESTUDIANTE | F28: DOCENTE | G28: COORDINACIÓN | H28: RESULTADOS POR COMPETENCIA
C29: 1.Dominio de la disciplina | D29: Conoce y explica a profundidad los conceptos, teorías, modelos, principios o prácticas del campo disciplinar de su especialidad. | E29: ='BD ESTUDIANTES'!I10 -> 96.428571 | F29: ='BD AUTOEVALUACIÓN'!F10 -> 89.285714 | H29: =AVERAGE(E29:G29) -> 92.857143
C30: 2.Vinculación profesional | D30: Tiene experiencia en su campo profesional y la relaciona con los procesos de aprendizaje de las y los estudiantes. | E30: ='BD ESTUDIANTES'!J10 -> 92.857143 | F30: ='BD AUTOEVALUACIÓN'!G10 -> 100 | H30: =AVERAGE(E30:G30) -> 96.428571
C31: 3.Comunicación | D31: Se comunica eficazmente con el grupo. | F31: ='BD AUTOEVALUACIÓN'!H10 -> 100 | H31: =AVERAGE(E31:G31) -> 100
C32: 4.Mediación de los aprendizajes | D32: En su actividad en el aula demuestra manejo de grupo, organización, liderazgo, capacidad de implementar actividades y recursos diversos y congruentes con los objetivos de aprendizaje. | E32: ='BD ESTUDIANTES'!K10 -> 92.857143 | F32: ='BD AUTOEVALUACIÓN'!J10 -> 82.142857 | H32: =AVERAGE(E32:G32) -> 87.5 | M32: |
C33: 5.Evaluación de los aprendizajes | D33: Anticipa y presenta criterios de evaluación claros, evalúa de manera integral y brinda retroalimentación oportuna. | E33: ='BD ESTUDIANTES'!L10 -> 89.285714 | F33: ='BD AUTOEVALUACIÓN'!K10 -> 78.571429 | H33: =AVERAGE(E33:G33) -> 83.928571
C34: 6.Generación de ambientes seguros | D34: Promueve un ambiente respetuoso y libre de violencias, lo que favorece el diálogo y la sana convivencia . Se conduce con respeto hacia todas las personas de la comunidad educativa. | E34: ='BD ESTUDIANTES'!M10 -> 92.857143 | F34: ='BD AUTOEVALUACIÓN'!L10 -> 100 | G34: ='BD COORDINACION'!E5 -> 87.5 | H34: =AVERAGE(E34:G34) -> 93.452381
C35: 7.Compromiso institucional | D35: Promueve los valores maristas, se conduce con honorabilidad e integridad, participa en reuniones, cumple compromisos administrativos y académicos. | F35: =AVERAGE('BD AUTOEVALUACIÓN'!I10,'BD AUTOEVALUACIÓN'!M10,'BD AUTOEVALUACIÓN'!N10,'BD AUTOEVALUACIÓN'!O10) -> 100 | G35: =AVERAGE('BD COORDINACION'!I5,'BD COORDINACION'!F5,'BD COORDINACION'!G5,'BD COORDINACION'!H5,'BD COORDINACION'!I5) -> 100 | H35: =AVERAGE(E35:G35) -> 100
C36: TOTALES | E36: =AVERAGE(E29,E30,E32,E33,E34) -> 92.857143 | F36: =AVERAGE(F29,F30,F31,F32,F33,F34,F35) -> 92.857143 | G36: =AVERAGE(G34,G35) -> 93.75 | H36: =AVERAGE(H29:H35) -> 93.452381
C40: COMENTARIOS DE ESTUDIANTES
C41: Muy buena maestra. Tiene mucha experiencia en su �rea. Excelente maestra, nos apoya para seguir aprendiendo y comprendiendo los temas Marivi es una maestra incre�ble, me gusta que sea mi maestra.
C42: COMENTARIOS DE LA O EL DOCENTE
C43: FORTALEZAS
C44: Escucha a mis alumnos, constante actualizaci�n, diversidad de herramientas para el aprendizaje en clase Hacer la clase din�mica, ser flexible con el alumnado, incluir herramientas o m�todos acordes a sus necesidades Flexibilidad con mis estudiantes, usar herramientas y m�todos a partir de sus necesidades, buscar conocimiento actualizado Paciencia, fomentar espacios de reflexi�n y di�logo, diversidad de herramientas
C45: ÁREAS DE MEJORA
C46: Seguirme capacitando como docente Mantener el orden en las actividades de di�logo o que se realicen de forma m�s l�dica Poner l�mites m�s firmes, de forma clara y tranquila, sobre todo con alumnos que no realicen tareas, asistan a clase, etc.
C47: COMENTARIOS DE LA COORDINACIÓN
C48: Muy responsable y excelente maestra.
C52: Le invitamos a reflexionar sobre estos resultados y a identificar posibles áreas de mejora como una oportunidad para fortalecer su práctica docente. En la parte inferior encontrará un espacio destinado a la formulación de sus compromisos para la mejora integral. Agradecemos profundamente su compromiso con la excelencia educativa. Quedamos a su disposición para brindarle el apoyo adicional que considere necesario.
D54: Atentamente,
D56: Nombre de la Jefatura académica
C58: Compromisos para la mejora integral:
C70: ¿DE DÓNDE SALIERON LOS NÚMEROS?
...

Sheet REPORTE PA-SUBD
C1: Fecha
C2: Logo UMG | D2: REPORTE DE DOCENTES PARA SUBDIRECCIÓN
D3: Ciclo 2025-II
C5: CA.LIFICACIÓN GENERAL:
C8: PARTICIPACIÓN
D9: PORCENTAJE DE PARTICIPACIÓN DE ESTUDIANTES | E9: PORCENTAJE DE PARTICIPACIÓN DE DOCENTES | F9: PORCENTAJE DE DOCENTES EVALUADOS POR LA COORDINACIÓN
C10: ADMINISTRACIÓN Y DIRECCIÓN DE NEGOCIOS | D10: Número de estudiantes que respondieron en su totalidad, entre número total de estudiantes, por cien | E10: Número de docentes que respondieron en su totalidad, entre número total de estudiantes, por cien | F10: Número de evaluaciones respondidas en su totalidad entre número de docentes del área, por cien.
C11: AEROESPACIAL
C12: ANIMACIÓN DIGITAL Y VIDEOJUEGOS
C13: ARQUITECTURA
C14: AUTOMOTRIZ
C15: CIBERNÉTICA Y EN SISTEMAS COMPUTACIONALES
C16: COMERCIO INTERNACIONAL
C17: DERECHO
C18: DISEÑO GRÁFICO Y DIGITAL
C19: IDIOMAS
C20: INDUSTRIAL Y EN SISTEMAS ORGANIZACIONALES
C21: INTELIGENCIA ARTIFICIAL
C22: MERCADOTECNIA Y PUBLICIDAD
... C31: RESULTADOS
D32: ADMINISTRACIÓN Y DIRECCIÓN DE NEGOCIOS | E32: AEROESPACIAL | F32: ANIMACIÓN DIGITAL Y VIDEOJUEGOS | G32: ARQUITECTURA | H32: AUTOMOTRIZ | I32: CIBERNÉTICA Y EN SISTEMAS COMPUTACIONALES | J32: COMERCIO INTERNACIONAL | K32: DERECHO | L32: DISEÑO GRÁFICO Y DIGITAL | M32: IDIOMAS | N32: INDUSTRIAL Y EN SISTEMAS ORGANIZACIONALES | O32: INTELIGENCIA ARTIFICIAL | P32: MERCADOTECNIA Y PUBLICIDAD | Q32: NUTRICIÓN Y GASTRONOMÍA | R32: PSICOLOGÍA | S32: SELLO (INSTITUCIONALES)
C33: ETAPA RUDID
C34: Capacitación | D34: Promedio de resultados de 7C
C35: Entrega y evaluación de la planeación didáctica | D35: Promedio de resultados de 8C
C36: Acompañamiento del proceso enseñanza-aprendizaje | D36: Promedio de resultados de 9C
C37: Evaluación por parte de las y los estudiantes | D37: Promedio de calificaciones dadas por estudiantes de una carrera, a un docente, por 20 entre 100 (regla de 3). O bien, promedio de los resultados de la tabla Evaluación integrada" por carrera.
C38: Autoevaluación | D38: Promedio de calificaciones dadas por el docente en su autoevaluación, por 10 entre 100 (regla de 3). O bien, promedio de los resultados de la tabla Evaluación integrada" por carrera.
C39: Evaluación por parte de la coordinación | D39: Promedio de calificaciones dadas por la coordinación a un docente, por 25 entre 100 (regla de 3). O bien, promedio de los resultados de la tabla Evaluación integrada" por carrera.
C40: COMPETENCIA
C41: 1.Dominio de la disciplina | D41: Promedio de los resultados de la tabla evaluación por competencias, por carrera.
C42: 2.Vinculación profesional
C43: 3.Comunicación
C44: 4.Mediación de los aprendizajes
C45: 5.Evaluación de los aprendizajes
C46: 6.Generación de ambientes seguros
C47: 7.Compromiso institucional
