Workbook

Sheet ALUMNOS
A1: Nivel | B1: Nombre Alumno | C1: A. Paterno Alumno | D1: A. Materno Alumno | E1: Correo | F1: Matrícula | G1: clave | H1: Nombre | I1: Carrera | J1: Grado | K1: Sexo | L1: Situación | M1: Grupo
A2: LICENCIATURA | B2: ABBY DESSIRE | C2: PELAYO | D2: DIAZ | E2: abbydessire.pelayodiaz | F2: '111772 | G2: TOMAR DEL SND | H2: PELAYO DIAZ ABBY DESSIRE | I2: NUTRICION Y GASTRONOMIA | J2: 2do | K2: Femenino | L2: Activo | M2: NUT 2°
A3: LICENCIATURA | B3: ABRIL ISABELLA | C3: GODOY | D3: FLORES | E3: abrilisabella.godoyflores | F3: '111103 | G3: TOMAR DEL SND | H3: GODOY FLORES ABRIL ISABELLA | I3: INGENIERIA CIBERNETICA Y EN SISTEMAS COMPUTACIONALES | J3: 4to | K3: Femenino | L3: Activo | M3: CIB 4°
A4: LICENCIATURA | B4: ADAN OSWALDO | C4: SANDOVAL | D4: CARDENAS | E4: adanoswaldo.sandovalcardenas | F4: '111031 | G4: TOMAR DEL SND | H4: SANDOVAL CARDENAS ADAN OSWALDO | I4: INGENIERIA AEROESPACIAL | J4: 4to | K4: Masculino | L4: Activo | M4: AERO 4°
A5: LICENCIATURA | B5: ADIB KALEB | C5: GONZALEZ | D5: TOSCANO | E5: adibkaleb.gonzaleztoscano | F5: '110517 | G5: TOMAR DEL SND | H5: GONZALEZ TOSCANO ADIB KALEB | I5: INGENIERIA AEROESPACIAL | J5: 6to | K5: Masculino | L5: Activo | M5: AERO 6°
A6: LICENCIATURA | B6: ADRIAN | C6: ESQUEDA | D6: MACIAS | E6: adrian.esquedamacias | F6: '109814 | G6: TOMAR DEL SND | H6: ESQUEDA MACIAS ADRIAN | I6: INGENIERIA AEROESPACIAL | J6: 8vo | K6: Masculino | L6: Activo | M6: AERO 8°
A7: LICENCIATURA | B7: ADRIAN | C7: JAIME | D7: OJEDA | E7: adrian.jaimeojeda | F7: '111784 | G7: TOMAR DEL SND | H7: JAIME OJEDA ADRIAN | I7: INGENIERÍA AUTOMOTRIZ | J7: 2do | K7: Masculino | L7: Activo | M7: AUTO 2° B
A8: LICENCIATURA | B8: ADRIAN | C8: PERFECTO | D8: ARELLANO | E8: adrian.perfectoarellano | F8: '109337 | G8: TOMAR DEL SND | H8: PERFECTO ARELLANO ADRIAN | I8: INGENIERIA AEROESPACIAL | J8: 10mo | K8: Masculino | L8: Activo | M8: AERO_10°
A9: LICENCIATURA | B9: ADRIAN ASSIS | C9: TAPIA | D9: CORRIPIO | E9: adrianassis.tapiacorripio | F9: '109374 | G9: TOMAR DEL SND | H9: TAPIA CORRIPIO ADRIAN ASSIS | I9: INGENIERIA AEROESPACIAL | J9: 4to | K9: Masculino | L9: Activo | M9: AERO 4°
A10: LICENCIATURA | B10: ADRIAN BRYANT | C10: VEGA | D10: CASTAÑEDA | E10: adrianbryant.vegacastañeda | F10: '111793 | G10: TOMAR DEL SND | H10: VEGA CASTAÑEDA ADRIAN BRYANT | I10: PSICOLOGIA | J10: 2do | K10: Masculino | L10: Activo | M10: PSI 2°
A11: LICENCIATURA | B11: ADRIAN FERNANDO | C11: OROZCO | D11: RIVAS | E11: adrianfernando.orozcorivas | F11: '109829 | G11: TOMAR DEL SND | H11: OROZCO RIVAS ADRIAN FERNANDO | I11: ARQUITECTURA | J11: 8vo | K11: Masculino | L11: Activo | M11: ARQ 8°
A12: LICENCIATURA | B12: ADRIANA | C12: AMARO | D12: BALTIERRA | E12: adriana.amarobaltierra | F12: '111068 | G12: TOMAR DEL SND | H12: AMARO BALTIERRA ADRIANA | I12: INGENIERIA AEROESPACIAL | J12: 4to | K12: Femenino | L12: Activo | M12: AERO 4°
... A439: LICENCIATURA | B439: MARIA FERNANDA | C439: ALVAREZ | D439: LOPEZ | E439: mariafernanda.alvarezlopez | F439: '111111 | G439: TOMAR DEL SND | H439: ALVAREZ LOPEZ MARIA FERNANDA | I439: DISEÑO GRAFICO Y DIGITAL | J439: 4to | K439: Femenino | L439: Activo | M439: DGD 4°
A440: LICENCIATURA | B440: MARIA FERNANDA | D440: OCHOA | E440: mariafernanda.alvarezochoa | F440: '110544 | G440: TOMAR DEL SND | H440: ALVAREZ OCHOA MARIA FERNANDA | I440: COMERCIO INTERNACIONAL | J440: 6to | K440: Femenino | L440: Activo | M440: COM 6°
A441: LICENCIATURA | B441: MARIA FERNANDA | D441: GONZALEZ | E441: mariafernanda.castillogonzalez | F441: '111197 | G441: TOMAR DEL SND | H441: CASTILLO GONZALEZ MARIA FERNANDA | I441: NUTRICION Y GASTRONOMIA | J441: 4to | K441: Femenino | L441: Activo | M441: NUT 4°
A442: LICENCIATURA | B442: MARIA FERNANDA | D442: NIEBLAS | E442: mariafernanda.domingueznieblas | F442: '007514 | G442: TOMAR DEL SND | H442: DOMINGUEZ NIEBLAS MARIA FERNANDA | I442: NUTRICION Y GASTRONOMIA | J442: 4to | K442: Femenino | L442: Activo | M442: NUT 4°
A443: LICENCIATURA | B443: MARIA FERNANDA | D443: MENDEZ | E443: mariafernanda.martinezmendez | F443: '110490 | G443: TOMAR DEL SND | H443: MARTINEZ MENDEZ MARIA FERNANDA | I443: ANIMACION DIGITAL Y VIDEOJUEGOS | J443: 6to | K443: Femenino | L443: Activo | M443: ANIM 6°
A444: LICENCIATURA | B444: MARIA FERNANDA | D444: SANCHEZ | E444: mariafernanda.ruizsanchez | F444: '111635 | G444: TOMAR DEL SND | H444: RUIZ SANCHEZ MARIA FERNANDA | I444: INGENIERIA AEROESPACIAL | J444: 2do | K444: Femenino | L444: Activo | M444: AERO 2° A
A445: LICENCIATURA | B445: MARIA FERNANDA | D445: RODRIGUEZ | E445: mariafernanda.sandovalrodriguez | F445: '007756 | G445: TOMAR DEL SND | H445: SANDOVAL RODRIGUEZ MARIA FERNANDA | I445: NUTRICION Y GASTRONOMIA | J445: 2do | K445: Femenino | L445: Activo | M445: NUT 2°
A446: LICENCIATURA | B446: MARIA INES | D446: LOPEZ | E446: mariaines.ruizlopez | F446: '110435 | G446: TOMAR DEL SND | H446: RUIZ LOPEZ MARIA INES | I446: COMERCIO INTERNACIONAL | J446: 6to | K446: Femenino | L446: Activo | M446: COM 6°
A447: LICENCIATURA | B447: MARIA PAULA | D447: PETTERSEN | E447: mariapaula.sandovalpettersen | F447: '111621 | G447: TOMAR DEL SND | H447: SANDOVAL PETTERSEN MARIA PAULA | I447: NUTRICION Y GASTRONOMIA | J447: 2do | K447: Femenino | L447: Activo | M447: NUT 2°
A448: LICENCIATURA | B448: MARIA SOFIA | D448: CONTRERAS | E448: mariasofia.esparzacontreras | F448: '111110 | G448: TOMAR DEL SND | H448: ESPARZA CONTRERAS MARIA SOFIA | I448: ADMINISTRACION Y DIRECCION DE NEGOCIOS | J448: 4to | K448: Femenino | L448: Activo | M448: ADMON 4°
A449: LICENCIATURA | B449: MARIAN ISABELLA | D449: MARTIN | E449: marianisabella.ruizmartin | F449: '111669 | G449: TOMAR DEL SND | H449: RUIZ MARTIN MARIAN ISABELLA | I449: INGENIERIA AEROESPACIAL | J449: 2do | K449: Femenino | L449: Activo | M449: AERO 2° A
A450: LICENCIATURA | B450: MARIANA | D450: ESTRADA | E450: mariana.avilaestrada | F450: '111116 | G450: TOMAR DEL SND | H450: AVILA ESTRADA MARIANA | I450: PSICOLOGIA | J450: 4to | K450: Femenino | L450: Activo | M450: PSI 4°
A451: LICENCIATURA | B451: MARIANA | D451: ANZOATEGUI | E451: mariana.castroanzoategui | F451: '111648 | G451: TOMAR DEL SND | H451: CASTRO ANZOATEGUI MARIANA | I451: ARQUITECTURA | J451: 2do | K451: Femenino | L451: Activo | M451: ARQ 2°
... A620: LICENCIATURA | B620: ZARA SOFIA | D620: AMBROCIO | E620: zarasofia.montañoambrocio | F620: '111628 | G620: TOMAR DEL SND | H620: MONTAÑO AMBROCIO ZARA SOFIA | I620: INGENIERÍA AUTOMOTRIZ | J620: 2do | K620: Femenino | L620: Activo | M620: AUTO 2° A

Sheet PARTICIPANTES
A1: ID | B1: Nivel | C1: Correo | D1: Matrícula | E1: Clave | F1: Nombre | G1: Carrera | H1: Grado | I1: Sexo | J1: Situación | K1: =CONCATENATE("INSERT INTO participantes (",L1,") VALUES (") -> INSERT INTO participantes (id,nivel,correo,matricula,clave,nombre,carrera,grado,sexo,situacion,evaluados,num_evaluados,total_evaluaciones,ultimo_acceso,nivel_acceso) VALUES ( | L1: id,nivel,correo,matricula,clave,nombre,carrera,grado,sexo,situacion,evaluados,num_evaluados,total_evaluaciones,ultimo_acceso,nivel_acceso
A2: 1001 | B2: 'LICENCIATURA' | C2: =CONCATENATE("'",ALUMNOS!E2,"'") -> 'abbydessire.pelayodiaz' | D2: =CONCATENATE(ALUMNOS!F2,"'") -> '111772' | E2: TOMAR DEL SND' | F2: =CONCATENATE("'",ALUMNOS!H2,"'") -> 'PELAYO DIAZ ABBY DESSIRE' | G2: =CONCATENATE("'",ALUMNOS!I2,"'") -> 'NUTRICION Y GASTRONOMIA' | H2: =CONCATENATE("'",ALUMNOS!J2,"'") -> '2do' | I2: =CONCATENATE("'",ALUMNOS!K2,"'") -> 'Femenino' | J2: =CONCATENATE("'",ALUMNOS!L2,"'") -> 'Activo' | K2: =CONCATENATE(A2,",",B2,",",C2,",",D2,",'",E2,",",F2,",",G2,",",H2,",",UPPER(I2),",",UPPER(J2),",'',0,0,'','ALUMNO'") -> 1001,'LICENCIATURA','abbydessire.pelayodiaz','111772','TOMAR DEL SND','PELAYO DIAZ ABBY DESSIRE','NUTRICION Y GASTRONOMIA','2do','FEMENINO','ACTIVO','',0,0,'','ALUMNO' | L2: =CONCATENATE($K$1,K2,");") -> INSERT INTO participantes (id,nivel,correo,matricula,clave,nombre,carrera,grado,sexo,situacion,evaluados,num_evaluados,total_evaluaciones,ultimo_acceso,nivel_acceso) VALUES (1001,'LICENCIATURA','abbydessire.pelayodiaz','111772','TOMAR DEL SND','PELAYO DIAZ ABBY DESSIRE','NUTRICION Y GASTRONOMIA','2do','FEMENINO','ACTIVO','',0,0,'','ALUMNO'); | M2: =CONCATENATE("update participantes set correo=",C2," where id=",A2,";") -> update participantes set correo='abbydessire.pelayodiaz' where id=1001;
A3: =A2+1 -> 1002 | B3: 'LICENCIATURA' | C3: =CONCATENATE("'",ALUMNOS!E3,"'") -> 'abrilisabella.godoyflores' | D3: =CONCATENATE(ALUMNOS!F3,"'") -> '111103' | E3: TOMAR DEL SND' | F3: =CONCATENATE("'",ALUMNOS!H3,"'") -> 'GODOY FLORES ABRIL ISABELLA' | G3: =CONCATENATE("'",ALUMNOS!I3,"'") -> 'INGENIERIA CIBERNETICA Y EN SISTEMAS COMPUTACIONALES' | H3: =CONCATENATE("'",ALUMNOS!J3,"'") -> '4to' | I3: =CONCATENATE("'",ALUMNOS!K3,"'") -> 'Femenino' | J3: =CONCATENATE("'",ALUMNOS!L3,"'") -> 'Activo' | K3: =CONCATENATE(A3,",",B3,",",C3,",",D3,",'",E3,",",F3,",",G3,",",H3,",",UPPER(I3),",",UPPER(J3),",'',0,0,'','ALUMNO'") -> 1002,'LICENCIATURA','abrilisabella.godoyflores','111103','TOMAR DEL SND','GODOY FLORES ABRIL ISABELLA','INGENIERIA CIBERNETICA Y EN SISTEMAS COMPUTACIONALES','4to','FEMENINO','ACTIVO','',0,0,'','ALUMNO' | L3: =CONCATENATE($K$1,K3,");") -> INSERT INTO participantes (id,nivel,correo,matricula,clave,nombre,carrera,grado,sexo,situacion,evaluados,num_evaluados,total_evaluaciones,ultimo_acceso,nivel_acceso) VALUES (1002,'LICENCIATURA','abrilisabella.godoyflores','111103','TOMAR DEL SND','GODOY FLORES ABRIL ISABELLA','INGENIERIA CIBERNETICA Y EN SISTEMAS COMPUTACIONALES','4to','FEMENINO','ACTIVO','',0,0,'','ALUMNO'); | M3: =CONCATENATE("update participantes set correo=",C3," where id=",A3,";") -> update participantes set correo='abrilisabella.godoyflores' where id=1002;
A4: =A3+1 -> 1003 | B4: 'LICENCIATURA' | C4: =CONCATENATE("'",ALUMNOS!E4,"'") -> 'adanoswaldo.sandovalcardenas' | D4: =CONCATENATE(ALUMNOS!F4,"'") -> '111031' | E4: TOMAR DEL SND' | F4: =CONCATENATE("'",ALUMNOS!H4,"'") -> 'SANDOVAL CARDENAS ADAN OSWALDO' | G4: =CONCATENATE("'",ALUMNOS!I4,"'") -> 'INGENIERIA AEROESPACIAL' | H4: =CONCATENATE("'",ALUMNOS!J4,"'") -> '4to' | I4: =CONCATENATE("'",ALUMNOS!K4,"'") -> 'Masculino' | J4: =CONCATENATE("'",ALUMNOS!L4,"'") -> 'Activo' | K4: =CONCATENATE(A4,",",B4,",",C4,",",D4,",'",E4,",",F4,",",G4,",",H4,",",UPPER(I4),",",UPPER(J4),",'',0,0,'','ALUMNO'") -> 1003,'LICENCIATURA','adanoswaldo.sandovalcardenas','111031','TOMAR DEL SND','SANDOVAL CARDENAS ADAN OSWALDO','INGENIERIA AEROESPACIAL','4to','MASCULINO','ACTIVO','',0,0,'','ALUMNO' | L4: =CONCATENATE($K$1,K4,");") -> INSERT INTO participantes (id,nivel,correo,matricula,clave,nombre,carrera,grado,sexo,situacion,evaluados,num_evaluados,total_evaluaciones,ultimo_acceso,nivel_acceso) VALUES (1003,'LICENCIATURA','adanoswaldo.sandovalcardenas','111031','TOMAR DEL SND','SANDOVAL CARDENAS ADAN OSWALDO','INGENIERIA AEROESPACIAL','4to','MASCULINO','ACTIVO','',0,0,'','ALUMNO'); | M4: =CONCATENATE("update participantes set correo=",C4," where id=",A4,";") -> update participantes set correo='adanoswaldo.sandovalcardenas' where id=1003;
A5: =A4+1 -> 1004 | B5: 'LICENCIATURA' | C5: =CONCATENATE("'",ALUMNOS!E5,"'") -> 'adibkaleb.gonzaleztoscano' | D5: =CONCATENATE(ALUMNOS!F5,"'") -> '110517' | E5: TOMAR DEL SND' | F5: =CONCATENATE("'",ALUMNOS!H5,"'") -> 'GONZALEZ TOSCANO ADIB KALEB' | G5: =CONCATENATE("'",ALUMNOS!I5,"'") -> 'INGENIERIA AEROESPACIAL' | H5: =CONCATENATE("'",ALUMNOS!J5,"'") -> '6to' | I5: =CONCATENATE("'",ALUMNOS!K5,"'") -> 'Masculino' | J5: =CONCATENATE("'",ALUMNOS!L5,"'") -> 'Activo' | K5: =CONCATENATE(A5,",",B5,",",C5,",",D5,",'",E5,",",F5,",",G5,",",H5,",",UPPER(I5),",",UPPER(J5),",'',0,0,'','ALUMNO'") -> 1004,'LICENCIATURA','adibkaleb.gonzaleztoscano','110517','TOMAR DEL SND','GONZALEZ TOSCANO ADIB KALEB','INGENIERIA AEROESPACIAL','6to','MASCULINO','ACTIVO','',0,0,'','ALUMNO' | L5: =CONCATENATE($K$1,K5,");") -> INSERT INTO participantes (id,nivel,correo,matricula,clave,nombre,carrera,grado,sexo,situacion,evaluados,num_evaluados,total_evaluaciones,ultimo_acceso,nivel_acceso) VALUES (1004,'LICENCIATURA','adibkaleb.gonzaleztoscano','110517','TOMAR DEL SND','GONZALEZ TOSCANO ADIB KALEB','INGENIERIA AEROESPACIAL','6to','MASCULINO','ACTIVO','',0,0,'','ALUMNO'); | M5: =CONCATENATE("update participantes set correo=",C5," where id=",A5,";") -> update participantes set correo='adibkaleb.gonzaleztoscano' where id=1004;
A6: =A5+1 -> 1005 | B6: 'LICENCIATURA' | C6: =CONCATENATE("'",ALUMNOS!E6,"'") -> 'adrian.esquedamacias' | D6: =CONCATENATE(ALUMNOS!F6,"'") -> '109814' | E6: TOMAR DEL SND' | F6: =CONCATENATE("'",ALUMNOS!H6,"'") -> 'ESQUEDA MACIAS ADRIAN' | G6: =CONCATENATE("'",ALUMNOS!I6,"'") -> 'INGENIERIA AEROESPACIAL' | H6: =CONCATENATE("'",ALUMNOS!J6,"'") -> '8vo' | I6: =CONCATENATE("'",ALUMNOS!K6,"'") -> 'Masculino' | J6: =CONCATENATE("'",ALUMNOS!L6,"'") -> 'Activo' | K6: =CONCATENATE(A6,",",B6,",",C6,",",D6,",'",E6,",",F6,",",G6,",",H6,",",UPPER(I6),",",UPPER(J6),",'',0,0,'','ALUMNO'") -> 1005,'LICENCIATURA','adrian.esquedamacias','109814','TOMAR DEL SND','ESQUEDA MACIAS ADRIAN','INGENIERIA AEROESPACIAL','8vo','MASCULINO','ACTIVO','',0,0,'','ALUMNO' | L6: =CONCATENATE($K$1,K6,");") -> INSERT INTO participantes (id,nivel,correo,matricula,clave,nombre,carrera,grado,sexo,situacion,evaluados,num_evaluados,total_evaluaciones,ultimo_acceso,nivel_acceso) VALUES (1005,'LICENCIATURA','adrian.esquedamacias','109814','TOMAR DEL SND','ESQUEDA MACIAS ADRIAN','INGENIERIA AEROESPACIAL','8vo','MASCULINO','ACTIVO','',0,0,'','ALUMNO'); | M6: =CONCATENATE("update participantes set correo=",C6," where id=",A6,";") -> update participantes set correo='adrian.esquedamacias' where id=1005;
A7: =A6+1 -> 1006 | B7: 'LICENCIATURA' | C7: =CONCATENATE("'",ALUMNOS!E7,"'") -> 'adrian.jaimeojeda' | D7: =CONCATENATE(ALUMNOS!F7,"'") -> '111784' | E7: TOMAR DEL SND' | F7: =CONCATENATE("'",ALUMNOS!H7,"'") -> 'JAIME OJEDA ADRIAN' | G7: =CONCATENATE("'",ALUMNOS!I7,"'") -> 'INGENIERÍA AUTOMOTRIZ' | H7: =CONCATENATE("'",ALUMNOS!J7,"'") -> '2do' | I7: =CONCATENATE("'",ALUMNOS!K7,"'") -> 'Masculino' | J7: =CONCATENATE("'",ALUMNOS!L7,"'") -> 'Activo' | K7: =CONCATENATE(A7,",",B7,",",C7,",",D7,",'",E7,",",F7,",",G7,",",H7,",",UPPER(I7),",",UPPER(J7),",'',0,0,'','ALUMNO'") -> 1006,'LICENCIATURA','adrian.jaimeojeda','111784','TOMAR DEL SND','JAIME OJEDA ADRIAN','INGENIERÍA AUTOMOTRIZ','2do','MASCULINO','ACTIVO','',0,0,'','ALUMNO' | L7: =CONCATENATE($K$1,K7,");") -> INSERT INTO participantes (id,nivel,correo,matricula,clave,nombre,carrera,grado,sexo,situacion,evaluados,num_evaluados,total_evaluaciones,ultimo_acceso,nivel_acceso) VALUES (1006,'LICENCIATURA','adrian.jaimeojeda','111784','TOMAR DEL SND','JAIME OJEDA ADRIAN','INGENIERÍA AUTOMOTRIZ','2do','MASCULINO','ACTIVO','',0,0,'','ALUMNO'); | M7: =CONCATENATE("update participantes set correo=",C7," where id=",A7,";") -> update participantes set correo='adrian.jaimeojeda' where id=1006;
A8: =A7+1 -> 1007 | B8: 'LICENCIATURA' | C8: =CONCATENATE("'",ALUMNOS!E8,"'") -> 'adrian.perfectoarellano' | D8: =CONCATENATE(ALUMNOS!F8,"'") -> '109337' | E8: TOMAR DEL SND' | F8: =CONCATENATE("'",ALUMNOS!H8,"'") -> 'PERFECTO ARELLANO ADRIAN' | G8: =CONCATENATE("'",ALUMNOS!I8,"'") -> 'INGENIERIA AEROESPACIAL' | H8: =CONCATENATE("'",ALUMNOS!J8,"'") -> '10mo' | I8: =CONCATENATE("'",ALUMNOS!K8,"'") -> 'Masculino' | J8: =CONCATENATE("'",ALUMNOS!L8,"'") -> 'Activo' | K8: =CONCATENATE(A8,",",B8,",",C8,",",D8,",'",E8,",",F8,",",G8,",",H8,",",UPPER(I8),",",UPPER(J8),",'',0,0,'','ALUMNO'") -> 1007,'LICENCIATURA','adrian.perfectoarellano','109337','TOMAR DEL SND','PERFECTO ARELLANO ADRIAN','INGENIERIA AEROESPACIAL','10mo','MASCULINO','ACTIVO','',0,0,'','ALUMNO' | L8: =CONCATENATE($K$1,K8,");") -> INSERT INTO participantes (id,nivel,correo,matricula,clave,nombre,carrera,grado,sexo,situacion,evaluados,num_evaluados,total_evaluaciones,ultimo_acceso,nivel_acceso) VALUES (1007,'LICENCIATURA','adrian.perfectoarellano','109337','TOMAR DEL SND','PERFECTO ARELLANO ADRIAN','INGENIERIA AEROESPACIAL','10mo','MASCULINO','ACTIVO','',0,0,'','ALUMNO'); | M8: =CONCATENATE("update participantes set correo=",C8," where id=",A8,";") -> update participantes set correo='adrian.perfectoarellano' where id=1007;
A9: =A8+1 -> 1008 | B9: 'LICENCIATURA' | C9: =CONCATENATE("'",ALUMNOS!E9,"'") -> 'adrianassis.tapiacorripio' | D9: =CONCATENATE(ALUMNOS!F9,"'") -> '109374' | E9: TOMAR DEL SND' | F9: =CONCATENATE("'",ALUMNOS!H9,"'") -> 'TAPIA CORRIPIO ADRIAN ASSIS' | G9: =CONCATENATE("'",ALUMNOS!I9,"'") -> 'INGENIERIA AEROESPACIAL' | H9: =CONCATENATE("'",ALUMNOS!J9,"'") -> '4to' | I9: =CONCATENATE("'",ALUMNOS!K9,"'") -> 'Masculino' | J9: =CONCATENATE("'",ALUMNOS!L9,"'") -> 'Activo' | K9: =CONCATENATE(A9,",",B9,",",C9,",",D9,",'",E9,",",F9,",",G9,",",H9,",",UPPER(I9),",",UPPER(J9),",'',0,0,'','ALUMNO'") -> 1008,'LICENCIATURA','adrianassis.tapiacorripio','109374','TOMAR DEL SND','TAPIA CORRIPIO ADRIAN ASSIS','INGENIERIA AEROESPACIAL','4to','MASCULINO','ACTIVO','',0,0,'','ALUMNO' | L9: =CONCATENATE($K$1,K9,");") -> INSERT INTO participantes (id,nivel,correo,matricula,clave,nombre,carrera,grado,sexo,situacion,evaluados,num_evaluados,total_evaluaciones,ultimo_acceso,nivel_acceso) VALUES (1008,'LICENCIATURA','adrianassis.tapiacorripio','109374','TOMAR DEL SND','TAPIA CORRIPIO ADRIAN ASSIS','INGENIERIA AEROESPACIAL','4to','MASCULINO','ACTIVO','',0,0,'','ALUMNO'); | M9: =CONCATENATE("update participantes set correo=",C9," where id=",A9,";") -> update participantes set correo='adrianassis.tapiacorripio' where id=1008;
A10: =A9+1 -> 1009 | B10: 'LICENCIATURA' | C10: =CONCATENATE("'",ALUMNOS!E10,"'") -> 'adrianbryant.vegacastañeda' | D10: =CONCATENATE(ALUMNOS!F10,"'") -> '111793' | E10: TOMAR DEL SND' | F10: =CONCATENATE("'",ALUMNOS!H10,"'") -> 'VEGA CASTAÑEDA ADRIAN BRYANT' | G10: =CONCATENATE("'",ALUMNOS!I10,"'") -> 'PSICOLOGIA' | H10: =CONCATENATE("'",ALUMNOS!J10,"'") -> '2do' | I10: =CONCATENATE("'",ALUMNOS!K10,"'") -> 'Masculino' | J10: =CONCATENATE("'",ALUMNOS!L10,"'") -> 'Activo' | K10: =CONCATENATE(A10,",",B10,",",C10,",",D10,",'",E10,",",F10,",",G10,",",H10,",",UPPER(I10),",",UPPER(J10),",'',0,0,'','ALUMNO'") -> 1009,'LICENCIATURA','adrianbryant.vegacastañeda','111793','TOMAR DEL SND','VEGA CASTAÑEDA ADRIAN BRYANT','PSICOLOGIA','2do','MASCULINO','ACTIVO','',0,0,'','ALUMNO' | L10: =CONCATENATE($K$1,K10,");") -> INSERT INTO participantes (id,nivel,correo,matricula,clave,nombre,carrera,grado,sexo,situacion,evaluados,num_evaluados,total_evaluaciones,ultimo_acceso,nivel_acceso) VALUES (1009,'LICENCIATURA','adrianbryant.vegacastañeda','111793','TOMAR DEL SND','VEGA CASTAÑEDA ADRIAN BRYANT','PSICOLOGIA','2do','MASCULINO','ACTIVO','',0,0,'','ALUMNO'); | M10: =CONCATENATE("update participantes set correo=",C10," where id=",A10,";") -> update participantes set correo='adrianbryant.vegacastañeda' where id=1009;
A11: =A10+1 -> 1010 | B11: 'LICENCIATURA' | C11: =CONCATENATE("'",ALUMNOS!E11,"'") -> 'adrianfernando.orozcorivas' | D11: =CONCATENATE(ALUMNOS!F11,"'") -> '109829' | E11: TOMAR DEL SND' | F11: =CONCATENATE("'",ALUMNOS!H11,"'") -> 'OROZCO RIVAS ADRIAN FERNANDO' | G11: =CONCATENATE("'",ALUMNOS!I11,"'") -> 'ARQUITECTURA' | H11: =CONCATENATE("'",ALUMNOS!J11,"'") -> '8vo' | I11: =CONCATENATE("'",ALUMNOS!K11,"'") -> 'Masculino' | J11: =CONCATENATE("'",ALUMNOS!L11,"'") -> 'Activo' | K11: =CONCATENATE(A11,",",B11,",",C11,",",D11,",'",E11,",",F11,",",G11,",",H11,",",UPPER(I11),",",UPPER(J11),",'',0,0,'','ALUMNO'") -> 1010,'LICENCIATURA','adrianfernando.orozcorivas','109829','TOMAR DEL SND','OROZCO RIVAS ADRIAN FERNANDO','ARQUITECTURA','8vo','MASCULINO','ACTIVO','',0,0,'','ALUMNO' | L11: =CONCATENATE($K$1,K11,");") -> INSERT INTO participantes (id,nivel,correo,matricula,clave,nombre,carrera,grado,sexo,situacion,evaluados,num_evaluados,total_evaluaciones,ultimo_acceso,nivel_acceso) VALUES (1010,'LICENCIATURA','adrianfernando.orozcorivas','109829','TOMAR DEL SND','OROZCO RIVAS ADRIAN FERNANDO','ARQUITECTURA','8vo','MASCULINO','ACTIVO','',0,0,'','ALUMNO'); | M11: =CONCATENATE("update participantes set correo=",C11," where id=",A11,";") -> update participantes set correo='adrianfernando.orozcorivas' where id=1010;
A12: =A11+1 -> 1011 | B12: 'LICENCIATURA' | C12: =CONCATENATE("'",ALUMNOS!E12,"'") -> 'adriana.amarobaltierra' | D12: =CONCATENATE(ALUMNOS!F12,"'") -> '111068' | E12: TOMAR DEL SND' | F12: =CONCATENATE("'",ALUMNOS!H12,"'") -> 'AMARO BALTIERRA ADRIANA' | G12: =CONCATENATE("'",ALUMNOS!I12,"'") -> 'INGENIERIA AEROESPACIAL' | H12: =CONCATENATE("'",ALUMNOS!J12,"'") -> '4to' | I12: =CONCATENATE("'",ALUMNOS!K12,"'") -> 'Femenino' | J12: =CONCATENATE("'",ALUMNOS!L12,"'") -> 'Activo' | K12: =CONCATENATE(A12,",",B12,",",C12,",",D12,",'",E12,",",F12,",",G12,",",H12,",",UPPER(I12),",",UPPER(J12),",'',0,0,'','ALUMNO'") -> 1011,'LICENCIATURA','adriana.amarobaltierra','111068','TOMAR DEL SND','AMARO BALTIERRA ADRIANA','INGENIERIA AEROESPACIAL','4to','FEMENINO','ACTIVO','',0,0,'','ALUMNO' | L12: =CONCATENATE($K$1,K12,");") -> INSERT INTO participantes (id,nivel,correo,matricula,clave,nombre,carrera,grado,sexo,situacion,evaluados,num_evaluados,total_evaluaciones,ultimo_acceso,nivel_acceso) VALUES (1011,'LICENCIATURA','adriana.amarobaltierra','111068','TOMAR DEL SND','AMARO BALTIERRA ADRIANA','INGENIERIA AEROESPACIAL','4to','FEMENINO','ACTIVO','',0,0,'','ALUMNO'); | M12: =CONCATENATE("update participantes set correo=",C12," where id=",A12,";") -> update participantes set correo='adriana.amarobaltierra' where id=1011;
A13: =A12+1 -> 1012 | B13: 'LICENCIATURA' | C13: =CONCATENATE("'",ALUMNOS!E13,"'") -> 'adrianaguadalupe.martinezarambula' | D13: =CONCATENATE(ALUMNOS!F13,"'") -> '110460' | E13: TOMAR DEL SND' | F13: =CONCATENATE("'",ALUMNOS!H13,"'") -> 'MARTINEZ ARAMBULA ADRIANA GUADALUPE' | G13: =CONCATENATE("'",ALUMNOS!I13,"'") -> 'ARQUITECTURA' | H13: =CONCATENATE("'",ALUMNOS!J13,"'") -> '4to' | I13: =CONCATENATE("'",ALUMNOS!K13,"'") -> 'Femenino' | J13: =CONCATENATE("'",ALUMNOS!L13,"'") -> 'Activo' | K13: =CONCATENATE(A13,",",B13,",",C13,",",D13,",'",E13,",",F13,",",G13,",",H13,",",UPPER(I13),",",UPPER(J13),",'',0,0,'','ALUMNO'") -> 1012,'LICENCIATURA','adrianaguadalupe.martinezarambula','110460','TOMAR DEL SND','MARTINEZ ARAMBULA ADRIANA GUADALUPE','ARQUITECTURA','4to','FEMENINO','ACTIVO','',0,0,'','ALUMNO' | L13: =CONCATENATE($K$1,K13,");") -> INSERT INTO participantes (id,nivel,correo,matricula,clave,nombre,carrera,grado,sexo,situacion,evaluados,num_evaluados,total_evaluaciones,ultimo_acceso,nivel_acceso) VALUES (1012,'LICENCIATURA','adrianaguadalupe.martinezarambula','110460','TOMAR DEL SND','MARTINEZ ARAMBULA ADRIANA GUADALUPE','ARQUITECTURA','4to','FEMENINO','ACTIVO','',0,0,'','ALUMNO'); | M13: =CONCATENATE("update participantes set correo=",C13," where id=",A13,";") -> update participantes set correo='adrianaguadalupe.martinezarambula' where id=1012;
A14: =A13+1 -> 1013 | B14: 'LICENCIATURA' | C14: =CONCATENATE("'",ALUMNOS!E14,"'") -> 'adrianapaola.rodriguezmartinez' | D14: =CONCATENATE(ALUMNOS!F14,"'") -> '111179' | E14: TOMAR DEL SND' | F14: =CONCATENATE("'",ALUMNOS!H14,"'") -> 'RODRIGUEZ MARTINEZ ADRIANA PAOLA' | G14: =CONCATENATE("'",ALUMNOS!I14,"'") -> 'ANIMACION DIGITAL Y VIDEOJUEGOS' | H14: =CONCATENATE("'",ALUMNOS!J14,"'") -> '4to' | I14: =CONCATENATE("'",ALUMNOS!K14,"'") -> 'Femenino' | J14: =CONCATENATE("'",ALUMNOS!L14,"'") -> 'Activo' | K14: =CONCATENATE(A14,",",B14,",",C14,",",D14,",'",E14,",",F14,",",G14,",",H14,",",UPPER(I14),",",UPPER(J14),",'',0,0,'','ALUMNO'") -> 1013,'LICENCIATURA','adrianapaola.rodriguezmartinez','111179','TOMAR DEL SND','RODRIGUEZ MARTINEZ ADRIANA PAOLA','ANIMACION DIGITAL Y VIDEOJUEGOS','4to','FEMENINO','ACTIVO','',0,0,'','ALUMNO' | L14: =CONCATENATE($K$1,K14,");") -> INSERT INTO participantes (id,nivel,correo,matricula,clave,nombre,carrera,grado,sexo,situacion,evaluados,num_evaluados,total_evaluaciones,ultimo_acceso,nivel_acceso) VALUES (1013,'LICENCIATURA','adrianapaola.rodriguezmartinez','111179','TOMAR DEL SND','RODRIGUEZ MARTINEZ ADRIANA PAOLA','ANIMACION DIGITAL Y VIDEOJUEGOS','4to','FEMENINO','ACTIVO','',0,0,'','ALUMNO'); | M14: =CONCATENATE("update participantes set correo=",C14," where id=",A14,";") -> update participantes set correo='adrianapaola.rodriguezmartinez' where id=1013;
... A27: =A26+1 -> 1026 | B27: 'LICENCIATURA' | C27: =CONCATENATE("'",ALUMNOS!E27,"'") -> 'alejandro.solisarriola' | D27: =CONCATENATE(ALUMNOS!F27,"'") -> '111827' | E27: TOMAR DEL SND' | F27: =CONCATENATE("'",ALUMNOS!H27,"'") -> 'SOLIS ARRIOLA ALEJANDRO' | G27: =CONCATENATE("'",ALUMNOS!I27,"'") -> 'ADMINISTRACION Y DIRECCION DE NEGOCIOS' | H27: =CONCATENATE("'",ALUMNOS!J27,"'") -> '2do' | I27: =CONCATENATE("'",ALUMNOS!K27,"'") -> 'Masculino' | J27: =CONCATENATE("'",ALUMNOS!L27,"'") -> 'Activo' | K27: =CONCATENATE(A27,",",B27,",",C27,",",D27,",'",E27,",",F27,",",G27,",",H27,",",UPPER(I27),",",UPPER(J27),",'',0,0,'','ALUMNO'") -> 1026,'LICENCIATURA','alejandro.solisarriola','111827','TOMAR DEL SND','SOLIS ARRIOLA ALEJANDRO','ADMINISTRACION Y DIRECCION DE NEGOCIOS','2do','MASCULINO','ACTIVO','',0,0,'','ALUMNO' | L27: =CONCATENATE($K$1,K27,");") -> INSERT INTO participantes (id,nivel,correo,matricula,clave,nombre,carrera,grado,sexo,situacion,evaluados,num_evaluados,total_evaluaciones,ultimo_acceso,nivel_acceso) VALUES (1026,'LICENCIATURA','alejandro.solisarriola','111827','TOMAR DEL SND','SOLIS ARRIOLA ALEJANDRO','ADMINISTRACION Y DIRECCION DE NEGOCIOS','2do','MASCULINO','ACTIVO','',0,0,'','ALUMNO'); | M27: =CONCATENATE("update participantes set correo=",C27," where id=",A27,";") -> update participantes set correo='alejandro.solisarriola' where id=1026;
A28: =A27+1 -> 1027 | B28: 'LICENCIATURA' | C28: =CONCATENATE("'",ALUMNOS!E29,"'") -> 'alexavianey.trujillonapoles' | D28: =CONCATENATE(ALUMNOS!F29,"'") -> '110525' | E28: TOMAR DEL SND' | F28: =CONCATENATE("'",ALUMNOS!H29,"'") -> 'TRUJILLO NAPOLES ALEXA VIANEY' | G28: =CONCATENATE("'",ALUMNOS!I29,"'") -> 'PSICOLOGIA' | H28: =CONCATENATE("'",ALUMNOS!J29,"'") -> '6to' | I28: =CONCATENATE("'",ALUMNOS!K29,"'") -> 'Femenino' | J28: =CONCATENATE("'",ALUMNOS!L29,"'") -> 'Activo' | K28: =CONCATENATE(A28,",",B28,",",C28,",",D28,",'",E28,",",F28,",",G28,",",H28,",",UPPER(I28),",",UPPER(J28),",'',0,0,'','ALUMNO'") -> 1027,'LICENCIATURA','alexavianey.trujillonapoles','110525','TOMAR DEL SND','TRUJILLO NAPOLES ALEXA VIANEY','PSICOLOGIA','6to','FEMENINO','ACTIVO','',0,0,'','ALUMNO' | L28: =CONCATENATE($K$1,K28,");") -> INSERT INTO participantes (id,nivel,correo,matricula,clave,nombre,carrera,grado,sexo,situacion,evaluados,num_evaluados,total_evaluaciones,ultimo_acceso,nivel_acceso) VALUES (1027,'LICENCIATURA','alexavianey.trujillonapoles','110525','TOMAR DEL SND','TRUJILLO NAPOLES ALEXA VIANEY','PSICOLOGIA','6to','FEMENINO','ACTIVO','',0,0,'','ALUMNO'); | M28: =CONCATENATE("update participantes set correo=",C28," where id=",A28,";") -> update participantes set correo='alexavianey.trujillonapoles' where id=1027;
A29: =A28+1 -> 1028 | B29: 'LICENCIATURA' | C29: =CONCATENATE("'",ALUMNOS!E30,"'") -> 'alfonso.rosalesvargas' | D29: =CONCATENATE(ALUMNOS!F30,"'") -> '110596' | E29: TOMAR DEL SND' | F29: =CONCATENATE("'",ALUMNOS!H30,"'") -> 'ROSALES VARGAS ALFONSO' | G29: =CONCATENATE("'",ALUMNOS!I30,"'") -> 'NUTRICION Y GASTRONOMIA' | H29: =CONCATENATE("'",ALUMNOS!J30,"'") -> '6to' | I29: =CONCATENATE("'",ALUMNOS!K30,"'") -> 'Masculino' | J29: =CONCATENATE("'",ALUMNOS!L30,"'") -> 'Activo' | K29: =CONCATENATE(A29,",",B29,",",C29,",",D29,",'",E29,",",F29,",",G29,",",H29,",",UPPER(I29),",",UPPER(J29),",'',0,0,'','ALUMNO'") -> 1028,'LICENCIATURA','alfonso.rosalesvargas','110596','TOMAR DEL SND','ROSALES VARGAS ALFONSO','NUTRICION Y GASTRONOMIA','6to','MASCULINO','ACTIVO','',0,0,'','ALUMNO' | L29: =CONCATENATE($K$1,K29,");") -> INSERT INTO participantes (id,nivel,correo,matricula,clave,nombre,carrera,grado,sexo,situacion,evaluados,num_evaluados,total_evaluaciones,ultimo_acceso,nivel_acceso) VALUES (1028,'LICENCIATURA','alfonso.rosalesvargas','110596','TOMAR DEL SND','ROSALES VARGAS ALFONSO','NUTRICION Y GASTRONOMIA','6to','MASCULINO','ACTIVO','',0,0,'','ALUMNO'); | M29: =CONCATENATE("update participantes set correo=",C29," where id=",A29,";") -> update participantes set correo='alfonso.rosalesvargas' where id=1028;
A30: =A29+1 -> 1029 | B30: 'LICENCIATURA' | C30: =CONCATENATE("'",ALUMNOS!E31,"'") -> 'alfredo.cortesañorve' | D30: =CONCATENATE(ALUMNOS!F31,"'") -> '110038' | E30: TOMAR DEL SND' | F30: =CONCATENATE("'",ALUMNOS!H31,"'") -> 'CORTES AÑORVE ALFREDO' | G30: =CONCATENATE("'",ALUMNOS!I31,"'") -> 'COMERCIO INTERNACIONAL' | H30: =CONCATENATE("'",ALUMNOS!J31,"'") -> '8vo' | I30: =CONCATENATE("'",ALUMNOS!K31,"'") -> 'Masculino' | J30: =CONCATENATE("'",ALUMNOS!L31,"'") -> 'Activo' | K30: =CONCATENATE(A30,",",B30,",",C30,",",D30,",'",E30,",",F30,",",G30,",",H30,",",UPPER(I30),",",UPPER(J30),",'',0,0,'','ALUMNO'") -> 1029,'LICENCIATURA','alfredo.cortesañorve','110038','TOMAR DEL SND','CORTES AÑORVE ALFREDO','COMERCIO INTERNACIONAL','8vo','MASCULINO','ACTIVO','',0,0,'','ALUMNO' | L30: =CONCATENATE($K$1,K30,");") -> INSERT INTO participantes (id,nivel,correo,matricula,clave,nombre,carrera,grado,sexo,situacion,evaluados,num_evaluados,total_evaluaciones,ultimo_acceso,nivel_acceso) VALUES (1029,'LICENCIATURA','alfredo.cortesañorve','110038','TOMAR DEL SND','CORTES AÑORVE ALFREDO','COMERCIO INTERNACIONAL','8vo','MASCULINO','ACTIVO','',0,0,'','ALUMNO'); | M30: =CONCATENATE("update participantes set correo=",C30," where id=",A30,";") -> update participantes set correo='alfredo.cortesañorve' where id=1029;
A31: =A30+1 -> 1030 | B31: 'LICENCIATURA' | C31: =CONCATENATE("'",ALUMNOS!E32,"'") -> 'almadaniela.santoyogarcia' | D31: =CONCATENATE(ALUMNOS!F32,"'") -> '111758' | E31: TOMAR DEL SND' | F31: =CONCATENATE("'",ALUMNOS!H32,"'") -> 'SANTOYO GARCIA ALMA DANIELA' | G31: =CONCATENATE("'",ALUMNOS!I32,"'") -> 'NUTRICION Y GASTRONOMIA' | H31: =CONCATENATE("'",ALUMNOS!J32,"'") -> '2do' | I31: =CONCATENATE("'",ALUMNOS!K32,"'") -> 'Femenino' | J31: =CONCATENATE("'",ALUMNOS!L32,"'") -> 'Activo' | K31: =CONCATENATE(A31,",",B31,",",C31,",",D31,",'",E31,",",F31,",",G31,",",H31,",",UPPER(I31),",",UPPER(J31),",'',0,0,'','ALUMNO'") -> 1030,'LICENCIATURA','almadaniela.santoyogarcia','111758','TOMAR DEL SND','SANTOYO GARCIA ALMA DANIELA','NUTRICION Y GASTRONOMIA','2do','FEMENINO','ACTIVO','',0,0,'','ALUMNO' | L31: =CONCATENATE($K$1,K31,");") -> INSERT INTO participantes (id,nivel,correo,matricula,clave,nombre,carrera,grado,sexo,situacion,evaluados,num_evaluados,total_evaluaciones,ultimo_acceso,nivel_acceso) VALUES (1030,'LICENCIATURA','almadaniela.santoyogarcia','111758','TOMAR DEL SND','SANTOYO GARCIA ALMA DANIELA','NUTRICION Y GASTRONOMIA','2do','FEMENINO','ACTIVO','',0,0,'','ALUMNO'); | M31: =CONCATENATE("update participantes set correo=",C31," where id=",A31,";") -> update participantes set correo='almadaniela.santoyogarcia' where id=1030;
A32: =A31+1 -> 1031 | B32: 'LICENCIATURA' | C32: =CONCATENATE("'",ALUMNOS!E33,"'") -> 'alondra.arredondobautista' | D32: =CONCATENATE(ALUMNOS!F33,"'") -> '109846' | E32: TOMAR DEL SND' | F32: =CONCATENATE("'",ALUMNOS!H33,"'") -> 'ARREDONDO BAUTISTA ALONDRA' | G32: =CONCATENATE("'",ALUMNOS!I33,"'") -> 'INGENIERIA AEROESPACIAL' | H32: =CONCATENATE("'",ALUMNOS!J33,"'") -> '8vo' | I32: =CONCATENATE("'",ALUMNOS!K33,"'") -> 'Femenino' | J32: =CONCATENATE("'",ALUMNOS!L33,"'") -> 'Activo' | K32: =CONCATENATE(A32,",",B32,",",C32,",",D32,",'",E32,",",F32,",",G32,",",H32,",",UPPER(I32),",",UPPER(J32),",'',0,0,'','ALUMNO'") -> 1031,'LICENCIATURA','alondra.arredondobautista','109846','TOMAR DEL SND','ARREDONDO BAUTISTA ALONDRA','INGENIERIA AEROESPACIAL','8vo','FEMENINO','ACTIVO','',0,0,'','ALUMNO' | L32: =CONCATENATE($K$1,K32,");") -> INSERT INTO participantes (id,nivel,correo,matricula,clave,nombre,carrera,grado,sexo,situacion,evaluados,num_evaluados,total_evaluaciones,ultimo_acceso,nivel_acceso) VALUES (1031,'LICENCIATURA','alondra.arredondobautista','109846','TOMAR DEL SND','ARREDONDO BAUTISTA ALONDRA','INGENIERIA AEROESPACIAL','8vo','FEMENINO','ACTIVO','',0,0,'','ALUMNO'); | M32: =CONCATENATE("update participantes set correo=",C32," where id=",A32,";") -> update participantes set correo='alondra.arredondobautista' where id=1031;
A33: =A32+1 -> 1032 | B33: 'LICENCIATURA' | C33: =CONCATENATE("'",ALUMNOS!E34,"'") -> 'alondra.ramosavalos' | D33: =CONCATENATE(ALUMNOS!F34,"'") -> '111091' | E33: TOMAR DEL SND' | F33: =CONCATENATE("'",ALUMNOS!H34,"'") -> 'RAMOS AVALOS ALONDRA' | G33: =CONCATENATE("'",ALUMNOS!I34,"'") -> 'ANIMACION DIGITAL Y VIDEOJUEGOS' | H33: =CONCATENATE("'",ALUMNOS!J34,"'") -> '4to' | I33: =CONCATENATE("'",ALUMNOS!K34,"'") -> 'Femenino' | J33: =CONCATENATE("'",ALUMNOS!L34,"'") -> 'Activo' | K33: =CONCATENATE(A33,",",B33,",",C33,",",D33,",'",E33,",",F33,",",G33,",",H33,",",UPPER(I33),",",UPPER(J33),",'',0,0,'','ALUMNO'") -> 1032,'LICENCIATURA','alondra.ramosavalos','111091','TOMAR DEL SND','RAMOS AVALOS ALONDRA','ANIMACION DIGITAL Y VIDEOJUEGOS','4to','FEMENINO','ACTIVO','',0,0,'','ALUMNO' | L33: =CONCATENATE($K$1,K33,");") -> INSERT INTO participantes (id,nivel,correo,matricula,clave,nombre,carrera,grado,sexo,situacion,evaluados,num_evaluados,total_evaluaciones,ultimo_acceso,nivel_acceso) VALUES (1032,'LICENCIATURA','alondra.ramosavalos','111091','TOMAR DEL SND','RAMOS AVALOS ALONDRA','ANIMACION DIGITAL Y VIDEOJUEGOS','4to','FEMENINO','ACTIVO','',0,0,'','ALUMNO'); | M33: =CONCATENATE("update participantes set correo=",C33," where id=",A33,";") -> update participantes set correo='alondra.ramosavalos' where id=1032;
A34: =A33+1 -> 1033 | B34: 'LICENCIATURA' | C34: =CONCATENATE("'",ALUMNOS!E35,"'") -> 'alondraarhemi.gonzalezorozco' | D34: =CONCATENATE(ALUMNOS!F35,"'") -> '109856' | E34: TOMAR DEL SND' | F34: =CONCATENATE("'",ALUMNOS!H35,"'") -> 'GONZALEZ OROZCO ALONDRA ARHEMI' | G34: =CONCATENATE("'",ALUMNOS!I35,"'") -> 'INGENIERIA AEROESPACIAL' | H34: =CONCATENATE("'",ALUMNOS!J35,"'") -> '8vo' | I34: =CONCATENATE("'",ALUMNOS!K35,"'") -> 'Femenino' | J34: =CONCATENATE("'",ALUMNOS!L35,"'") -> 'Activo' | K34: =CONCATENATE(A34,",",B34,",",C34,",",D34,",'",E34,",",F34,",",G34,",",H34,",",UPPER(I34),",",UPPER(J34),",'',0,0,'','ALUMNO'") -> 1033,'LICENCIATURA','alondraarhemi.gonzalezorozco','109856','TOMAR DEL SND','GONZALEZ OROZCO ALONDRA ARHEMI','INGENIERIA AEROESPACIAL','8vo','FEMENINO','ACTIVO','',0,0,'','ALUMNO' | L34: =CONCATENATE($K$1,K34,");") -> INSERT INTO participantes (id,nivel,correo,matricula,clave,nombre,carrera,grado,sexo,situacion,evaluados,num_evaluados,total_evaluaciones,ultimo_acceso,nivel_acceso) VALUES (1033,'LICENCIATURA','alondraarhemi.gonzalezorozco','109856','TOMAR DEL SND','GONZALEZ OROZCO ALONDRA ARHEMI','INGENIERIA AEROESPACIAL','8vo','FEMENINO','ACTIVO','',0,0,'','ALUMNO'); | M34: =CONCATENATE("update participantes set correo=",C34," where id=",A34,";") -> update participantes set correo='alondraarhemi.gonzalezorozco' where id=1033;
A35: =A34+1 -> 1034 | B35: 'LICENCIATURA' | C35: =CONCATENATE("'",ALUMNOS!E36,"'") -> 'alondrajamileth.velazquezcastro' | D35: =CONCATENATE(ALUMNOS!F36,"'") -> '111113' | E35: TOMAR DEL SND' | F35: =CONCATENATE("'",ALUMNOS!H36,"'") -> 'VELAZQUEZ CASTRO ALONDRA JAMILETH' | G35: =CONCATENATE("'",ALUMNOS!I36,"'") -> 'INGENIERIA AEROESPACIAL' | H35: =CONCATENATE("'",ALUMNOS!J36,"'") -> '4to' | I35: =CONCATENATE("'",ALUMNOS!K36,"'") -> 'Femenino' | J35: =CONCATENATE("'",ALUMNOS!L36,"'") -> 'Activo' | K35: =CONCATENATE(A35,",",B35,",",C35,",",D35,",'",E35,",",F35,",",G35,",",H35,",",UPPER(I35),",",UPPER(J35),",'',0,0,'','ALUMNO'") -> 1034,'LICENCIATURA','alondrajamileth.velazquezcastro','111113','TOMAR DEL SND','VELAZQUEZ CASTRO ALONDRA JAMILETH','INGENIERIA AEROESPACIAL','4to','FEMENINO','ACTIVO','',0,0,'','ALUMNO' | L35: =CONCATENATE($K$1,K35,");") -> INSERT INTO participantes (id,nivel,correo,matricula,clave,nombre,carrera,grado,sexo,situacion,evaluados,num_evaluados,total_evaluaciones,ultimo_acceso,nivel_acceso) VALUES (1034,'LICENCIATURA','alondrajamileth.velazquezcastro','111113','TOMAR DEL SND','VELAZQUEZ CASTRO ALONDRA JAMILETH','INGENIERIA AEROESPACIAL','4to','FEMENINO','ACTIVO','',0,0,'','ALUMNO'); | M35: =CONCATENATE("update participantes set correo=",C35," where id=",A35,";") -> update participantes set correo='alondrajamileth.velazquezcastro' where id=1034;
A36: =A35+1 -> 1035 | B36: 'LICENCIATURA' | C36: =CONCATENATE("'",ALUMNOS!E37,"'") -> 'alondramarisol.ramosarias' | D36: =CONCATENATE(ALUMNOS!F37,"'") -> '111074' | E36: TOMAR DEL SND' | F36: =CONCATENATE("'",ALUMNOS!H37,"'") -> 'RAMOS ARIAS ALONDRA MARISOL' | G36: =CONCATENATE("'",ALUMNOS!I37,"'") -> 'ARQUITECTURA' | H36: =CONCATENATE("'",ALUMNOS!J37,"'") -> '4to' | I36: =CONCATENATE("'",ALUMNOS!K37,"'") -> 'Femenino' | J36: =CONCATENATE("'",ALUMNOS!L37,"'") -> 'Activo' | K36: =CONCATENATE(A36,",",B36,",",C36,",",D36,",'",E36,",",F36,",",G36,",",H36,",",UPPER(I36),",",UPPER(J36),",'',0,0,'','ALUMNO'") -> 1035,'LICENCIATURA','alondramarisol.ramosarias','111074','TOMAR DEL SND','RAMOS ARIAS ALONDRA MARISOL','ARQUITECTURA','4to','FEMENINO','ACTIVO','',0,0,'','ALUMNO' | L36: =CONCATENATE($K$1,K36,");") -> INSERT INTO participantes (id,nivel,correo,matricula,clave,nombre,carrera,grado,sexo,situacion,evaluados,num_evaluados,total_evaluaciones,ultimo_acceso,nivel_acceso) VALUES (1035,'LICENCIATURA','alondramarisol.ramosarias','111074','TOMAR DEL SND','RAMOS ARIAS ALONDRA MARISOL','ARQUITECTURA','4to','FEMENINO','ACTIVO','',0,0,'','ALUMNO'); | M36: =CONCATENATE("update participantes set correo=",C36," where id=",A36,";") -> update participantes set correo='alondramarisol.ramosarias' where id=1035;
A37: =A36+1 -> 1036 | B37: 'LICENCIATURA' | C37: =CONCATENATE("'",ALUMNOS!E38,"'") -> 'alondrasofia.ornelasaltamirano' | D37: =CONCATENATE(ALUMNOS!F38,"'") -> '006767' | E37: TOMAR DEL SND' | F37: =CONCATENATE("'",ALUMNOS!H38,"'") -> 'ORNELAS ALTAMIRANO ALONDRA SOFIA' | G37: =CONCATENATE("'",ALUMNOS!I38,"'") -> 'ARQUITECTURA' | H37: =CONCATENATE("'",ALUMNOS!J38,"'") -> '8vo' | I37: =CONCATENATE("'",ALUMNOS!K38,"'") -> 'Femenino' | J37: =CONCATENATE("'",ALUMNOS!L38,"'") -> 'Activo' | K37: =CONCATENATE(A37,",",B37,",",C37,",",D37,",'",E37,",",F37,",",G37,",",H37,",",UPPER(I37),",",UPPER(J37),",'',0,0,'','ALUMNO'") -> 1036,'LICENCIATURA','alondrasofia.ornelasaltamirano','006767','TOMAR DEL SND','ORNELAS ALTAMIRANO ALONDRA SOFIA','ARQUITECTURA','8vo','FEMENINO','ACTIVO','',0,0,'','ALUMNO' | L37: =CONCATENATE($K$1,K37,");") -> INSERT INTO participantes (id,nivel,correo,matricula,clave,nombre,carrera,grado,sexo,situacion,evaluados,num_evaluados,total_evaluaciones,ultimo_acceso,nivel_acceso) VALUES (1036,'LICENCIATURA','alondrasofia.ornelasaltamirano','006767','TOMAR DEL SND','ORNELAS ALTAMIRANO ALONDRA SOFIA','ARQUITECTURA','8vo','FEMENINO','ACTIVO','',0,0,'','ALUMNO'); | M37: =CONCATENATE("update participantes set correo=",C37," where id=",A37,";") -> update participantes set correo='alondrasofia.ornelasaltamirano' where id=1036;
A38: =A37+1 -> 1037 | B38: 'LICENCIATURA' | C38: =CONCATENATE("'",ALUMNOS!E39,"'") -> 'alvaro.delapeñaperez' | D38: =CONCATENATE(ALUMNOS!F39,"'") -> '111100' | E38: TOMAR DEL SND' | F38: =CONCATENATE("'",ALUMNOS!H39,"'") -> 'DE LA PEÑA PEREZ ALVARO' | G38: =CONCATENATE("'",ALUMNOS!I39,"'") -> 'INGENIERIA AEROESPACIAL' | H38: =CONCATENATE("'",ALUMNOS!J39,"'") -> '4to' | I38: =CONCATENATE("'",ALUMNOS!K39,"'") -> 'Masculino' | J38: =CONCATENATE("'",ALUMNOS!L39,"'") -> 'Activo' | K38: =CONCATENATE(A38,",",B38,",",C38,",",D38,",'",E38,",",F38,",",G38,",",H38,",",UPPER(I38),",",UPPER(J38),",'',0,0,'','ALUMNO'") -> 1037,'LICENCIATURA','alvaro.delapeñaperez','111100','TOMAR DEL SND','DE LA PEÑA PEREZ ALVARO','INGENIERIA AEROESPACIAL','4to','MASCULINO','ACTIVO','',0,0,'','ALUMNO' | L38: =CONCATENATE($K$1,K38,");") -> INSERT INTO participantes (id,nivel,correo,matricula,clave,nombre,carrera,grado,sexo,situacion,evaluados,num_evaluados,total_evaluaciones,ultimo_acceso,nivel_acceso) VALUES (1037,'LICENCIATURA','alvaro.delapeñaperez','111100','TOMAR DEL SND','DE LA PEÑA PEREZ ALVARO','INGENIERIA AEROESPACIAL','4to','MASCULINO','ACTIVO','',0,0,'','ALUMNO'); | M38: =CONCATENATE("update participantes set correo=",C38," where id=",A38,";") -> update participantes set correo='alvaro.delapeñaperez' where id=1037;
A39: =A38+1 -> 1038 | B39: 'LICENCIATURA' | C39: =CONCATENATE("'",ALUMNOS!E40,"'") -> 'amandacarmiña.guzmanarias' | D39: =CONCATENATE(ALUMNOS!F40,"'") -> '109882' | E39: TOMAR DEL SND' | F39: =CONCATENATE("'",ALUMNOS!H40,"'") -> 'GUZMAN ARIAS AMANDA CARMIÑA' | G39: =CONCATENATE("'",ALUMNOS!I40,"'") -> 'INGENIERIA AEROESPACIAL' | H39: =CONCATENATE("'",ALUMNOS!J40,"'") -> '8vo' | I39: =CONCATENATE("'",ALUMNOS!K40,"'") -> 'Femenino' | J39: =CONCATENATE("'",ALUMNOS!L40,"'") -> 'Activo' | K39: =CONCATENATE(A39,",",B39,",",C39,",",D39,",'",E39,",",F39,",",G39,",",H39,",",UPPER(I39),",",UPPER(J39),",'',0,0,'','ALUMNO'") -> 1038,'LICENCIATURA','amandacarmiña.guzmanarias','109882','TOMAR DEL SND','GUZMAN ARIAS AMANDA CARMIÑA','INGENIERIA AEROESPACIAL','8vo','FEMENINO','ACTIVO','',0,0,'','ALUMNO' | L39: =CONCATENATE($K$1,K39,");") -> INSERT INTO participantes (id,nivel,correo,matricula,clave,nombre,carrera,grado,sexo,situacion,evaluados,num_evaluados,total_evaluaciones,ultimo_acceso,nivel_acceso) VALUES (1038,'LICENCIATURA','amandacarmiña.guzmanarias','109882','TOMAR DEL SND','GUZMAN ARIAS AMANDA CARMIÑA','INGENIERIA AEROESPACIAL','8vo','FEMENINO','ACTIVO','',0,0,'','ALUMNO'); | M39: =CONCATENATE("update participantes set correo=",C39," where id=",A39,";") -> update participantes set correo='amandacarmiña.guzmanarias' where id=1038;
... A44: =A43+1 -> 1043 | B44: 'LICENCIATURA' | C44: =CONCATENATE("'",ALUMNOS!E45,"'") -> 'anacristina.guerrerosoltero' | D44: =CONCATENATE(ALUMNOS!F45,"'") -> '110475' | E44: TOMAR DEL SND' | F44: =CONCATENATE("'",ALUMNOS!H45,"'") -> 'GUERRERO SOLTERO ANA CRISTINA' | G44: =CONCATENATE("'",ALUMNOS!I45,"'") -> 'NUTRICION Y GASTRONOMIA' | H44: =CONCATENATE("'",ALUMNOS!J45,"'") -> '6to' | I44: =CONCATENATE("'",ALUMNOS!K45,"'") -> 'Femenino' | J44: =CONCATENATE("'",ALUMNOS!L45,"'") -> 'Activo' | K44: =CONCATENATE(A44,",",B44,",",C44,",",D44,",'",E44,",",F44,",",G44,",",H44,",",UPPER(I44),",",UPPER(J44),",'',0,0,'','ALUMNO'") -> 1043,'LICENCIATURA','anacristina.guerrerosoltero','110475','TOMAR DEL SND','GUERRERO SOLTERO ANA CRISTINA','NUTRICION Y GASTRONOMIA','6to','FEMENINO','ACTIVO','',0,0,'','ALUMNO' | L44: =CONCATENATE($K$1,K44,");") -> INSERT INTO participantes (id,nivel,correo,matricula,clave,nombre,carrera,grado,sexo,situacion,evaluados,num_evaluados,total_evaluaciones,ultimo_acceso,nivel_acceso) VALUES (1043,'LICENCIATURA','anacristina.guerrerosoltero','110475','TOMAR DEL SND','GUERRERO SOLTERO ANA CRISTINA','NUTRICION Y GASTRONOMIA','6to','FEMENINO','ACTIVO','',0,0,'','ALUMNO'); | M44: =CONCATENATE("update participantes set correo=",C44," where id=",A44,";") -> update participantes set correo='anacristina.guerrerosoltero' where id=1043;
A45: =A44+1 -> 1044 | B45: 'LICENCIATURA' | C45: =CONCATENATE("'",ALUMNOS!E47,"'") -> 'anakarol.jimenezmartinez' | D45: =CONCATENATE(ALUMNOS!F47,"'") -> '111765' | E45: TOMAR DEL SND' | F45: =CONCATENATE("'",ALUMNOS!H47,"'") -> 'JIMENEZ MARTINEZ ANA KAROL' | G45: =CONCATENATE("'",ALUMNOS!I47,"'") -> 'NUTRICION Y GASTRONOMIA' | H45: =CONCATENATE("'",ALUMNOS!J47,"'") -> '2do' | I45: =CONCATENATE("'",ALUMNOS!K47,"'") -> 'Femenino' | J45: =CONCATENATE("'",ALUMNOS!L47,"'") -> 'Activo' | K45: =CONCATENATE(A45,",",B45,",",C45,",",D45,",'",E45,",",F45,",",G45,",",H45,",",UPPER(I45),",",UPPER(J45),",'',0,0,'','ALUMNO'") -> 1044,'LICENCIATURA','anakarol.jimenezmartinez','111765','TOMAR DEL SND','JIMENEZ MARTINEZ ANA KAROL','NUTRICION Y GASTRONOMIA','2do','FEMENINO','ACTIVO','',0,0,'','ALUMNO' | L45: =CONCATENATE($K$1,K45,");") -> INSERT INTO participantes (id,nivel,correo,matricula,clave,nombre,carrera,grado,sexo,situacion,evaluados,num_evaluados,total_evaluaciones,ultimo_acceso,nivel_acceso) VALUES (1044,'LICENCIATURA','anakarol.jimenezmartinez','111765','TOMAR DEL SND','JIMENEZ MARTINEZ ANA KAROL','NUTRICION Y GASTRONOMIA','2do','FEMENINO','ACTIVO','',0,0,'','ALUMNO'); | M45: =CONCATENATE("update participantes set correo=",C45," where id=",A45,";") -> update participantes set correo='anakarol.jimenezmartinez' where id=1044;
A46: =A45+1 -> 1045 | B46: 'LICENCIATURA' | C46: =CONCATENATE("'",ALUMNOS!E48,"'") -> 'analorena.camachoherrera' | D46: =CONCATENATE(ALUMNOS!F48,"'") -> '109343' | E46: TOMAR DEL SND' | F46: =CONCATENATE("'",ALUMNOS!H48,"'") -> 'CAMACHO HERRERA ANA LORENA' | G46: =CONCATENATE("'",ALUMNOS!I48,"'") -> 'INGENIERIA AEROESPACIAL' | H46: =CONCATENATE("'",ALUMNOS!J48,"'") -> '10mo' | I46: =CONCATENATE("'",ALUMNOS!K48,"'") -> 'Femenino' | J46: =CONCATENATE("'",ALUMNOS!L48,"'") -> 'Activo' | K46: =CONCATENATE(A46,",",B46,",",C46,",",D46,",'",E46,",",F46,",",G46,",",H46,",",UPPER(I46),",",UPPER(J46),",'',0,0,'','ALUMNO'") -> 1045,'LICENCIATURA','analorena.camachoherrera','109343','TOMAR DEL SND','CAMACHO HERRERA ANA LORENA','INGENIERIA AEROESPACIAL','10mo','FEMENINO','ACTIVO','',0,0,'','ALUMNO' | L46: =CONCATENATE($K$1,K46,");") -> INSERT INTO participantes (id,nivel,correo,matricula,clave,nombre,carrera,grado,sexo,situacion,evaluados,num_evaluados,total_evaluaciones,ultimo_acceso,nivel_acceso) VALUES (1045,'LICENCIATURA','analorena.camachoherrera','109343','TOMAR DEL SND','CAMACHO HERRERA ANA LORENA','INGENIERIA AEROESPACIAL','10mo','FEMENINO','ACTIVO','',0,0,'','ALUMNO'); | M46: =CONCATENATE("update participantes set correo=",C46," where id=",A46,";") -> update participantes set correo='analorena.camachoherrera' where id=1045;
A47: =A46+1 -> 1046 | B47: 'LICENCIATURA' | C47: =CONCATENATE("'",ALUMNOS!E49,"'") -> 'analucia.fongurquidy' | D47: =CONCATENATE(ALUMNOS!F49,"'") -> '111097' | E47: TOMAR DEL SND' | F47: =CONCATENATE("'",ALUMNOS!H49,"'") -> 'FONG URQUIDY ANA LUCIA' | G47: =CONCATENATE("'",ALUMNOS!I49,"'") -> 'ARQUITECTURA' | H47: =CONCATENATE("'",ALUMNOS!J49,"'") -> '4to' | I47: =CONCATENATE("'",ALUMNOS!K49,"'") -> 'Femenino' | J47: =CONCATENATE("'",ALUMNOS!L49,"'") -> 'Activo' | K47: =CONCATENATE(A47,",",B47,",",C47,",",D47,",'",E47,",",F47,",",G47,",",H47,",",UPPER(I47),",",UPPER(J47),",'',0,0,'','ALUMNO'") -> 1046,'LICENCIATURA','analucia.fongurquidy','111097','TOMAR DEL SND','FONG URQUIDY ANA LUCIA','ARQUITECTURA','4to','FEMENINO','ACTIVO','',0,0,'','ALUMNO' | L47: =CONCATENATE($K$1,K47,");") -> INSERT INTO participantes (id,nivel,correo,matricula,clave,nombre,carrera,grado,sexo,situacion,evaluados,num_evaluados,total_evaluaciones,ultimo_acceso,nivel_acceso) VALUES (1046,'LICENCIATURA','analucia.fongurquidy','111097','TOMAR DEL SND','FONG URQUIDY ANA LUCIA','ARQUITECTURA','4to','FEMENINO','ACTIVO','',0,0,'','ALUMNO'); | M47: =CONCATENATE("update participantes set correo=",C47," where id=",A47,";") -> update participantes set correo='analucia.fongurquidy' where id=1046;
A48: =A47+1 -> 1047 | B48: 'LICENCIATURA' | C48: =CONCATENATE("'",ALUMNOS!E50,"'") -> 'anapaula.rodriguezlozano' | D48: =CONCATENATE(ALUMNOS!F50,"'") -> '109961' | E48: TOMAR DEL SND' | F48: =CONCATENATE("'",ALUMNOS!H50,"'") -> 'RODRIGUEZ LOZANO ANA PAULA' | G48: =CONCATENATE("'",ALUMNOS!I50,"'") -> 'PSICOLOGIA' | H48: =CONCATENATE("'",ALUMNOS!J50,"'") -> '8vo' | I48: =CONCATENATE("'",ALUMNOS!K50,"'") -> 'Femenino' | J48: =CONCATENATE("'",ALUMNOS!L50,"'") -> 'Activo' | K48: =CONCATENATE(A48,",",B48,",",C48,",",D48,",'",E48,",",F48,",",G48,",",H48,",",UPPER(I48),",",UPPER(J48),",'',0,0,'','ALUMNO'") -> 1047,'LICENCIATURA','anapaula.rodriguezlozano','109961','TOMAR DEL SND','RODRIGUEZ LOZANO ANA PAULA','PSICOLOGIA','8vo','FEMENINO','ACTIVO','',0,0,'','ALUMNO' | L48: =CONCATENATE($K$1,K48,");") -> INSERT INTO participantes (id,nivel,correo,matricula,clave,nombre,carrera,grado,sexo,situacion,evaluados,num_evaluados,total_evaluaciones,ultimo_acceso,nivel_acceso) VALUES (1047,'LICENCIATURA','anapaula.rodriguezlozano','109961','TOMAR DEL SND','RODRIGUEZ LOZANO ANA PAULA','PSICOLOGIA','8vo','FEMENINO','ACTIVO','',0,0,'','ALUMNO'); | M48: =CONCATENATE("update participantes set correo=",C48," where id=",A48,";") -> update participantes set correo='anapaula.rodriguezlozano' where id=1047;
A49: =A48+1 -> 1048 | B49: 'LICENCIATURA' | C49: =CONCATENATE("'",ALUMNOS!E51,"'") -> 'anapaula.ruelasnavarro' | D49: =CONCATENATE(ALUMNOS!F51,"'") -> '111152' | E49: TOMAR DEL SND' | F49: =CONCATENATE("'",ALUMNOS!H51,"'") -> 'RUELAS NAVARRO ANA PAULA' | G49: =CONCATENATE("'",ALUMNOS!I51,"'") -> 'PSICOLOGIA' | H49: =CONCATENATE("'",ALUMNOS!J51,"'") -> '4to' | I49: =CONCATENATE("'",ALUMNOS!K51,"'") -> 'Femenino' | J49: =CONCATENATE("'",ALUMNOS!L51,"'") -> 'Activo' | K49: =CONCATENATE(A49,",",B49,",",C49,",",D49,",'",E49,",",F49,",",G49,",",H49,",",UPPER(I49),",",UPPER(J49),",'',0,0,'','ALUMNO'") -> 1048,'LICENCIATURA','anapaula.ruelasnavarro','111152','TOMAR DEL SND','RUELAS NAVARRO ANA PAULA','PSICOLOGIA','4to','FEMENINO','ACTIVO','',0,0,'','ALUMNO' | L49: =CONCATENATE($K$1,K49,");") -> INSERT INTO participantes (id,nivel,correo,matricula,clave,nombre,carrera,grado,sexo,situacion,evaluados,num_evaluados,total_evaluaciones,ultimo_acceso,nivel_acceso) VALUES (1048,'LICENCIATURA','anapaula.ruelasnavarro','111152','TOMAR DEL SND','RUELAS NAVARRO ANA PAULA','PSICOLOGIA','4to','FEMENINO','ACTIVO','',0,0,'','ALUMNO'); | M49: =CONCATENATE("update participantes set correo=",C49," where id=",A49,";") -> update participantes set correo='anapaula.ruelasnavarro' where id=1048;
A50: =A49+1 -> 1049 | B50: 'LICENCIATURA' | C50: =CONCATENATE("'",ALUMNOS!E52,"'") -> 'anasofia.carrionlopez' | D50: =CONCATENATE(ALUMNOS!F52,"'") -> '111799' | E50: TOMAR DEL SND' | F50: =CONCATENATE("'",ALUMNOS!H52,"'") -> 'CARRION LOPEZ ANA SOFIA' | G50: =CONCATENATE("'",ALUMNOS!I52,"'") -> 'ANIMACION DIGITAL Y VIDEOJUEGOS' | H50: =CONCATENATE("'",ALUMNOS!J52,"'") -> '2do' | I50: =CONCATENATE("'",ALUMNOS!K52,"'") -> 'Femenino' | J50: =CONCATENATE("'",ALUMNOS!L52,"'") -> 'Activo' | K50: =CONCATENATE(A50,",",B50,",",C50,",",D50,",'",E50,",",F50,",",G50,",",H50,",",UPPER(I50),",",UPPER(J50),",'',0,0,'','ALUMNO'") -> 1049,'LICENCIATURA','anasofia.carrionlopez','111799','TOMAR DEL SND','CARRION LOPEZ ANA SOFIA','ANIMACION DIGITAL Y VIDEOJUEGOS','2do','FEMENINO','ACTIVO','',0,0,'','ALUMNO' | L50: =CONCATENATE($K$1,K50,");") -> INSERT INTO participantes (id,nivel,correo,matricula,clave,nombre,carrera,grado,sexo,situacion,evaluados,num_evaluados,total_evaluaciones,ultimo_acceso,nivel_acceso) VALUES (1049,'LICENCIATURA','anasofia.carrionlopez','111799','TOMAR DEL SND','CARRION LOPEZ ANA SOFIA','ANIMACION DIGITAL Y VIDEOJUEGOS','2do','FEMENINO','ACTIVO','',0,0,'','ALUMNO'); | M50: =CONCATENATE("update participantes set correo=",C50," where id=",A50,";") -> update participantes set correo='anasofia.carrionlopez' where id=1049;
A51: =A50+1 -> 1050 | B51: 'LICENCIATURA' | C51: =CONCATENATE("'",ALUMNOS!E53,"'") -> 'anasofia.fierrosluna' | D51: =CONCATENATE(ALUMNOS!F53,"'") -> '111625' | E51: TOMAR DEL SND' | F51: =CONCATENATE("'",ALUMNOS!H53,"'") -> 'FIERROS LUNA ANA SOFIA' | G51: =CONCATENATE("'",ALUMNOS!I53,"'") -> 'INGENIERÍA AUTOMOTRIZ' | H51: =CONCATENATE("'",ALUMNOS!J53,"'") -> '2do' | I51: =CONCATENATE("'",ALUMNOS!K53,"'") -> 'Femenino' | J51: =CONCATENATE("'",ALUMNOS!L53,"'") -> 'Activo' | K51: =CONCATENATE(A51,",",B51,",",C51,",",D51,",'",E51,",",F51,",",G51,",",H51,",",UPPER(I51),",",UPPER(J51),",'',0,0,'','ALUMNO'") -> 1050,'LICENCIATURA','anasofia.fierrosluna','111625','TOMAR DEL SND','FIERROS LUNA ANA SOFIA','INGENIERÍA AUTOMOTRIZ','2do','FEMENINO','ACTIVO','',0,0,'','ALUMNO' | L51: =CONCATENATE($K$1,K51,");") -> INSERT INTO participantes (id,nivel,correo,matricula,clave,nombre,carrera,grado,sexo,situacion,evaluados,num_evaluados,total_evaluaciones,ultimo_acceso,nivel_acceso) VALUES (1050,'LICENCIATURA','anasofia.fierrosluna','111625','TOMAR DEL SND','FIERROS LUNA ANA SOFIA','INGENIERÍA AUTOMOTRIZ','2do','FEMENINO','ACTIVO','',0,0,'','ALUMNO'); | M51: =CONCATENATE("update participantes set correo=",C51," where id=",A51,";") -> update participantes set correo='anasofia.fierrosluna' where id=1050;
A52: =A51+1 -> 1051 | B52: 'LICENCIATURA' | C52: =CONCATENATE("'",ALUMNOS!E54,"'") -> 'anasofia.sanchezesqueda' | D52: =CONCATENATE(ALUMNOS!F54,"'") -> '109811' | E52: TOMAR DEL SND' | F52: =CONCATENATE("'",ALUMNOS!H54,"'") -> 'SANCHEZ ESQUEDA ANA SOFIA' | G52: =CONCATENATE("'",ALUMNOS!I54,"'") -> 'NUTRICION Y GASTRONOMIA' | H52: =CONCATENATE("'",ALUMNOS!J54,"'") -> '8vo' | I52: =CONCATENATE("'",ALUMNOS!K54,"'") -> 'Femenino' | J52: =CONCATENATE("'",ALUMNOS!L54,"'") -> 'Activo' | K52: =CONCATENATE(A52,",",B52,",",C52,",",D52,",'",E52,",",F52,",",G52,",",H52,",",UPPER(I52),",",UPPER(J52),",'',0,0,'','ALUMNO'") -> 1051,'LICENCIATURA','anasofia.sanchezesqueda','109811','TOMAR DEL SND','SANCHEZ ESQUEDA ANA SOFIA','NUTRICION Y GASTRONOMIA','8vo','FEMENINO','ACTIVO','',0,0,'','ALUMNO' | L52: =CONCATENATE($K$1,K52,");") -> INSERT INTO participantes (id,nivel,correo,matricula,clave,nombre,carrera,grado,sexo,situacion,evaluados,num_evaluados,total_evaluaciones,ultimo_acceso,nivel_acceso) VALUES (1051,'LICENCIATURA','anasofia.sanchezesqueda','109811','TOMAR DEL SND','SANCHEZ ESQUEDA ANA SOFIA','NUTRICION Y GASTRONOMIA','8vo','FEMENINO','ACTIVO','',0,0,'','ALUMNO'); | M52: =CONCATENATE("update participantes set correo=",C52," where id=",A52,";") -> update participantes set correo='anasofia.sanchezesqueda' where id=1051;
A53: =A52+1 -> 1052 | B53: 'LICENCIATURA' | C53: =CONCATENATE("'",ALUMNOS!E55,"'") -> 'anavaleria.godinezsanchez' | D53: =CONCATENATE(ALUMNOS!F55,"'") -> '111604' | E53: TOMAR DEL SND' | F53: =CONCATENATE("'",ALUMNOS!H55,"'") -> 'GODINEZ SANCHEZ ANA VALERIA' | G53: =CONCATENATE("'",ALUMNOS!I55,"'") -> 'PSICOLOGIA' | H53: =CONCATENATE("'",ALUMNOS!J55,"'") -> '2do' | I53: =CONCATENATE("'",ALUMNOS!K55,"'") -> 'Femenino' | J53: =CONCATENATE("'",ALUMNOS!L55,"'") -> 'Activo' | K53: =CONCATENATE(A53,",",B53,",",C53,",",D53,",'",E53,",",F53,",",G53,",",H53,",",UPPER(I53),",",UPPER(J53),",'',0,0,'','ALUMNO'") -> 1052,'LICENCIATURA','anavaleria.godinezsanchez','111604','TOMAR DEL SND','GODINEZ SANCHEZ ANA VALERIA','PSICOLOGIA','2do','FEMENINO','ACTIVO','',0,0,'','ALUMNO' | L53: =CONCATENATE($K$1,K53,");") -> INSERT INTO participantes (id,nivel,correo,matricula,clave,nombre,carrera,grado,sexo,situacion,evaluados,num_evaluados,total_evaluaciones,ultimo_acceso,nivel_acceso) VALUES (1052,'LICENCIATURA','anavaleria.godinezsanchez','111604','TOMAR DEL SND','GODINEZ SANCHEZ ANA VALERIA','PSICOLOGIA','2do','FEMENINO','ACTIVO','',0,0,'','ALUMNO'); | M53: =CONCATENATE("update participantes set correo=",C53," where id=",A53,";") -> update participantes set correo='anavaleria.godinezsanchez' where id=1052;
A54: =A53+1 -> 1053 | B54: 'LICENCIATURA' | C54: =CONCATENATE("'",ALUMNOS!E56,"'") -> 'anavictoria.orozcoquiñonez' | D54: =CONCATENATE(ALUMNOS!F56,"'") -> '110613' | E54: TOMAR DEL SND' | F54: =CONCATENATE("'",ALUMNOS!H56,"'") -> 'OROZCO QUIÑONEZ ANA VICTORIA' | G54: =CONCATENATE("'",ALUMNOS!I56,"'") -> 'ARQUITECTURA' | H54: =CONCATENATE("'",ALUMNOS!J56,"'") -> '6to' | I54: =CONCATENATE("'",ALUMNOS!K56,"'") -> 'Femenino' | J54: =CONCATENATE("'",ALUMNOS!L56,"'") -> 'Activo' | K54: =CONCATENATE(A54,",",B54,",",C54,",",D54,",'",E54,",",F54,",",G54,",",H54,",",UPPER(I54),",",UPPER(J54),",'',0,0,'','ALUMNO'") -> 1053,'LICENCIATURA','anavictoria.orozcoquiñonez','110613','TOMAR DEL SND','OROZCO QUIÑONEZ ANA VICTORIA','ARQUITECTURA','6to','FEMENINO','ACTIVO','',0,0,'','ALUMNO' | L54: =CONCATENATE($K$1,K54,");") -> INSERT INTO participantes (id,nivel,correo,matricula,clave,nombre,carrera,grado,sexo,situacion,evaluados,num_evaluados,total_evaluaciones,ultimo_acceso,nivel_acceso) VALUES (1053,'LICENCIATURA','anavictoria.orozcoquiñonez','110613','TOMAR DEL SND','OROZCO QUIÑONEZ ANA VICTORIA','ARQUITECTURA','6to','FEMENINO','ACTIVO','',0,0,'','ALUMNO'); | M54: =CONCATENATE("update participantes set correo=",C54," where id=",A54,";") -> update participantes set correo='anavictoria.orozcoquiñonez' where id=1053;
A55: =A54+1 -> 1054 | B55: 'LICENCIATURA' | C55: =CONCATENATE("'",ALUMNOS!E57,"'") -> 'anailyguadalupe.chavezortiz' | D55: =CONCATENATE(ALUMNOS!F57,"'") -> '111181' | E55: TOMAR DEL SND' | F55: =CONCATENATE("'",ALUMNOS!H57,"'") -> 'CHAVEZ ORTIZ ANAILY GUADALUPE' | G55: =CONCATENATE("'",ALUMNOS!I57,"'") -> 'ARQUITECTURA' | H55: =CONCATENATE("'",ALUMNOS!J57,"'") -> '4to' | I55: =CONCATENATE("'",ALUMNOS!K57,"'") -> 'Femenino' | J55: =CONCATENATE("'",ALUMNOS!L57,"'") -> 'Activo' | K55: =CONCATENATE(A55,",",B55,",",C55,",",D55,",'",E55,",",F55,",",G55,",",H55,",",UPPER(I55),",",UPPER(J55),",'',0,0,'','ALUMNO'") -> 1054,'LICENCIATURA','anailyguadalupe.chavezortiz','111181','TOMAR DEL SND','CHAVEZ ORTIZ ANAILY GUADALUPE','ARQUITECTURA','4to','FEMENINO','ACTIVO','',0,0,'','ALUMNO' | L55: =CONCATENATE($K$1,K55,");") -> INSERT INTO participantes (id,nivel,correo,matricula,clave,nombre,carrera,grado,sexo,situacion,evaluados,num_evaluados,total_evaluaciones,ultimo_acceso,nivel_acceso) VALUES (1054,'LICENCIATURA','anailyguadalupe.chavezortiz','111181','TOMAR DEL SND','CHAVEZ ORTIZ ANAILY GUADALUPE','ARQUITECTURA','4to','FEMENINO','ACTIVO','',0,0,'','ALUMNO'); | M55: =CONCATENATE("update participantes set correo=",C55," where id=",A55,";") -> update participantes set correo='anailyguadalupe.chavezortiz' where id=1054;
A56: =A55+1 -> 1055 | B56: 'LICENCIATURA' | C56: =CONCATENATE("'",ALUMNOS!E58,"'") -> 'andre.diazmarquez' | D56: =CONCATENATE(ALUMNOS!F58,"'") -> '111675' | E56: TOMAR DEL SND' | F56: =CONCATENATE("'",ALUMNOS!H58,"'") -> 'DIAZ MARQUEZ ANDRE' | G56: =CONCATENATE("'",ALUMNOS!I58,"'") -> 'INGENIERÍA AUTOMOTRIZ' | H56: =CONCATENATE("'",ALUMNOS!J58,"'") -> '2do' | I56: =CONCATENATE("'",ALUMNOS!K58,"'") -> 'Masculino' | J56: =CONCATENATE("'",ALUMNOS!L58,"'") -> 'Activo' | K56: =CONCATENATE(A56,",",B56,",",C56,",",D56,",'",E56,",",F56,",",G56,",",H56,",",UPPER(I56),",",UPPER(J56),",'',0,0,'','ALUMNO'") -> 1055,'LICENCIATURA','andre.diazmarquez','111675','TOMAR DEL SND','DIAZ MARQUEZ ANDRE','INGENIERÍA AUTOMOTRIZ','2do','MASCULINO','ACTIVO','',0,0,'','ALUMNO' | L56: =CONCATENATE($K$1,K56,");") -> INSERT INTO participantes (id,nivel,correo,matricula,clave,nombre,carrera,grado,sexo,situacion,evaluados,num_evaluados,total_evaluaciones,ultimo_acceso,nivel_acceso) VALUES (1055,'LICENCIATURA','andre.diazmarquez','111675','TOMAR DEL SND','DIAZ MARQUEZ ANDRE','INGENIERÍA AUTOMOTRIZ','2do','MASCULINO','ACTIVO','',0,0,'','ALUMNO'); | M56: =CONCATENATE("update participantes set correo=",C56," where id=",A56,";") -> update participantes set correo='andre.diazmarquez' where id=1055;
...
