Workbook

Sheet Hoja2
A1: Nível | B1: Nombre Maestro | C1: Paterno Maestro | D1: Materno Maestro | E1: Maestro | F1: Nombre | G1: Sexo | H1: correo
A2: LICENCIATURA | B2: AIDA CITLALI | C2: HERNANDEZ | D2: MONTAÑO | E2: HMA1841 | F2: HERNANDEZ MONTAÑO AIDA CITLALI | G2: FEMENINO | H2: aidacitlali.hernandezmontaño
A3: LICENCIATURA | B3: ALAM | C3: GOMEZ | D3: CANALES | E3: GCA1735 | F3: GOMEZ CANALES ALAM | G3: MASCULINO | H3: alam.gomezcanales
A4: LICENCIATURA | B4: ALDO EVERARDO | C4: GONZALEZ | D4: PULIDO | E4: GPA1916 | F4: GONZALEZ PULIDO ALDO EVERARDO | G4: MASCULINO | H4: aldoeverardo.gonzalezpulido
A5: LICENCIATURA | B5: ALDO MACIEL | C5: RUIZ | D5: AREVALO | E5: RAA1942 | F5: RUIZ AREVALO ALDO MACIEL | G5: MASCULINO | H5: aldomaciel.ruizarevalo
A6: LICENCIATURA | B6: ALEJANDRA | C6: CHAVEZ | D6: OSORIO | E6: COA1894 | F6: CHAVEZ OSORIO ALEJANDRA | G6: FEMENINO | H6: alejandra.chavezosorio
A7: LICENCIATURA | B7: ALEJANDRO | C7: URIBE | D7: LOPEZ | E7: ULA0927 | F7: URIBE LOPEZ ALEJANDRO | G7: MASCULINO | H7: alejandro.uribelopez
A8: LICENCIATURA | B8: ALFONSO | C8: ASCENCIO | D8: RUBIO | E8: ARA0918 | F8: ASCENCIO RUBIO ALFONSO | G8: MASCULINO | H8: alfonso.ascenciorubio
A9: LICENCIATURA | B9: ALFREDO | C9: GARCIA | D9: VALDERRAMA | E9: GVA1919 | F9: GARCIA VALDERRAMA ALFREDO | G9: MASCULINO | H9: alfredo.garciavalderrama
A10: LICENCIATURA | B10: ALFREDO DE JESUS | C10: VELAZQUEZ | D10: SANTOS | E10: VSA1861 | F10: VELAZQUEZ SANTOS ALFREDO DE JESUS | G10: MASCULINO | H10: alfredodejesus.velazquezsantos
A11: LICENCIATURA | B11: ALMA DANIELA | C11: VELAZQUEZ | D11: NAVARRETE | E11: VNA1925 | F11: VELAZQUEZ NAVARRETE ALMA DANIELA | G11: FEMENINO | H11: almadaniela.velazqueznavarrete
A12: LICENCIATURA | B12: ALVARO | C12: MORENO | D12: CORRAL | E12: MCA1844 | F12: MORENO CORRAL ALVARO | G12: MASCULINO | H12: alvaro.morenocorral
... A179: LICENCIATURA | B179: ZAIRA MARLENE | C179: ZAMBRANO | D179: LOPEZ | E179: ZLZ1862 | F179: ZAMBRANO LOPEZ ZAIRA MARLENE | G179: FEMENINO | H179: zairamarlene.zambranolopez

Sheet Hoja1
A1: Nível | B1: Carrera | C1: Grupo | D1: Nombre | E1: Materia | F1: Sexo
A2: LICENCIATURA | B2: MATERIAS INSTITUCIONALES | C2: TC 0503 1 | D2: LUNA HERRERA JOSE CARLOS | E2: CIUDADANIA Y DESARROLLO PROFESIONAL | F2: MASCULINO
A3: LICENCIATURA | B3: MATERIAS INSTITUCIONALES | C3: TC 0503 2 | D3: TAPIA VELAZQUEZ FRANCISCO | E3: CIUDADANIA Y DESARROLLO PROFESIONAL | F3: MASCULINO
A4: LICENCIATURA | B4: MATERIAS INSTITUCIONALES | C4: TC 0601 1 | D4: CHAN NUÑEZ MARIA ELENA | E4: ESCENARIO DE INTERVENCION SOCIAL I | F4: FEMENINO
A5: LICENCIATURA | B5: MATERIAS INSTITUCIONALES | C5: TC 0603 1 | D5: LUNA HERRERA JOSE CARLOS | E5: LIDERAZGO Y MANEJO DE GRUPOS | F5: MASCULINO
A6: LICENCIATURA | B6: MATERIAS INSTITUCIONALES | C6: TC 0801 | D6: CHAN NUÑEZ MARIA ELENA | E6: ESCENARIO DE INTERVENCION III | F6: FEMENINO
A7: LICENCIATURA | B7: MATERIAS INSTITUCIONALES | C7: TC0201 1 | D7: HERNANDEZ MONTAÑO AIDA CITLALI | E7: EXPERIENCIA DE ACCION SOCIAL | F7: FEMENINO
A8: LICENCIATURA | B8: MATERIAS INSTITUCIONALES | C8: TC0201 2 | D8: AGUILAR CEBALLOS CARLA MARIANA | E8: EXPERIENCIA DE ACCION SOCIAL | F8: FEMENINO
A9: LICENCIATURA | B9: MATERIAS INSTITUCIONALES | C9: TC0201 3 | D9: FARIAS CASTELLANOS ISIS | E9: EXPERIENCIA DE ACCION SOCIAL | F9: FEMENINO
A10: LICENCIATURA | B10: MATERIAS INSTITUCIONALES | C10: TC0201 4 | D10: CASILLAS MORA MONICA DANIELA | E10: EXPERIENCIA DE ACCION SOCIAL | F10: FEMENINO
A11: LICENCIATURA | B11: MATERIAS INSTITUCIONALES | C11: TC0201 5 | D11: HERNANDEZ MONTAÑO AIDA CITLALI | E11: EXPERIENCIA DE ACCION SOCIAL | F11: FEMENINO
A12: LICENCIATURA | B12: MATERIAS INSTITUCIONALES | C12: TC0201 6 | D12: AGUILAR CEBALLOS CARLA MARIANA | E12: EXPERIENCIA DE ACCION SOCIAL | F12: FEMENINO
... A329: LICENCIATURA | B329: PSICOLOGIA | C329: PSI 8° | D329: SALCEDO ROSALES ERIKA IVETTE | E329: TENDENCIAS CONTEMPORANEAS DE LA PSICOLOGIA | F329: FEMENINO

Sheet PARTICIPANTES
A1: id | B1: Nivel | C1: Correo | D1: matricula | E1: clave | F1: Nombre | G1: carrera | H1: grado | I1: sexo | J1: situacion | K1: =CONCATENATE("INSERT INTO participantes (",L1,") VALUES (") -> INSERT INTO participantes (id,nivel,correo,matricula,clave,nombre,carrera,grado,sexo,situacion,evaluados,num_evaluados,total_evaluaciones,ultimo_acceso,nivel_acceso) VALUES ( | L1: id,nivel,correo,matricula,clave,nombre,carrera,grado,sexo,situacion,evaluados,num_evaluados,total_evaluaciones,ultimo_acceso,nivel_acceso
A2: 2001 | B2: 'LICENCIATURA' | C2: =Hoja2!H2 -> aidacitlali.hernandezmontaño | D2: =Hoja2!E2 -> HMA1841 | E2: TOMAR DEL SND' | F2: =Hoja2!F2 -> HERNANDEZ MONTAÑO AIDA CITLALI | G2: PROFESORES | I2: =Hoja2!G2 -> FEMENINO | K2: =CONCATENATE(A2,",",B2,",'",C2,"','",D2,"','",E2,",'",F2,"','",G2,"','",H2,"','",UPPER(I2),"','",UPPER(J2),"','',0,0,'','PROFESOR'") -> 2001,'LICENCIATURA','aidacitlali.hernandezmontaño','HMA1841','TOMAR DEL SND','HERNANDEZ MONTAÑO AIDA CITLALI','PROFESORES','','FEMENINO','','',0,0,'','PROFESOR' | L2: =CONCATENATE($K$1,K2,");") -> INSERT INTO participantes (id,nivel,correo,matricula,clave,nombre,carrera,grado,sexo,situacion,evaluados,num_evaluados,total_evaluaciones,ultimo_acceso,nivel_acceso) VALUES (2001,'LICENCIATURA','aidacitlali.hernandezmontaño','HMA1841','TOMAR DEL SND','HERNANDEZ MONTAÑO AIDA CITLALI','PROFESORES','','FEMENINO','','',0,0,'','PROFESOR');
A3: =A2+1 -> 2002 | B3: 'LICENCIATURA' | C3: =Hoja2!H3 -> alam.gomezcanales | D3: =Hoja2!E3 -> GCA1735 | E3: TOMAR DEL SND' | F3: =Hoja2!F3 -> GOMEZ CANALES ALAM | G3: PROFESORES | I3: =Hoja2!G3 -> MASCULINO | K3: =CONCATENATE(A3,",",B3,",'",C3,"','",D3,"','",E3,",'",F3,"','",G3,"','",H3,"','",UPPER(I3),"','",UPPER(J3),"','',0,0,'','PROFESOR'") -> 2002,'LICENCIATURA','alam.gomezcanales','GCA1735','TOMAR DEL SND','GOMEZ CANALES ALAM','PROFESORES','','MASCULINO','','',0,0,'','PROFESOR' | L3: =CONCATENATE($K$1,K3,");") -> INSERT INTO participantes (id,nivel,correo,matricula,clave,nombre,carrera,grado,sexo,situacion,evaluados,num_evaluados,total_evaluaciones,ultimo_acceso,nivel_acceso) VALUES (2002,'LICENCIATURA','alam.gomezcanales','GCA1735','TOMAR DEL SND','GOMEZ CANALES ALAM','PROFESORES','','MASCULINO','','',0,0,'','PROFESOR');
A4: =A3+1 -> 2003 | B4: 'LICENCIATURA' | C4: =Hoja2!H4 -> aldoeverardo.gonzalezpulido | D4: =Hoja2!E4 -> GPA1916 | E4: TOMAR DEL SND' | F4: =Hoja2!F4 -> GONZALEZ PULIDO ALDO EVERARDO | G4: PROFESORES | I4: =Hoja2!G4 -> MASCULINO | K4: =CONCATENATE(A4,",",B4,",'",C4,"','",D4,"','",E4,",'",F4,"','",G4,"','",H4,"','",UPPER(I4),"','",UPPER(J4),"','',0,0,'','PROFESOR'") -> 2003,'LICENCIATURA','aldoeverardo.gonzalezpulido','GPA1916','TOMAR DEL SND','GONZALEZ PULIDO ALDO EVERARDO','PROFESORES','','MASCULINO','','',0,0,'','PROFESOR' | L4: =CONCATENATE($K$1,K4,");") -> INSERT INTO participantes (id,nivel,correo,matricula,clave,nombre,carrera,grado,sexo,situacion,evaluados,num_evaluados,total_evaluaciones,ultimo_acceso,nivel_acceso) VALUES (2003,'LICENCIATURA','aldoeverardo.gonzalezpulido','GPA1916','TOMAR DEL SND','GONZALEZ PULIDO ALDO EVERARDO','PROFESORES','','MASCULINO','','',0,0,'','PROFESOR');
A5: =A4+1 -> 2004 | B5: 'LICENCIATURA' | C5: =Hoja2!H5 -> aldomaciel.ruizarevalo | D5: =Hoja2!E5 -> RAA1942 | E5: TOMAR DEL SND' | F5: =Hoja2!F5 -> RUIZ AREVALO ALDO MACIEL | G5: PROFESORES | I5: =Hoja2!G5 -> MASCULINO | K5: =CONCATENATE(A5,",",B5,",'",C5,"','",D5,"','",E5,",'",F5,"','",G5,"','",H5,"','",UPPER(I5),"','",UPPER(J5),"','',0,0,'','PROFESOR'") -> 2004,'LICENCIATURA','aldomaciel.ruizarevalo','RAA1942','TOMAR DEL SND','RUIZ AREVALO ALDO MACIEL','PROFESORES','','MASCULINO','','',0,0,'','PROFESOR' | L5: =CONCATENATE($K$1,K5,");") -> INSERT INTO participantes (id,nivel,correo,matricula,clave,nombre,carrera,grado,sexo,situacion,evaluados,num_evaluados,total_evaluaciones,ultimo_acceso,nivel_acceso) VALUES (2004,'LICENCIATURA','aldomaciel.ruizarevalo','RAA1942','TOMAR DEL SND','RUIZ AREVALO ALDO MACIEL','PROFESORES','','MASCULINO','','',0,0,'','PROFESOR');
A6: =A5+1 -> 2005 | B6: 'LICENCIATURA' | C6: =Hoja2!H6 -> alejandra.chavezosorio | D6: =Hoja2!E6 -> COA1894 | E6: TOMAR DEL SND' | F6: =Hoja2!F6 -> CHAVEZ OSORIO ALEJANDRA | G6: PROFESORES | I6: =Hoja2!G6 -> FEMENINO | K6: =CONCATENATE(A6,",",B6,",'",C6,"','",D6,"','",E6,",'",F6,"','",G6,"','",H6,"','",UPPER(I6),"','",UPPER(J6),"','',0,0,'','PROFESOR'") -> 2005,'LICENCIATURA','alejandra.chavezosorio','COA1894','TOMAR DEL SND','CHAVEZ OSORIO ALEJANDRA','PROFESORES','','FEMENINO','','',0,0,'','PROFESOR' | L6: =CONCATENATE($K$1,K6,");") -> INSERT INTO participantes (id,nivel,correo,matricula,clave,nombre,carrera,grado,sexo,situacion,evaluados,num_evaluados,total_evaluaciones,ultimo_acceso,nivel_acceso) VALUES (2005,'LICENCIATURA','alejandra.chavezosorio','COA1894','TOMAR DEL SND','CHAVEZ OSORIO ALEJANDRA','PROFESORES','','FEMENINO','','',0,0,'','PROFESOR');
A7: =A6+1 -> 2006 | B7: 'LICENCIATURA' | C7: =Hoja2!H7 -> alejandro.uribelopez | D7: =Hoja2!E7 -> ULA0927 | E7: TOMAR DEL SND' | F7: =Hoja2!F7 -> URIBE LOPEZ ALEJANDRO | G7: PROFESORES | I7: =Hoja2!G7 -> MASCULINO | K7: =CONCATENATE(A7,",",B7,",'",C7,"','",D7,"','",E7,",'",F7,"','",G7,"','",H7,"','",UPPER(I7),"','",UPPER(J7),"','',0,0,'','PROFESOR'") -> 2006,'LICENCIATURA','alejandro.uribelopez','ULA0927','TOMAR DEL SND','URIBE LOPEZ ALEJANDRO','PROFESORES','','MASCULINO','','',0,0,'','PROFESOR' | L7: =CONCATENATE($K$1,K7,");") -> INSERT INTO participantes (id,nivel,correo,matricula,clave,nombre,carrera,grado,sexo,situacion,evaluados,num_evaluados,total_evaluaciones,ultimo_acceso,nivel_acceso) VALUES (2006,'LICENCIATURA','alejandro.uribelopez','ULA0927','TOMAR DEL SND','URIBE LOPEZ ALEJANDRO','PROFESORES','','MASCULINO','','',0,0,'','PROFESOR');
A8: =A7+1 -> 2007 | B8: 'LICENCIATURA' | C8: =Hoja2!H8 -> alfonso.ascenciorubio | D8: =Hoja2!E8 -> ARA0918 | E8: TOMAR DEL SND' | F8: =Hoja2!F8 -> ASCENCIO RUBIO ALFONSO | G8: PROFESORES | I8: =Hoja2!G8 -> MASCULINO | K8: =CONCATENATE(A8,",",B8,",'",C8,"','",D8,"','",E8,",'",F8,"','",G8,"','",H8,"','",UPPER(I8),"','",UPPER(J8),"','',0,0,'','PROFESOR'") -> 2007,'LICENCIATURA','alfonso.ascenciorubio','ARA0918','TOMAR DEL SND','ASCENCIO RUBIO ALFONSO','PROFESORES','','MASCULINO','','',0,0,'','PROFESOR' | L8: =CONCATENATE($K$1,K8,");") -> INSERT INTO participantes (id,nivel,correo,matricula,clave,nombre,carrera,grado,sexo,situacion,evaluados,num_evaluados,total_evaluaciones,ultimo_acceso,nivel_acceso) VALUES (2007,'LICENCIATURA','alfonso.ascenciorubio','ARA0918','TOMAR DEL SND','ASCENCIO RUBIO ALFONSO','PROFESORES','','MASCULINO','','',0,0,'','PROFESOR');
A9: =A8+1 -> 2008 | B9: 'LICENCIATURA' | C9: =Hoja2!H9 -> alfredo.garciavalderrama | D9: =Hoja2!E9 -> GVA1919 | E9: TOMAR DEL SND' | F9: =Hoja2!F9 -> GARCIA VALDERRAMA ALFREDO | G9: PROFESORES | I9: =Hoja2!G9 -> MASCULINO | K9: =CONCATENATE(A9,",",B9,",'",C9,"','",D9,"','",E9,",'",F9,"','",G9,"','",H9,"','",UPPER(I9),"','",UPPER(J9),"','',0,0,'','PROFESOR'") -> 2008,'LICENCIATURA','alfredo.garciavalderrama','GVA1919','TOMAR DEL SND','GARCIA VALDERRAMA ALFREDO','PROFESORES','','MASCULINO','','',0,0,'','PROFESOR' | L9: =CONCATENATE($K$1,K9,");") -> INSERT INTO participantes (id,nivel,correo,matricula,clave,nombre,carrera,grado,sexo,situacion,evaluados,num_evaluados,total_evaluaciones,ultimo_acceso,nivel_acceso) VALUES (2008,'LICENCIATURA','alfredo.garciavalderrama','GVA1919','TOMAR DEL SND','GARCIA VALDERRAMA ALFREDO','PROFESORES','','MASCULINO','','',0,0,'','PROFESOR');
A10: =A9+1 -> 2009 | B10: 'LICENCIATURA' | C10: =Hoja2!H10 -> alfredodejesus.velazquezsantos | D10: =Hoja2!E10 -> VSA1861 | E10: TOMAR DEL SND' | F10: =Hoja2!F10 -> VELAZQUEZ SANTOS ALFREDO DE JESUS | G10: PROFESORES | I10: =Hoja2!G10 -> MASCULINO | K10: =CONCATENATE(A10,",",B10,",'",C10,"','",D10,"','",E10,",'",F10,"','",G10,"','",H10,"','",UPPER(I10),"','",UPPER(J10),"','',0,0,'','PROFESOR'") -> 2009,'LICENCIATURA','alfredodejesus.velazquezsantos','VSA1861','TOMAR DEL SND','VELAZQUEZ SANTOS ALFREDO DE JESUS','PROFESORES','','MASCULINO','','',0,0,'','PROFESOR' | L10: =CONCATENATE($K$1,K10,");") -> INSERT INTO participantes (id,nivel,correo,matricula,clave,nombre,carrera,grado,sexo,situacion,evaluados,num_evaluados,total_evaluaciones,ultimo_acceso,nivel_acceso) VALUES (2009,'LICENCIATURA','alfredodejesus.velazquezsantos','VSA1861','TOMAR DEL SND','VELAZQUEZ SANTOS ALFREDO DE JESUS','PROFESORES','','MASCULINO','','',0,0,'','PROFESOR');
A11: =A10+1 -> 2010 | B11: 'LICENCIATURA' | C11: =Hoja2!H11 -> almadaniela.velazqueznavarrete | D11: =Hoja2!E11 -> VNA1925 | E11: TOMAR DEL SND' | F11: =Hoja2!F11 -> VELAZQUEZ NAVARRETE ALMA DANIELA | G11: PROFESORES | I11: =Hoja2!G11 -> FEMENINO | K11: =CONCATENATE(A11,",",B11,",'",C11,"','",D11,"','",E11,",'",F11,"','",G11,"','",H11,"','",UPPER(I11),"','",UPPER(J11),"','',0,0,'','PROFESOR'") -> 2010,'LICENCIATURA','almadaniela.velazqueznavarrete','VNA1925','TOMAR DEL SND','VELAZQUEZ NAVARRETE ALMA DANIELA','PROFESORES','','FEMENINO','','',0,0,'','PROFESOR' | L11: =CONCATENATE($K$1,K11,");") -> INSERT INTO participantes (id,nivel,correo,matricula,clave,nombre,carrera,grado,sexo,situacion,evaluados,num_evaluados,total_evaluaciones,ultimo_acceso,nivel_acceso) VALUES (2010,'LICENCIATURA','almadaniela.velazqueznavarrete','VNA1925','TOMAR DEL SND','VELAZQUEZ NAVARRETE ALMA DANIELA','PROFESORES','','FEMENINO','','',0,0,'','PROFESOR');
A12: =A11+1 -> 2011 | B12: 'LICENCIATURA' | C12: =Hoja2!H12 -> alvaro.morenocorral | D12: =Hoja2!E12 -> MCA1844 | E12: TOMAR DEL SND' | F12: =Hoja2!F12 -> MORENO CORRAL ALVARO | G12: PROFESORES | I12: =Hoja2!G12 -> MASCULINO | K12: =CONCATENATE(A12,",",B12,",'",C12,"','",D12,"','",E12,",'",F12,"','",G12,"','",H12,"','",UPPER(I12),"','",UPPER(J12),"','',0,0,'','PROFESOR'") -> 2011,'LICENCIATURA','alvaro.morenocorral','MCA1844','TOMAR DEL SND','MORENO CORRAL ALVARO','PROFESORES','','MASCULINO','','',0,0,'','PROFESOR' | L12: =CONCATENATE($K$1,K12,");") -> INSERT INTO participantes (id,nivel,correo,matricula,clave,nombre,carrera,grado,sexo,situacion,evaluados,num_evaluados,total_evaluaciones,ultimo_acceso,nivel_acceso) VALUES (2011,'LICENCIATURA','alvaro.morenocorral','MCA1844','TOMAR DEL SND','MORENO CORRAL ALVARO','PROFESORES','','MASCULINO','','',0,0,'','PROFESOR');
A13: =A12+1 -> 2012 | B13: 'LICENCIATURA' | C13: =Hoja2!H13 -> alvaro.pujolbecerra | D13: =Hoja2!E13 -> PBA1849 | E13: TOMAR DEL SND' | F13: =Hoja2!F13 -> PUJOL BECERRA ALVARO | G13: PROFESORES | I13: =Hoja2!G13 -> MASCULINO | K13: =CONCATENATE(A13,",",B13,",'",C13,"','",D13,"','",E13,",'",F13,"','",G13,"','",H13,"','",UPPER(I13),"','",UPPER(J13),"','',0,0,'','PROFESOR'") -> 2012,'LICENCIATURA','alvaro.pujolbecerra','PBA1849','TOMAR DEL SND','PUJOL BECERRA ALVARO','PROFESORES','','MASCULINO','','',0,0,'','PROFESOR' | L13: =CONCATENATE($K$1,K13,");") -> INSERT INTO participantes (id,nivel,correo,matricula,clave,nombre,carrera,grado,sexo,situacion,evaluados,num_evaluados,total_evaluaciones,ultimo_acceso,nivel_acceso) VALUES (2012,'LICENCIATURA','alvaro.pujolbecerra','PBA1849','TOMAR DEL SND','PUJOL BECERRA ALVARO','PROFESORES','','MASCULINO','','',0,0,'','PROFESOR');
A14: =A13+1 -> 2013 | B14: 'LICENCIATURA' | C14: =Hoja2!H14 -> amandajanette.renteriajimenez | D14: =Hoja2!E14 -> RJA1850 | E14: TOMAR DEL SND' | F14: =Hoja2!F14 -> RENTERIA JIMENEZ AMANDA JANETTE | G14: PROFESORES | I14: =Hoja2!G14 -> FEMENINO | K14: =CONCATENATE(A14,",",B14,",'",C14,"','",D14,"','",E14,",'",F14,"','",G14,"','",H14,"','",UPPER(I14),"','",UPPER(J14),"','',0,0,'','PROFESOR'") -> 2013,'LICENCIATURA','amandajanette.renteriajimenez','RJA1850','TOMAR DEL SND','RENTERIA JIMENEZ AMANDA JANETTE','PROFESORES','','FEMENINO','','',0,0,'','PROFESOR' | L14: =CONCATENATE($K$1,K14,");") -> INSERT INTO participantes (id,nivel,correo,matricula,clave,nombre,carrera,grado,sexo,situacion,evaluados,num_evaluados,total_evaluaciones,ultimo_acceso,nivel_acceso) VALUES (2013,'LICENCIATURA','amandajanette.renteriajimenez','RJA1850','TOMAR DEL SND','RENTERIA JIMENEZ AMANDA JANETTE','PROFESORES','','FEMENINO','','',0,0,'','PROFESOR');
... A179: =A178+1 -> 2178 | B179: 'LICENCIATURA' | C179: =Hoja2!H179 -> zairamarlene.zambranolopez | D179: =Hoja2!E179 -> ZLZ1862 | E179: TOMAR DEL SND' | F179: =Hoja2!F179 -> ZAMBRANO LOPEZ ZAIRA MARLENE | G179: PROFESORES | I179: =Hoja2!G179 -> FEMENINO | K179: =CONCATENATE(A179,",",B179,",'",C179,"','",D179,"','",E179,",'",F179,"','",G179,"','",H179,"','",UPPER(I179),"','",UPPER(J179),"','',0,0,'','PROFESOR'") -> 2178,'LICENCIATURA','zairamarlene.zambranolopez','ZLZ1862','TOMAR DEL SND','ZAMBRANO LOPEZ ZAIRA MARLENE','PROFESORES','','FEMENINO','','',0,0,'','PROFESOR' | L179: =CONCATENATE($K$1,K179,");") -> INSERT INTO participantes (id,nivel,correo,matricula,clave,nombre,carrera,grado,sexo,situacion,evaluados,num_evaluados,total_evaluaciones,ultimo_acceso,nivel_acceso) VALUES (2178,'LICENCIATURA','zairamarlene.zambranolopez','ZLZ1862','TOMAR DEL SND','ZAMBRANO LOPEZ ZAIRA MARLENE','PROFESORES','','FEMENINO','','',0,0,'','PROFESOR');

Sheet Materias
A1: ID | B1: NIVEL | C1: Carrera | D1: Grupo | E1: Nombre | F1: Materia | G1: Sexo | H1: SELLO | I1: INSERT INTO profesores (id,nivel,carrera,grupo,nombre,materia,sexo,sello) VALUES (
A2: 1001 | B2: LICENCIATURA | C2: =Hoja1!B2 -> MATERIAS INSTITUCIONALES | D2: TC 0503 1' | E2: =Hoja1!D2 -> LUNA HERRERA JOSE CARLOS | F2: =Hoja1!E2 -> CIUDADANIA Y DESARROLLO PROFESIONAL | G2: =Hoja1!F2 -> MASCULINO | H2: =IF(C2="MATERIAS INSTITUCIONALES",1,0) -> 1 | I2: =CONCATENATE(A2,",'",B2,"','",C2,"','",D2,",'",E2,"','",F2,"','",G2,"',",H2) -> 1001,'LICENCIATURA','MATERIAS INSTITUCIONALES','TC 0503 1','LUNA HERRERA JOSE CARLOS','CIUDADANIA Y DESARROLLO PROFESIONAL','MASCULINO',1 | J2: =CONCATENATE($I$1,I2,");") -> INSERT INTO profesores (id,nivel,carrera,grupo,nombre,materia,sexo,sello) VALUES (1001,'LICENCIATURA','MATERIAS INSTITUCIONALES','TC 0503 1','LUNA HERRERA JOSE CARLOS','CIUDADANIA Y DESARROLLO PROFESIONAL','MASCULINO',1);
A3: =A2+1 -> 1002 | B3: LICENCIATURA | C3: =Hoja1!B3 -> MATERIAS INSTITUCIONALES | D3: TC 0503 2' | E3: =Hoja1!D3 -> TAPIA VELAZQUEZ FRANCISCO | F3: =Hoja1!E3 -> CIUDADANIA Y DESARROLLO PROFESIONAL | G3: =Hoja1!F3 -> MASCULINO | H3: =IF(C3="MATERIAS INSTITUCIONALES",1,0) -> 1 | I3: =CONCATENATE(A3,",'",B3,"','",C3,"','",D3,",'",E3,"','",F3,"','",G3,"',",H3) -> 1002,'LICENCIATURA','MATERIAS INSTITUCIONALES','TC 0503 2','TAPIA VELAZQUEZ FRANCISCO','CIUDADANIA Y DESARROLLO PROFESIONAL','MASCULINO',1 | J3: =CONCATENATE($I$1,I3,");") -> INSERT INTO profesores (id,nivel,carrera,grupo,nombre,materia,sexo,sello) VALUES (1002,'LICENCIATURA','MATERIAS INSTITUCIONALES','TC 0503 2','TAPIA VELAZQUEZ FRANCISCO','CIUDADANIA Y DESARROLLO PROFESIONAL','MASCULINO',1);
A4: =A3+1 -> 1003 | B4: LICENCIATURA | C4: =Hoja1!B4 -> MATERIAS INSTITUCIONALES | D4: TC 0601 1' | E4: =Hoja1!D4 -> CHAN NUÑEZ MARIA ELENA | F4: =Hoja1!E4 -> ESCENARIO DE INTERVENCION SOCIAL I | G4: =Hoja1!F4 -> FEMENINO | H4: =IF(C4="MATERIAS INSTITUCIONALES",1,0) -> 1 | I4: =CONCATENATE(A4,",'",B4,"','",C4,"','",D4,",'",E4,"','",F4,"','",G4,"',",H4) -> 1003,'LICENCIATURA','MATERIAS INSTITUCIONALES','TC 0601 1','CHAN NUÑEZ MARIA ELENA','ESCENARIO DE INTERVENCION SOCIAL I','FEMENINO',1 | J4: =CONCATENATE($I$1,I4,");") -> INSERT INTO profesores (id,nivel,carrera,grupo,nombre,materia,sexo,sello) VALUES (1003,'LICENCIATURA','MATERIAS INSTITUCIONALES','TC 0601 1','CHAN NUÑEZ MARIA ELENA','ESCENARIO DE INTERVENCION SOCIAL I','FEMENINO',1);
A5: =A4+1 -> 1004 | B5: LICENCIATURA | C5: =Hoja1!B5 -> MATERIAS INSTITUCIONALES | D5: TC 0603 1' | E5: =Hoja1!D5 -> LUNA HERRERA JOSE CARLOS | F5: =Hoja1!E5 -> LIDERAZGO Y MANEJO DE GRUPOS | G5: =Hoja1!F5 -> MASCULINO | H5: =IF(C5="MATERIAS INSTITUCIONALES",1,0) -> 1 | I5: =CONCATENATE(A5,",'",B5,"','",C5,"','",D5,",'",E5,"','",F5,"','",G5,"',",H5) -> 1004,'LICENCIATURA','MATERIAS INSTITUCIONALES','TC 0603 1','LUNA HERRERA JOSE CARLOS','LIDERAZGO Y MANEJO DE GRUPOS','MASCULINO',1 | J5: =CONCATENATE($I$1,I5,");") -> INSERT INTO profesores (id,nivel,carrera,grupo,nombre,materia,sexo,sello) VALUES (1004,'LICENCIATURA','MATERIAS INSTITUCIONALES','TC 0603 1','LUNA HERRERA JOSE CARLOS','LIDERAZGO Y MANEJO DE GRUPOS','MASCULINO',1);
A6: =A5+1 -> 1005 | B6: LICENCIATURA | C6: =Hoja1!B6 -> MATERIAS INSTITUCIONALES | D6: TC 0801' | E6: =Hoja1!D6 -> CHAN NUÑEZ MARIA ELENA | F6: =Hoja1!E6 -> ESCENARIO DE INTERVENCION III | G6: =Hoja1!F6 -> FEMENINO | H6: =IF(C6="MATERIAS INSTITUCIONALES",1,0) -> 1 | I6: =CONCATENATE(A6,",'",B6,"','",C6,"','",D6,",'",E6,"','",F6,"','",G6,"',",H6) -> 1005,'LICENCIATURA','MATERIAS INSTITUCIONALES','TC 0801','CHAN NUÑEZ MARIA ELENA','ESCENARIO DE INTERVENCION III','FEMENINO',1 | J6: =CONCATENATE($I$1,I6,");") -> INSERT INTO profesores (id,nivel,carrera,grupo,nombre,materia,sexo,sello) VALUES (1005,'LICENCIATURA','MATERIAS INSTITUCIONALES','TC 0801','CHAN NUÑEZ MARIA ELENA','ESCENARIO DE INTERVENCION III','FEMENINO',1);
A7: =A6+1 -> 1006 | B7: LICENCIATURA | C7: =Hoja1!B7 -> MATERIAS INSTITUCIONALES | D7: TC0201 1' | E7: =Hoja1!D7 -> HERNANDEZ MONTAÑO AIDA CITLALI | F7: =Hoja1!E7 -> EXPERIENCIA DE ACCION SOCIAL | G7: =Hoja1!F7 -> FEMENINO | H7: =IF(C7="MATERIAS INSTITUCIONALES",1,0) -> 1 | I7: =CONCATENATE(A7,",'",B7,"','",C7,"','",D7,",'",E7,"','",F7,"','",G7,"',",H7) -> 1006,'LICENCIATURA','MATERIAS INSTITUCIONALES','TC0201 1','HERNANDEZ MONTAÑO AIDA CITLALI','EXPERIENCIA DE ACCION SOCIAL','FEMENINO',1 | J7: =CONCATENATE($I$1,I7,");") -> INSERT INTO profesores (id,nivel,carrera,grupo,nombre,materia,sexo,sello) VALUES (1006,'LICENCIATURA','MATERIAS INSTITUCIONALES','TC0201 1','HERNANDEZ MONTAÑO AIDA CITLALI','EXPERIENCIA DE ACCION SOCIAL','FEMENINO',1);
A8: =A7+1 -> 1007 | B8: LICENCIATURA | C8: =Hoja1!B8 -> MATERIAS INSTITUCIONALES | D8: TC0201 2' | E8: =Hoja1!D8 -> AGUILAR CEBALLOS CARLA MARIANA | F8: =Hoja1!E8 -> EXPERIENCIA DE ACCION SOCIAL | G8: =Hoja1!F8 -> FEMENINO | H8: =IF(C8="MATERIAS INSTITUCIONALES",1,0) -> 1 | I8: =CONCATENATE(A8,",'",B8,"','",C8,"','",D8,",'",E8,"','",F8,"','",G8,"',",H8) -> 1007,'LICENCIATURA','MATERIAS INSTITUCIONALES','TC0201 2','AGUILAR CEBALLOS CARLA MARIANA','EXPERIENCIA DE ACCION SOCIAL','FEMENINO',1 | J8: =CONCATENATE($I$1,I8,");") -> INSERT INTO profesores (id,nivel,carrera,grupo,nombre,materia,sexo,sello) VALUES (1007,'LICENCIATURA','MATERIAS INSTITUCIONALES','TC0201 2','AGUILAR CEBALLOS CARLA MARIANA','EXPERIENCIA DE ACCION SOCIAL','FEMENINO',1);
A9: =A8+1 -> 1008 | B9: LICENCIATURA | C9: =Hoja1!B9 -> MATERIAS INSTITUCIONALES | D9: TC0201 3' | E9: =Hoja1!D9 -> FARIAS CASTELLANOS ISIS | F9: =Hoja1!E9 -> EXPERIENCIA DE ACCION SOCIAL | G9: =Hoja1!F9 -> FEMENINO | H9: =IF(C9="MATERIAS INSTITUCIONALES",1,0) -> 1 | I9: =CONCATENATE(A9,",'",B9,"','",C9,"','",D9,",'",E9,"','",F9,"','",G9,"',",H9) -> 1008,'LICENCIATURA','MATERIAS INSTITUCIONALES','TC0201 3','FARIAS CASTELLANOS ISIS','EXPERIENCIA DE ACCION SOCIAL','FEMENINO',1 | J9: =CONCATENATE($I$1,I9,");") -> INSERT INTO profesores (id,nivel,carrera,grupo,nombre,materia,sexo,sello) VALUES (1008,'LICENCIATURA','MATERIAS INSTITUCIONALES','TC0201 3','FARIAS CASTELLANOS ISIS','EXPERIENCIA DE ACCION SOCIAL','FEMENINO',1);
A10: =A9+1 -> 1009 | B10: LICENCIATURA | C10: =Hoja1!B10 -> MATERIAS INSTITUCIONALES | D10: TC0201 4' | E10: =Hoja1!D10 -> CASILLAS MORA MONICA DANIELA | F10: =Hoja1!E10 -> EXPERIENCIA DE ACCION SOCIAL | G10: =Hoja1!F10 -> FEMENINO | H10: =IF(C10="MATERIAS INSTITUCIONALES",1,0) -> 1 | I10: =CONCATENATE(A10,",'",B10,"','",C10,"','",D10,",'",E10,"','",F10,"','",G10,"',",H10) -> 1009,'LICENCIATURA','MATERIAS INSTITUCIONALES','TC0201 4','CASILLAS MORA MONICA DANIELA','EXPERIENCIA DE ACCION SOCIAL','FEMENINO',1 | J10: =CONCATENATE($I$1,I10,");") -> INSERT INTO profesores (id,nivel,carrera,grupo,nombre,materia,sexo,sello) VALUES (1009,'LICENCIATURA','MATERIAS INSTITUCIONALES','TC0201 4','CASILLAS MORA MONICA DANIELA','EXPERIENCIA DE ACCION SOCIAL','FEMENINO',1);
A11: =A10+1 -> 1010 | B11: LICENCIATURA | C11: =Hoja1!B11 -> MATERIAS INSTITUCIONALES | D11: TC0201 5' | E11: =Hoja1!D11 -> HERNANDEZ MONTAÑO AIDA CITLALI | F11: =Hoja1!E11 -> EXPERIENCIA DE ACCION SOCIAL | G11: =Hoja1!F11 -> FEMENINO | H11: =IF(C11="MATERIAS INSTITUCIONALES",1,0) -> 1 | I11: =CONCATENATE(A11,",'",B11,"','",C11,"','",D11,",'",E11,"','",F11,"','",G11,"',",H11) -> 1010,'LICENCIATURA','MATERIAS INSTITUCIONALES','TC0201 5','HERNANDEZ MONTAÑO AIDA CITLALI','EXPERIENCIA DE ACCION SOCIAL','FEMENINO',1 | J11: =CONCATENATE($I$1,I11,");") -> INSERT INTO profesores (id,nivel,carrera,grupo,nombre,materia,sexo,sello) VALUES (1010,'LICENCIATURA','MATERIAS INSTITUCIONALES','TC0201 5','HERNANDEZ MONTAÑO AIDA CITLALI','EXPERIENCIA DE ACCION SOCIAL','FEMENINO',1);
A12: =A11+1 -> 1011 | B12: LICENCIATURA | C12: =Hoja1!B12 -> MATERIAS INSTITUCIONALES | D12: TC0201 6' | E12: =Hoja1!D12 -> AGUILAR CEBALLOS CARLA MARIANA | F12: =Hoja1!E12 -> EXPERIENCIA DE ACCION SOCIAL | G12: =Hoja1!F12 -> FEMENINO | H12: =IF(C12="MATERIAS INSTITUCIONALES",1,0) -> 1 | I12: =CONCATENATE(A12,",'",B12,"','",C12,"','",D12,",'",E12,"','",F12,"','",G12,"',",H12) -> 1011,'LICENCIATURA','MATERIAS INSTITUCIONALES','TC0201 6','AGUILAR CEBALLOS CARLA MARIANA','EXPERIENCIA DE ACCION SOCIAL','FEMENINO',1 | J12: =CONCATENATE($I$1,I12,");") -> INSERT INTO profesores (id,nivel,carrera,grupo,nombre,materia,sexo,sello) VALUES (1011,'LICENCIATURA','MATERIAS INSTITUCIONALES','TC0201 6','AGUILAR CEBALLOS CARLA MARIANA','EXPERIENCIA DE ACCION SOCIAL','FEMENINO',1);
A13: =A12+1 -> 1012 | B13: LICENCIATURA | C13: =Hoja1!B13 -> MATERIAS INSTITUCIONALES | D13: TC0201 7' | E13: =Hoja1!D13 -> FARIAS CASTELLANOS ISIS | F13: =Hoja1!E13 -> EXPERIENCIA DE ACCION SOCIAL | G13: =Hoja1!F13 -> FEMENINO | H13: =IF(C13="MATERIAS INSTITUCIONALES",1,0) -> 1 | I13: =CONCATENATE(A13,",'",B13,"','",C13,"','",D13,",'",E13,"','",F13,"','",G13,"',",H13) -> 1012,'LICENCIATURA','MATERIAS INSTITUCIONALES','TC0201 7','FARIAS CASTELLANOS ISIS','EXPERIENCIA DE ACCION SOCIAL','FEMENINO',1 | J13: =CONCATENATE($I$1,I13,");") -> INSERT INTO profesores (id,nivel,carrera,grupo,nombre,materia,sexo,sello) VALUES (1012,'LICENCIATURA','MATERIAS INSTITUCIONALES','TC0201 7','FARIAS CASTELLANOS ISIS','EXPERIENCIA DE ACCION SOCIAL','FEMENINO',1);
A14: =A13+1 -> 1013 | B14: LICENCIATURA | C14: =Hoja1!B14 -> MATERIAS INSTITUCIONALES | D14: TC0201 8' | E14: =Hoja1!D14 -> CASILLAS MORA MONICA DANIELA | F14: =Hoja1!E14 -> EXPERIENCIA DE ACCION SOCIAL | G14: =Hoja1!F14 -> FEMENINO | H14: =IF(C14="MATERIAS INSTITUCIONALES",1,0) -> 1 | I14: =CONCATENATE(A14,",'",B14,"','",C14,"','",D14,",'",E14,"','",F14,"','",G14,"',",H14) -> 1013,'LICENCIATURA','MATERIAS INSTITUCIONALES','TC0201 8','CASILLAS MORA MONICA DANIELA','EXPERIENCIA DE ACCION SOCIAL','FEMENINO',1 | J14: =CONCATENATE($I$1,I14,");") -> INSERT INTO profesores (id,nivel,carrera,grupo,nombre,materia,sexo,sello) VALUES (1013,'LICENCIATURA','MATERIAS INSTITUCIONALES','TC0201 8','CASILLAS MORA MONICA DANIELA','EXPERIENCIA DE ACCION SOCIAL','FEMENINO',1);
... A50: =A49+1 -> 1049 | B50: LICENCIATURA | C50: =Hoja1!B50 -> MATERIAS INSTITUCIONALES | D50: TC0801 5' | E50: =Hoja1!D50 -> BUSTAMANTE RAMIREZ LIDIA SELENE | F50: =Hoja1!E50 -> ESCENARIO DE INTERVENCION III | G50: =Hoja1!F50 -> MASCULINO | H50: =IF(C50="MATERIAS INSTITUCIONALES",1,0) -> 1 | I50: =CONCATENATE(A50,",'",B50,"','",C50,"','",D50,",'",E50,"','",F50,"','",G50,"',",H50) -> 1049,'LICENCIATURA','MATERIAS INSTITUCIONALES','TC0801 5','BUSTAMANTE RAMIREZ LIDIA SELENE','ESCENARIO DE INTERVENCION III','MASCULINO',1 | J50: =CONCATENATE($I$1,I50,");") -> INSERT INTO profesores (id,nivel,carrera,grupo,nombre,materia,sexo,sello) VALUES (1049,'LICENCIATURA','MATERIAS INSTITUCIONALES','TC0801 5','BUSTAMANTE RAMIREZ LIDIA SELENE','ESCENARIO DE INTERVENCION III','MASCULINO',1);
A51: =A50+1 -> 1050 | B51: LICENCIATURA | C51: IDIOMAS | D51: TIDIOMAS_1' | E51: =Hoja1!D51 -> ESPEJO REGALADO ERIKA | F51: =Hoja1!E51 -> IDIOMAS 2 | G51: =Hoja1!F51 -> FEMENINO | H51: 1 | I51: =CONCATENATE(A51,",'",B51,"','",C51,"','",D51,",'",E51,"','",F51,"','",G51,"',",H51) -> 1050,'LICENCIATURA','IDIOMAS','TIDIOMAS_1','ESPEJO REGALADO ERIKA','IDIOMAS 2','FEMENINO',1 | J51: =CONCATENATE($I$1,I51,");") -> INSERT INTO profesores (id,nivel,carrera,grupo,nombre,materia,sexo,sello) VALUES (1050,'LICENCIATURA','IDIOMAS','TIDIOMAS_1','ESPEJO REGALADO ERIKA','IDIOMAS 2','FEMENINO',1);
A52: =A51+1 -> 1051 | B52: LICENCIATURA | C52: IDIOMAS | D52: TIDIOMAS_2' | E52: =Hoja1!D52 -> CORTES VELASCO CLAUDIA PAOLA | F52: =Hoja1!E52 -> IDIOMAS 2 | G52: =Hoja1!F52 -> FEMENINO | H52: 1 | I52: =CONCATENATE(A52,",'",B52,"','",C52,"','",D52,",'",E52,"','",F52,"','",G52,"',",H52) -> 1051,'LICENCIATURA','IDIOMAS','TIDIOMAS_2','CORTES VELASCO CLAUDIA PAOLA','IDIOMAS 2','FEMENINO',1 | J52: =CONCATENATE($I$1,I52,");") -> INSERT INTO profesores (id,nivel,carrera,grupo,nombre,materia,sexo,sello) VALUES (1051,'LICENCIATURA','IDIOMAS','TIDIOMAS_2','CORTES VELASCO CLAUDIA PAOLA','IDIOMAS 2','FEMENINO',1);
A53: =A52+1 -> 1052 | B53: LICENCIATURA | C53: IDIOMAS | D53: TIDIOMAS_3' | E53: =Hoja1!D53 -> GARIBAY GARCIA GABRIELA | F53: =Hoja1!E53 -> IDIOMAS 2 | G53: =Hoja1!F53 -> FEMENINO | H53: 1 | I53: =CONCATENATE(A53,",'",B53,"','",C53,"','",D53,",'",E53,"','",F53,"','",G53,"',",H53) -> 1052,'LICENCIATURA','IDIOMAS','TIDIOMAS_3','GARIBAY GARCIA GABRIELA','IDIOMAS 2','FEMENINO',1 | J53: =CONCATENATE($I$1,I53,");") -> INSERT INTO profesores (id,nivel,carrera,grupo,nombre,materia,sexo,sello) VALUES (1052,'LICENCIATURA','IDIOMAS','TIDIOMAS_3','GARIBAY GARCIA GABRIELA','IDIOMAS 2','FEMENINO',1);
A54: =A53+1 -> 1053 | B54: LICENCIATURA | C54: IDIOMAS | D54: TIDIOMAS_4' | E54: =Hoja1!D54 -> DE LA ROSA RICARIO MELISSA | F54: =Hoja1!E54 -> IDIOMAS 2 | G54: =Hoja1!F54 -> FEMENINO | H54: 1 | I54: =CONCATENATE(A54,",'",B54,"','",C54,"','",D54,",'",E54,"','",F54,"','",G54,"',",H54) -> 1053,'LICENCIATURA','IDIOMAS','TIDIOMAS_4','DE LA ROSA RICARIO MELISSA','IDIOMAS 2','FEMENINO',1 | J54: =CONCATENATE($I$1,I54,");") -> INSERT INTO profesores (id,nivel,carrera,grupo,nombre,materia,sexo,sello) VALUES (1053,'LICENCIATURA','IDIOMAS','TIDIOMAS_4','DE LA ROSA RICARIO MELISSA','IDIOMAS 2','FEMENINO',1);
A55: =A54+1 -> 1054 | B55: LICENCIATURA | C55: IDIOMAS | D55: TIDIOMAS_5' | E55: =Hoja1!D55 -> MONCAYO TARIN ITZEL ALABAMA | F55: =Hoja1!E55 -> IDIOMAS 2 | G55: =Hoja1!F55 -> FEMENINO | H55: 1 | I55: =CONCATENATE(A55,",'",B55,"','",C55,"','",D55,",'",E55,"','",F55,"','",G55,"',",H55) -> 1054,'LICENCIATURA','IDIOMAS','TIDIOMAS_5','MONCAYO TARIN ITZEL ALABAMA','IDIOMAS 2','FEMENINO',1 | J55: =CONCATENATE($I$1,I55,");") -> INSERT INTO profesores (id,nivel,carrera,grupo,nombre,materia,sexo,sello) VALUES (1054,'LICENCIATURA','IDIOMAS','TIDIOMAS_5','MONCAYO TARIN ITZEL ALABAMA','IDIOMAS 2','FEMENINO',1);
A56: =A55+1 -> 1055 | B56: LICENCIATURA | C56: IDIOMAS | D56: TIDIOMAS_6' | E56: =Hoja1!D56 -> QUIROZ ZEPEDA JUAN PABLO | F56: =Hoja1!E56 -> IDIOMAS 2 | G56: =Hoja1!F56 -> MASCULINO | H56: 1 | I56: =CONCATENATE(A56,",'",B56,"','",C56,"','",D56,",'",E56,"','",F56,"','",G56,"',",H56) -> 1055,'LICENCIATURA','IDIOMAS','TIDIOMAS_6','QUIROZ ZEPEDA JUAN PABLO','IDIOMAS 2','MASCULINO',1 | J56: =CONCATENATE($I$1,I56,");") -> INSERT INTO profesores (id,nivel,carrera,grupo,nombre,materia,sexo,sello) VALUES (1055,'LICENCIATURA','IDIOMAS','TIDIOMAS_6','QUIROZ ZEPEDA JUAN PABLO','IDIOMAS 2','MASCULINO',1);
A57: =A56+1 -> 1056 | B57: LICENCIATURA | C57: IDIOMAS | D57: TIDIOMAS_7' | E57: =Hoja1!D57 -> JIMENEZ ROBLES LINA ADITH | F57: =Hoja1!E57 -> IDIOMAS 2 | G57: =Hoja1!F57 -> FEMENINO | H57: 1 | I57: =CONCATENATE(A57,",'",B57,"','",C57,"','",D57,",'",E57,"','",F57,"','",G57,"',",H57) -> 1056,'LICENCIATURA','IDIOMAS','TIDIOMAS_7','JIMENEZ ROBLES LINA ADITH','IDIOMAS 2','FEMENINO',1 | J57: =CONCATENATE($I$1,I57,");") -> INSERT INTO profesores (id,nivel,carrera,grupo,nombre,materia,sexo,sello) VALUES (1056,'LICENCIATURA','IDIOMAS','TIDIOMAS_7','JIMENEZ ROBLES LINA ADITH','IDIOMAS 2','FEMENINO',1);
A58: =A57+1 -> 1057 | B58: LICENCIATURA | C58: =Hoja1!B58 -> ADMINISTRACION Y DIRECCION DE NEGOCIOS | D58: ADMON 2°' | E58: =Hoja1!D58 -> DELGADO BEJAR RUTH | F58: =Hoja1!E58 -> CONTABILIDAD BASICA | G58: =Hoja1!F58 -> FEMENINO | H58: =IF(C58="MATERIAS INSTITUCIONALES",1,0) -> 0 | I58: =CONCATENATE(A58,",'",B58,"','",C58,"','",D58,",'",E58,"','",F58,"','",G58,"',",H58) -> 1057,'LICENCIATURA','ADMINISTRACION Y DIRECCION DE NEGOCIOS','ADMON 2°','DELGADO BEJAR RUTH','CONTABILIDAD BASICA','FEMENINO',0 | J58: =CONCATENATE($I$1,I58,");") -> INSERT INTO profesores (id,nivel,carrera,grupo,nombre,materia,sexo,sello) VALUES (1057,'LICENCIATURA','ADMINISTRACION Y DIRECCION DE NEGOCIOS','ADMON 2°','DELGADO BEJAR RUTH','CONTABILIDAD BASICA','FEMENINO',0);
A59: =A58+1 -> 1058 | B59: LICENCIATURA | C59: =Hoja1!B59 -> ADMINISTRACION Y DIRECCION DE NEGOCIOS | D59: ADMON 2°' | E59: =Hoja1!D59 -> ESCARCEGA GARCIA DE LEON MIGUEL ANGEL | F59: =Hoja1!E59 -> ESTADISTICA I | G59: =Hoja1!F59 -> MASCULINO | H59: =IF(C59="MATERIAS INSTITUCIONALES",1,0) -> 0 | I59: =CONCATENATE(A59,",'",B59,"','",C59,"','",D59,",'",E59,"','",F59,"','",G59,"',",H59) -> 1058,'LICENCIATURA','ADMINISTRACION Y DIRECCION DE NEGOCIOS','ADMON 2°','ESCARCEGA GARCIA DE LEON MIGUEL ANGEL','ESTADISTICA I','MASCULINO',0 | J59: =CONCATENATE($I$1,I59,");") -> INSERT INTO profesores (id,nivel,carrera,grupo,nombre,materia,sexo,sello) VALUES (1058,'LICENCIATURA','ADMINISTRACION Y DIRECCION DE NEGOCIOS','ADMON 2°','ESCARCEGA GARCIA DE LEON MIGUEL ANGEL','ESTADISTICA I','MASCULINO',0);
A60: =A59+1 -> 1059 | B60: LICENCIATURA | C60: =Hoja1!B60 -> ADMINISTRACION Y DIRECCION DE NEGOCIOS | D60: ADMON 2°' | E60: =Hoja1!D60 -> LUA HERRERA LILIANA | F60: =Hoja1!E60 -> MATEMATICAS FINANCIERAS | G60: =Hoja1!F60 -> FEMENINO | H60: =IF(C60="MATERIAS INSTITUCIONALES",1,0) -> 0 | I60: =CONCATENATE(A60,",'",B60,"','",C60,"','",D60,",'",E60,"','",F60,"','",G60,"',",H60) -> 1059,'LICENCIATURA','ADMINISTRACION Y DIRECCION DE NEGOCIOS','ADMON 2°','LUA HERRERA LILIANA','MATEMATICAS FINANCIERAS','FEMENINO',0 | J60: =CONCATENATE($I$1,I60,");") -> INSERT INTO profesores (id,nivel,carrera,grupo,nombre,materia,sexo,sello) VALUES (1059,'LICENCIATURA','ADMINISTRACION Y DIRECCION DE NEGOCIOS','ADMON 2°','LUA HERRERA LILIANA','MATEMATICAS FINANCIERAS','FEMENINO',0);
A61: =A60+1 -> 1060 | B61: LICENCIATURA | C61: =Hoja1!B61 -> ADMINISTRACION Y DIRECCION DE NEGOCIOS | D61: ADMON 2°' | E61: =Hoja1!D61 -> MORENO CORRAL ALVARO | F61: =Hoja1!E61 -> PLANEACION ESTRATEGICA | G61: =Hoja1!F61 -> MASCULINO | H61: =IF(C61="MATERIAS INSTITUCIONALES",1,0) -> 0 | I61: =CONCATENATE(A61,",'",B61,"','",C61,"','",D61,",'",E61,"','",F61,"','",G61,"',",H61) -> 1060,'LICENCIATURA','ADMINISTRACION Y DIRECCION DE NEGOCIOS','ADMON 2°','MORENO CORRAL ALVARO','PLANEACION ESTRATEGICA','MASCULINO',0 | J61: =CONCATENATE($I$1,I61,");") -> INSERT INTO profesores (id,nivel,carrera,grupo,nombre,materia,sexo,sello) VALUES (1060,'LICENCIATURA','ADMINISTRACION Y DIRECCION DE NEGOCIOS','ADMON 2°','MORENO CORRAL ALVARO','PLANEACION ESTRATEGICA','MASCULINO',0);
A62: =A61+1 -> 1061 | B62: LICENCIATURA | C62: =Hoja1!B62 -> ADMINISTRACION Y DIRECCION DE NEGOCIOS | D62: ADMON 2°' | E62: =Hoja1!D62 -> OROZCO DIAZ BEATRIZ IRENE | F62: =Hoja1!E62 -> DERECHO MERCANTIL | G62: =Hoja1!F62 -> FEMENINO | H62: =IF(C62="MATERIAS INSTITUCIONALES",1,0) -> 0 | I62: =CONCATENATE(A62,",'",B62,"','",C62,"','",D62,",'",E62,"','",F62,"','",G62,"',",H62) -> 1061,'LICENCIATURA','ADMINISTRACION Y DIRECCION DE NEGOCIOS','ADMON 2°','OROZCO DIAZ BEATRIZ IRENE','DERECHO MERCANTIL','FEMENINO',0 | J62: =CONCATENATE($I$1,I62,");") -> INSERT INTO profesores (id,nivel,carrera,grupo,nombre,materia,sexo,sello) VALUES (1061,'LICENCIATURA','ADMINISTRACION Y DIRECCION DE NEGOCIOS','ADMON 2°','OROZCO DIAZ BEATRIZ IRENE','DERECHO MERCANTIL','FEMENINO',0);
A63: =A62+1 -> 1062 | B63: LICENCIATURA | C63: =Hoja1!B63 -> ADMINISTRACION Y DIRECCION DE NEGOCIOS | D63: ADMON 2°' | E63: =Hoja1!D63 -> PADILLA MARTINEZ ELSA GEORGINA | F63: =Hoja1!E63 -> DISEÑO DE ESTRUCTURAS Y SISTEMAS ADMINISTRATIVOS | G63: =Hoja1!F63 -> FEMENINO | H63: =IF(C63="MATERIAS INSTITUCIONALES",1,0) -> 0 | I63: =CONCATENATE(A63,",'",B63,"','",C63,"','",D63,",'",E63,"','",F63,"','",G63,"',",H63) -> 1062,'LICENCIATURA','ADMINISTRACION Y DIRECCION DE NEGOCIOS','ADMON 2°','PADILLA MARTINEZ ELSA GEORGINA','DISEÑO DE ESTRUCTURAS Y SISTEMAS ADMINISTRATIVOS','FEMENINO',0 | J63: =CONCATENATE($I$1,I63,");") -> INSERT INTO profesores (id,nivel,carrera,grupo,nombre,materia,sexo,sello) VALUES (1062,'LICENCIATURA','ADMINISTRACION Y DIRECCION DE NEGOCIOS','ADMON 2°','PADILLA MARTINEZ ELSA GEORGINA','DISEÑO DE ESTRUCTURAS Y SISTEMAS ADMINISTRATIVOS','FEMENINO',0);
A64: =A63+1 -> 1063 | B64: LICENCIATURA | C64: =Hoja1!B64 -> ADMINISTRACION Y DIRECCION DE NEGOCIOS | D64: ADMON 2°' | E64: =Hoja1!D64 -> RODRIGUEZ ROMERO DENIS PAUL | F64: =Hoja1!E64 -> ECONOMIA MEXICANA Y DESARROLLO | G64: =Hoja1!F64 -> MASCULINO | H64: =IF(C64="MATERIAS INSTITUCIONALES",1,0) -> 0 | I64: =CONCATENATE(A64,",'",B64,"','",C64,"','",D64,",'",E64,"','",F64,"','",G64,"',",H64) -> 1063,'LICENCIATURA','ADMINISTRACION Y DIRECCION DE NEGOCIOS','ADMON 2°','RODRIGUEZ ROMERO DENIS PAUL','ECONOMIA MEXICANA Y DESARROLLO','MASCULINO',0 | J64: =CONCATENATE($I$1,I64,");") -> INSERT INTO profesores (id,nivel,carrera,grupo,nombre,materia,sexo,sello) VALUES (1063,'LICENCIATURA','ADMINISTRACION Y DIRECCION DE NEGOCIOS','ADMON 2°','RODRIGUEZ ROMERO DENIS PAUL','ECONOMIA MEXICANA Y DESARROLLO','MASCULINO',0);
A65: =A64+1 -> 1064 | B65: LICENCIATURA | C65: =Hoja1!B65 -> ADMINISTRACION Y DIRECCION DE NEGOCIOS | D65: ADMON 4°' | E65: =Hoja1!D65 -> ESCARCEGA GARCIA DE LEON MIGUEL ANGEL | F65: =Hoja1!E65 -> FUNDAMENTOS DE MERCADOTECNIA | G65: =Hoja1!F65 -> MASCULINO | H65: =IF(C65="MATERIAS INSTITUCIONALES",1,0) -> 0 | I65: =CONCATENATE(A65,",'",B65,"','",C65,"','",D65,",'",E65,"','",F65,"','",G65,"',",H65) -> 1064,'LICENCIATURA','ADMINISTRACION Y DIRECCION DE NEGOCIOS','ADMON 4°','ESCARCEGA GARCIA DE LEON MIGUEL ANGEL','FUNDAMENTOS DE MERCADOTECNIA','MASCULINO',0 | J65: =CONCATENATE($I$1,I65,");") -> INSERT INTO profesores (id,nivel,carrera,grupo,nombre,materia,sexo,sello) VALUES (1064,'LICENCIATURA','ADMINISTRACION Y DIRECCION DE NEGOCIOS','ADMON 4°','ESCARCEGA GARCIA DE LEON MIGUEL ANGEL','FUNDAMENTOS DE MERCADOTECNIA','MASCULINO',0);
A66: =A65+1 -> 1065 | B66: LICENCIATURA | C66: =Hoja1!B66 -> ADMINISTRACION Y DIRECCION DE NEGOCIOS | D66: ADMON 4°' | E66: =Hoja1!D66 -> GUILLEN LAGUNES JOSE JAVIER | F66: =Hoja1!E66 -> DIAGNOSTICO Y DESARROLLO ORGANIZACIONAL | G66: =Hoja1!F66 -> MASCULINO | H66: =IF(C66="MATERIAS INSTITUCIONALES",1,0) -> 0 | I66: =CONCATENATE(A66,",'",B66,"','",C66,"','",D66,",'",E66,"','",F66,"','",G66,"',",H66) -> 1065,'LICENCIATURA','ADMINISTRACION Y DIRECCION DE NEGOCIOS','ADMON 4°','GUILLEN LAGUNES JOSE JAVIER','DIAGNOSTICO Y DESARROLLO ORGANIZACIONAL','MASCULINO',0 | J66: =CONCATENATE($I$1,I66,");") -> INSERT INTO profesores (id,nivel,carrera,grupo,nombre,materia,sexo,sello) VALUES (1065,'LICENCIATURA','ADMINISTRACION Y DIRECCION DE NEGOCIOS','ADMON 4°','GUILLEN LAGUNES JOSE JAVIER','DIAGNOSTICO Y DESARROLLO ORGANIZACIONAL','MASCULINO',0);
A67: =A66+1 -> 1066 | B67: LICENCIATURA | C67: =Hoja1!B67 -> ADMINISTRACION Y DIRECCION DE NEGOCIOS | D67: ADMON 4°' | E67: =Hoja1!D67 -> LUA HERRERA LILIANA | F67: =Hoja1!E67 -> DERECHO TRIBUTARIO | G67: =Hoja1!F67 -> FEMENINO | H67: =IF(C67="MATERIAS INSTITUCIONALES",1,0) -> 0 | I67: =CONCATENATE(A67,",'",B67,"','",C67,"','",D67,",'",E67,"','",F67,"','",G67,"',",H67) -> 1066,'LICENCIATURA','ADMINISTRACION Y DIRECCION DE NEGOCIOS','ADMON 4°','LUA HERRERA LILIANA','DERECHO TRIBUTARIO','FEMENINO',0 | J67: =CONCATENATE($I$1,I67,");") -> INSERT INTO profesores (id,nivel,carrera,grupo,nombre,materia,sexo,sello) VALUES (1066,'LICENCIATURA','ADMINISTRACION Y DIRECCION DE NEGOCIOS','ADMON 4°','LUA HERRERA LILIANA','DERECHO TRIBUTARIO','FEMENINO',0);
A68: =A67+1 -> 1067 | B68: LICENCIATURA | C68: =Hoja1!B68 -> ADMINISTRACION Y DIRECCION DE NEGOCIOS | D68: ADMON 4°' | E68: =Hoja1!D68 -> MAGALLON RAMIREZ MARIA DEL CARMEN | F68: =Hoja1!E68 -> GESTIÓN FINANCIERA | G68: =Hoja1!F68 -> FEMENINO | H68: =IF(C68="MATERIAS INSTITUCIONALES",1,0) -> 0 | I68: =CONCATENATE(A68,",'",B68,"','",C68,"','",D68,",'",E68,"','",F68,"','",G68,"',",H68) -> 1067,'LICENCIATURA','ADMINISTRACION Y DIRECCION DE NEGOCIOS','ADMON 4°','MAGALLON RAMIREZ MARIA DEL CARMEN','GESTIÓN FINANCIERA','FEMENINO',0 | J68: =CONCATENATE($I$1,I68,");") -> INSERT INTO profesores (id,nivel,carrera,grupo,nombre,materia,sexo,sello) VALUES (1067,'LICENCIATURA','ADMINISTRACION Y DIRECCION DE NEGOCIOS','ADMON 4°','MAGALLON RAMIREZ MARIA DEL CARMEN','GESTIÓN FINANCIERA','FEMENINO',0);
A69: =A68+1 -> 1068 | B69: LICENCIATURA | C69: =Hoja1!B69 -> ADMINISTRACION Y DIRECCION DE NEGOCIOS | D69: ADMON 4°' | E69: =Hoja1!D69 -> RODRIGUEZ ROMERO DENIS PAUL | F69: =Hoja1!E69 -> PRESUPUESTOS | G69: =Hoja1!F69 -> MASCULINO | H69: =IF(C69="MATERIAS INSTITUCIONALES",1,0) -> 0 | I69: =CONCATENATE(A69,",'",B69,"','",C69,"','",D69,",'",E69,"','",F69,"','",G69,"',",H69) -> 1068,'LICENCIATURA','ADMINISTRACION Y DIRECCION DE NEGOCIOS','ADMON 4°','RODRIGUEZ ROMERO DENIS PAUL','PRESUPUESTOS','MASCULINO',0 | J69: =CONCATENATE($I$1,I69,");") -> INSERT INTO profesores (id,nivel,carrera,grupo,nombre,materia,sexo,sello) VALUES (1068,'LICENCIATURA','ADMINISTRACION Y DIRECCION DE NEGOCIOS','ADMON 4°','RODRIGUEZ ROMERO DENIS PAUL','PRESUPUESTOS','MASCULINO',0);
... A118: =A117+1 -> 1117 | B118: LICENCIATURA | C118: =Hoja1!B118 -> ARQUITECTURA | D118: ARQ 2°' | E118: =Hoja1!D118 -> PUJOL BECERRA ALVARO | F118: =Hoja1!E118 -> DIBUJO ASISTIDO POR COMPUTADORA | G118: =Hoja1!F118 -> MASCULINO | H118: =IF(C118="MATERIAS INSTITUCIONALES",1,0) -> 0 | I118: =CONCATENATE(A118,",'",B118,"','",C118,"','",D118,",'",E118,"','",F118,"','",G118,"',",H118) -> 1117,'LICENCIATURA','ARQUITECTURA','ARQ 2°','PUJOL BECERRA ALVARO','DIBUJO ASISTIDO POR COMPUTADORA','MASCULINO',0 | J118: =CONCATENATE($I$1,I118,");") -> INSERT INTO profesores (id,nivel,carrera,grupo,nombre,materia,sexo,sello) VALUES (1117,'LICENCIATURA','ARQUITECTURA','ARQ 2°','PUJOL BECERRA ALVARO','DIBUJO ASISTIDO POR COMPUTADORA','MASCULINO',0);
A119: =A118+1 -> 1118 | B119: LICENCIATURA | C119: =Hoja1!B119 -> ARQUITECTURA | D119: ARQ 4°' | E119: CUESTA SÁNCHEZ EDUARDO | F119: =Hoja1!E119 -> HISTORIA DE LA ARQUITECTURA MEXICANA | G119: =Hoja1!F119 -> MASCULINO | H119: =IF(C119="MATERIAS INSTITUCIONALES",1,0) -> 0 | I119: =CONCATENATE(A119,",'",B119,"','",C119,"','",D119,",'",E119,"','",F119,"','",G119,"',",H119) -> 1118,'LICENCIATURA','ARQUITECTURA','ARQ 4°','CUESTA SÁNCHEZ EDUARDO','HISTORIA DE LA ARQUITECTURA MEXICANA','MASCULINO',0 | J119: =CONCATENATE($I$1,I119,");") -> INSERT INTO profesores (id,nivel,carrera,grupo,nombre,materia,sexo,sello) VALUES (1118,'LICENCIATURA','ARQUITECTURA','ARQ 4°','CUESTA SÁNCHEZ EDUARDO','HISTORIA DE LA ARQUITECTURA MEXICANA','MASCULINO',0);
A120: =A119+1 -> 1119 | B120: LICENCIATURA | C120: =Hoja1!B120 -> ARQUITECTURA | D120: ARQ 4°' | E120: =Hoja1!D120 -> ESPINO CAMPOS NYDIA | F120: =Hoja1!E120 -> DISEÑO DEL ESPACIO RELIGIOSO Y EDUCATIVO | G120: =Hoja1!F120 -> FEMENINO | H120: =IF(C120="MATERIAS INSTITUCIONALES",1,0) -> 0 | I120: =CONCATENATE(A120,",'",B120,"','",C120,"','",D120,",'",E120,"','",F120,"','",G120,"',",H120) -> 1119,'LICENCIATURA','ARQUITECTURA','ARQ 4°','ESPINO CAMPOS NYDIA','DISEÑO DEL ESPACIO RELIGIOSO Y EDUCATIVO','FEMENINO',0 | J120: =CONCATENATE($I$1,I120,");") -> INSERT INTO profesores (id,nivel,carrera,grupo,nombre,materia,sexo,sello) VALUES (1119,'LICENCIATURA','ARQUITECTURA','ARQ 4°','ESPINO CAMPOS NYDIA','DISEÑO DEL ESPACIO RELIGIOSO Y EDUCATIVO','FEMENINO',0);
A121: =A120+1 -> 1120 | B121: LICENCIATURA | C121: =Hoja1!B121 -> ARQUITECTURA | D121: ARQ 4°' | E121: =Hoja1!D121 -> MARTINEZ GOMEZ LETICIA | F121: =Hoja1!E121 -> ARQUITECTURA DEL PAISAJISMO | G121: =Hoja1!F121 -> FEMENINO | H121: =IF(C121="MATERIAS INSTITUCIONALES",1,0) -> 0 | I121: =CONCATENATE(A121,",'",B121,"','",C121,"','",D121,",'",E121,"','",F121,"','",G121,"',",H121) -> 1120,'LICENCIATURA','ARQUITECTURA','ARQ 4°','MARTINEZ GOMEZ LETICIA','ARQUITECTURA DEL PAISAJISMO','FEMENINO',0 | J121: =CONCATENATE($I$1,I121,");") -> INSERT INTO profesores (id,nivel,carrera,grupo,nombre,materia,sexo,sello) VALUES (1120,'LICENCIATURA','ARQUITECTURA','ARQ 4°','MARTINEZ GOMEZ LETICIA','ARQUITECTURA DEL PAISAJISMO','FEMENINO',0);
A122: =A121+1 -> 1121 | B122: LICENCIATURA | C122: =Hoja1!B122 -> ARQUITECTURA | D122: ARQ 4°' | E122: =Hoja1!D122 -> MONTELONGO AGUAYO DANIEL | F122: =Hoja1!E122 -> DISEÑO DE INSTALACIONES HIDRAULICAS SANITARIAS | G122: =Hoja1!F122 -> MASCULINO | H122: =IF(C122="MATERIAS INSTITUCIONALES",1,0) -> 0 | I122: =CONCATENATE(A122,",'",B122,"','",C122,"','",D122,",'",E122,"','",F122,"','",G122,"',",H122) -> 1121,'LICENCIATURA','ARQUITECTURA','ARQ 4°','MONTELONGO AGUAYO DANIEL','DISEÑO DE INSTALACIONES HIDRAULICAS SANITARIAS','MASCULINO',0 | J122: =CONCATENATE($I$1,I122,");") -> INSERT INTO profesores (id,nivel,carrera,grupo,nombre,materia,sexo,sello) VALUES (1121,'LICENCIATURA','ARQUITECTURA','ARQ 4°','MONTELONGO AGUAYO DANIEL','DISEÑO DE INSTALACIONES HIDRAULICAS SANITARIAS','MASCULINO',0);
A123: =A122+1 -> 1122 | B123: LICENCIATURA | C123: =Hoja1!B123 -> ARQUITECTURA | D123: ARQ 4°' | E123: =Hoja1!D123 -> RAMOS RENTERIA MONTSERRAT FABIOLA | F123: =Hoja1!E123 -> FOTOGRAFIA | G123: =Hoja1!F123 -> FEMENINO | H123: =IF(C123="MATERIAS INSTITUCIONALES",1,0) -> 0 | I123: =CONCATENATE(A123,",'",B123,"','",C123,"','",D123,",'",E123,"','",F123,"','",G123,"',",H123) -> 1122,'LICENCIATURA','ARQUITECTURA','ARQ 4°','RAMOS RENTERIA MONTSERRAT FABIOLA','FOTOGRAFIA','FEMENINO',0 | J123: =CONCATENATE($I$1,I123,");") -> INSERT INTO profesores (id,nivel,carrera,grupo,nombre,materia,sexo,sello) VALUES (1122,'LICENCIATURA','ARQUITECTURA','ARQ 4°','RAMOS RENTERIA MONTSERRAT FABIOLA','FOTOGRAFIA','FEMENINO',0);
...
